Workbook

Sheet V1 · Individual
A1: VIEW 1 — INDIVIDUAL CONTRIBUTION | Booking (Revenue) | H1 & Annual
A2: # | B2: Employee Name | C2: Division | D2: FY | E2: Type / Notes | F2: Q1 Quota (₹ Cr) | G2: Q1 Actuals (₹ Cr) | H2: Attainment % (Q1) | I2: Q2 Quota (₹ Cr) | J2: Q2 Actuals (₹ Cr) | K2: Attainment % (Q2) | L2: H1 Quota (₹ Cr) | M2: H1 Actuals (₹ Cr) | N2: Attainment % (H1) | O2: H2 Quota (₹ Cr) | P2: H2 Actuals (₹ Cr) | Q2: Attainment % (H2) | R2: Annual Quota (₹ Cr) | S2: Annual Actuals (₹ Cr) | T2: Attainment % (Annual) | U2: # Deals (Total) | V2: Led-By Deals (count) | W2: Led-By Rev (₹ Cr) | X2: Contributed Deals (count) | Y2: Contributed Rev (₹ Cr) | Z2: Rank (Div.)
A3: S1 Division
A4: 1 | B4: Tasneem K | C4: S1 | D4: FY 25-26 | E4: IC | F4: =L4/2 -> 65.175 | G4: =SUMIF('[1]Opportunity Pipeline 1Apr to 21'!$F:$F,"Tasneem K",'[1]Opportunity Pipeline 1Apr to 21'!$O:$O)/10^7 -> 15.340588 | H4: =IFERROR(G4/F4,"-") -> 0.23537534 | I4: =L4/2 -> 65.175 | J4: - | K4: =IFERROR(J4/I4,"-") -> - | L4: ='[2]Tasneem- TARGET LETTER - 26-27'!$D$9/10^7 -> 130.35 | M4: =SUM(G4,J4) -> 15.340588 | N4: =IFERROR(M4/L4,"-") -> 0.11768767 | O4: ='[2]Tasneem- TARGET LETTER - 26-27'!$D$16/10^7 -> 129.65 | P4: - | Q4: =IFERROR(P4/O4,"-") -> - | R4: =SUM(L4,O4) -> 260 | S4: =SUM(M4,P4) -> 15.340588 | T4: =IFERROR(S4/R4,"-") -> 0.059002261 | U4: =COUNTIF([3]in!$F$1:$F$27,'V1 · Individual'!B4) -> #VALUE! | Z4: =IFERROR(RANK(S4,S4:S50,0),"-") -> -
A5: 2 | B5: Riya Roshyara | C5: S1 | D5: FY 25-26 | E5: IC | F5: =L5/2 -> 29.5 | G5: =SUMIF('[1]Opportunity Pipeline 1Apr to 21'!$F:$F,"Riya Roshyara",'[1]Opportunity Pipeline 1Apr to 21'!$O:$O)/10^7 -> 0 | H5: =IFERROR(G5/F5,"-") -> 0 | I5: =L5/2 -> 29.5 | J5: - | K5: =IFERROR(J5/I5,"-") -> - | L5: ='[4]RIYA- TARGET LETTER - 26-27'!$D$9/10^7 -> 59 | M5: =SUM(G5,J5) -> 0 | N5: =IFERROR(M5/L5,"-") -> 0 | O5: ='[4]RIYA- TARGET LETTER - 26-27'!$D$15/10^7 -> 61 | P5: - | Q5: =IFERROR(P5/O5,"-") -> - | R5: =SUM(L5,O5) -> 120 | S5: =SUM(M5,P5) -> 0 | T5: =IFERROR(S5/R5,"-") -> 0 | U5: =COUNTIF([3]in!$F$1:$F$27,'V1 · Individual'!B5) -> #VALUE! | Z5: =IFERROR(RANK(S5,S5:S51,0),"-") -> -
A6: 3 | B6: Chirag Palande | C6: S1 | D6: FY 25-26 | E6: IC | F6: =L6/2 -> 13.75 | G6: =SUMIF('[1]Opportunity Pipeline 1Apr to 21'!$F:$F,"Chirag Palande",'[1]Opportunity Pipeline 1Apr to 21'!$O:$O)/10^7 -> 0.1286674 | H6: =IFERROR(G6/F6,"-") -> 0.0093576291 | I6: =L6/2 -> 13.75 | J6: - | K6: =IFERROR(J6/I6,"-") -> - | L6: ='[5]Chirag- TARGET LETTER - 26-27'!$D$9/10^7 -> 27.5 | M6: =SUM(G6,J6) -> 0.1286674 | N6: =IFERROR(M6/L6,"-") -> 0.0046788145 | O6: ='[5]Chirag- TARGET LETTER - 26-27'!$D$14/10^7 -> 32.5 | P6: - | Q6: =IFERROR(P6/O6,"-") -> - | R6: =SUM(L6,O6) -> 60 | S6: =SUM(M6,P6) -> 0.1286674 | T6: =IFERROR(S6/R6,"-") -> 0.0021444567 | U6: =COUNTIF([3]in!$F$1:$F$27,'V1 · Individual'!B6) -> #VALUE! | Z6: =IFERROR(RANK(S6,S6:S52,0),"-") -> -
A7: 4 | B7: Richa Tiwari | C7: S1 | D7: FY 25-26 | E7: IC | F7: =L7/2 -> 12.5 | G7: =SUMIF('[1]Opportunity Pipeline 1Apr to 21'!$F:$F,"Richa Tiwari",'[1]Opportunity Pipeline 1Apr to 21'!$O:$O)/10^7 -> 9.9605375 | H7: =IFERROR(G7/F7,"-") -> 0.796843 | I7: =L7/2 -> 12.5 | J7: - | K7: =IFERROR(J7/I7,"-") -> - | L7: ='[6]Richa- TARGET LETTER - 26-27'!$D$9/10^7 -> 25 | M7: =SUM(G7,J7) -> 9.9605375 | N7: =IFERROR(M7/L7,"-") -> 0.3984215 | O7: ='[6]Richa- TARGET LETTER - 26-27'!$D$12/10^7 -> 35 | P7: - | Q7: =IFERROR(P7/O7,"-") -> - | R7: =SUM(L7,O7) -> 60 | S7: =SUM(M7,P7) -> 9.9605375 | T7: =IFERROR(S7/R7,"-") -> 0.16600896 | U7: =COUNTIF([3]in!$F$1:$F$27,'V1 · Individual'!B7) -> #VALUE! | Z7: =IFERROR(RANK(S7,S7:S54,0),"-") -> -
A8: 5 | B8: Pratik Kadam | C8: S1 | D8: FY 25-26 | E8: IC | F8: =L8/2 -> 2.5 | G8: =SUMIF('[1]Opportunity Pipeline 1Apr to 21'!$F:$F,"Pratik Kadam",'[1]Opportunity Pipeline 1Apr to 21'!$O:$O)/10^7 -> 1.3329669 | H8: =IFERROR(G8/F8,"-") -> 0.53318675 | I8: =L8/2 -> 2.5 | J8: - | K8: =IFERROR(J8/I8,"-") -> - | L8: ='[7]Pratik- TARGET LETTER - 26-27'!$D$9/10^7 -> 5 | M8: =SUM(G8,J8) -> 1.3329669 | N8: =IFERROR(M8/L8,"-") -> 0.26659337 | O8: ='[7]Pratik- TARGET LETTER - 26-27'!$D$10/10^7 -> 5 | P8: - | Q8: =IFERROR(P8/O8,"-") -> - | R8: =SUM(L8,O8) -> 10 | S8: =SUM(M8,P8) -> 1.3329669 | T8: =IFERROR(S8/R8,"-") -> 0.13329669 | U8: =COUNTIF([3]in!$F$1:$F$27,'V1 · Individual'!B8) -> #VALUE! | Z8: =IFERROR(RANK(S8,S8:S55,0),"-") -> -
B9: IC Subtotal — S1 | F9: =SUM(F4,F5,F6,F7,F8) -> 123.425 | G9: =SUM(G4,G5,G6,G7,G8) -> 26.76276 | H9: =IFERROR(G9/F9,"-") -> 0.21683419 | I9: =SUM(I4,I5,I6,I7,I8) -> 123.425 | J9: =SUM(J4,J5,J6,J7,J8) -> 0 | K9: =SUM(K4,K5,K6,K7,K8) -> 0 | L9: =SUM(L4,L5,L6,L7,L8) -> 246.85 | M9: =SUM(M4,M5,M6,M7,M8) -> 26.76276 | N9: =IFERROR(M9/L9,"-") -> 0.10841709 | O9: =SUM(O4,O5,O6,O7,O8) -> 263.15 | P9: =SUM(P4,P5,P6,P7,P8) -> 0 | Q9: =SUM(Q4,Q5,Q6,Q7,Q8) -> 0 | R9: =SUM(R4,R5,R6,R7,R8) -> 510 | S9: =SUM(S4,S5,S6,S7,S8) -> 26.76276 | T9: =IFERROR(S9/R9,"-") -> 0.052475999 | U9: =SUM(U4,U5,U6,U7,U8) -> #VALUE! | V9: =IFERROR(SUM(V4:V8),"—") -> 0 | W9: =IFERROR(SUM(W4:W8),"—") -> 0 | X9: =IFERROR(SUM(X4:X8),"—") -> 0 | Y9: =IFERROR(SUM(Y4:Y8),"—") -> 0
A10: # | B10: Prashant Ddugu | C10: S1 | D10: FY 25-26 | E10: TL | F10: =L10/2 -> 30.25 | G10: =SUM(G6:G7) -> 10.089205 | H10: =IFERROR(G10/F10,"-") -> 0.33352743 | I10: =L10/2 -> 30.25 | J10: - | K10: =IFERROR(J10/I10,"-") -> - | L10: ='[8]Prashant- TARGET LETTER - 26-27'!$D$9/10^7 -> 60.5 | M10: =SUM(G10,J10) -> 10.089205 | N10: =IFERROR(M10/L10,"-") -> 0.16676372 | O10: ='[8]Prashant- TARGET LETTER - 26-27'!$D$13/10^7 -> 89.5 | P10: - | Q10: =IFERROR(P10/O10,"-") -> - | R10: =SUM(L10,O10) -> 150 | S10: =M10 -> 10.089205 | T10: =IFERROR(S10/R10,"-") -> 0.067261366 | U10: 8
A12: S2 Division
A13: 1 | B13: Rohit Deshmukh | C13: S2 | D13: FY 25-26 | E13: IC | F13: =L13/2 -> 38 | G13: =SUMIF('[1]Opportunity Pipeline 1Apr to 21'!$F:$F,"Rohit Deshmukh",'[1]Opportunity Pipeline 1Apr to 21'!$O:$O)/10^7 -> 2.2807318 | H13: =IFERROR(G13/F13,"-") -> 0.060019257 | I13: =L13/2 -> 38 | J13: - | K13: =IFERROR(J13/I13,"-") -> - | L13: ='[9]Rohit- TARGET LETTER - 26-27'!$D$9/10^7 -> 76 | M13: =SUM(G13,J13) -> 2.2807318 | N13: =IFERROR(M13/L13,"-") -> 0.030009628 | O13: ='[9]Rohit- TARGET LETTER - 26-27'!$D$12/10^7 -> 59 | P13: - | Q13: =IFERROR(P13/O13,"-") -> - | R13: 135 | S13: =SUM(M13,P13) -> 2.2807318 | T13: =IFERROR(S13/R13,"-") -> 0.016894309 | U13: =COUNTIF([3]in!$F$1:$F$27,'V1 · Individual'!B13) -> #VALUE! | Z13: =IFERROR(RANK(S13,S13:S57,0),"-") -> -
A14: 2 | B14: Chetna Sharma | C14: S2 | D14: FY 25-26 | E14: IC | F14: =L14/2 -> 10 | G14: =SUMIF('[1]Opportunity Pipeline 1Apr to 21'!$F:$F,"Chetna Sharma",'[1]Opportunity Pipeline 1Apr to 21'!$O:$O)/10^7 -> 11.771069 | H14: =IFERROR(G14/F14,"-") -> 1.1771069 | I14: =L14/2 -> 10 | J14: - | K14: =IFERROR(J14/I14,"-") -> - | L14: ='[10]Chetna- TARGET LETTER - 26-27'!$D$9/10^7 -> 20 | M14: =SUM(G14,J14) -> 11.771069 | N14: =IFERROR(M14/L14,"-") -> 0.58855343 | O14: ='[10]Chetna- TARGET LETTER - 26-27'!$D$17/10^7 -> 49 | P14: - | Q14: =IFERROR(P14/O14,"-") -> - | R14: 69 | S14: =SUM(M14,P14) -> 11.771069 | T14: =IFERROR(S14/R14,"-") -> 0.1705952 | U14: =COUNTIF([3]in!$F$1:$F$27,'V1 · Individual'!B14) -> #VALUE! | Z14: =IFERROR(RANK(S14,S14:S58,0),"-") -> -
A15: 3 | B15: TBH (Varsha) | C15: S2 | D15: FY 25-26 | E15: IC | F15: 7.3 | G15: =SUMIF('[1]Opportunity Pipeline 1Apr to 21'!$F:$F,"Varsha",'[1]Opportunity Pipeline 1Apr to 21'!$O:$O)/10^7 -> 0 | H15: =IFERROR(G15/F15,"-") -> 0 | I15: 9.8 | J15: - | K15: =IFERROR(J15/I15,"-") -> - | L15: =SUM(F15,I15) -> 17.1 | M15: =SUM(G15,J15) -> 0 | N15: =IFERROR(M15/L15,"-") -> 0 | O15: - | P15: - | Q15: =IFERROR(P15/O15,"-") -> - | R15: 40.5 | S15: =SUM(M15,P15) -> 0 | T15: =IFERROR(S15/R15,"-") -> 0 | U15: =COUNTIF([3]in!$F$1:$F$27,'V1 · Individual'!B15) -> #VALUE! | Z15: =IFERROR(RANK(S15,S15:S59,0),"-") -> -
A16: 4 | B16: TBH (Arpit) | C16: S2 | D16: FY 25-26 | E16: IC | F16: 6.75 | G16: =SUMIF('[1]Opportunity Pipeline 1Apr to 21'!$F:$F,"Arpit",'[1]Opportunity Pipeline 1Apr to 21'!$O:$O)/10^7 -> 0 | H16: =IFERROR(G16/F16,"-") -> 0 | I16: 6.75 | J16: - | K16: =IFERROR(J16/I16,"-") -> - | L16: =SUM(F16,I16) -> 13.5 | M16: =SUM(G16,J16) -> 0 | N16: =IFERROR(M16/L16,"-") -> 0 | O16: - | P16: - | Q16: =IFERROR(P16/O16,"-") -> - | R16: 32.5 | S16: =SUM(M16,P16) -> 0 | T16: =IFERROR(S16/R16,"-") -> 0 | U16: =COUNTIF([3]in!$F$1:$F$27,'V1 · Individual'!B16) -> #VALUE! | Z16: =IFERROR(RANK(S16,S16:S60,0),"-") -> -
A17: 5 | B17: TBH (Dennis) | C17: S2 | D17: FY 25-26 | E17: IC | F17: 1.05 | G17: =SUMIF('[1]Opportunity Pipeline 1Apr to 21'!$F:$F,"Dennis",'[1]Opportunity Pipeline 1Apr to 21'!$O:$O)/10^7 -> 0 | H17: =IFERROR(G17/F17,"-") -> 0 | I17: 1.85 | J17: - | K17: =IFERROR(J17/I17,"-") -> - | L17: =SUM(F17,I17) -> 2.9 | M17: =SUM(G17,J17) -> 0 | N17: =IFERROR(M17/L17,"-") -> 0 | O17: - | P17: - | Q17: =IFERROR(P17/O17,"-") -> - | R17: 6 | S17: =SUM(M17,P17) -> 0 | T17: =IFERROR(S17/R17,"-") -> 0 | U17: =COUNTIF([3]in!$F$1:$F$27,'V1 · Individual'!B17) -> #VALUE! | Z17: =IFERROR(RANK(S17,S17:S61,0),"-") -> -
A18: 6 | B18: Sankeerth | C18: S2 | D18: FY 25-26 | E18: IC | F18: =L18/2 -> 5.875 | G18: =SUMIF('[1]Opportunity Pipeline 1Apr to 21'!$F:$F,"Sankeerth",'[1]Opportunity Pipeline 1Apr to 21'!$O:$O)/10^7 -> 0 | H18: =IFERROR(G18/F18,"-") -> 0 | I18: =L18/2 -> 5.875 | J18: - | K18: =IFERROR(J18/I18,"-") -> - | L18: ='[11]Sankeerth TARGET LETTER - 26-27'!$D$9/10^7 -> 11.75 | M18: =SUM(G18,J18) -> 0 | N18: =IFERROR(M18/L18,"-") -> 0 | O18: ='[11]Sankeerth TARGET LETTER - 26-27'!$D$15/10^7 -> 30.25 | P18: - | Q18: =IFERROR(P18/O18,"-") -> - | R18: 17 | S18: =SUM(M18,P18) -> 0 | T18: =IFERROR(S18/R18,"-") -> 0 | U18: =COUNTIF([3]in!$F$1:$F$27,'V1 · Individual'!B18) -> #VALUE! | Z18: =IFERROR(RANK(S18,S18:S62,0),"-") -> -
B19: IC Subtotal — S2 | F19: =SUM(F13,F14,F18) -> 53.875 | G19: =SUM(G13,G14,G18) -> 14.0518 | H19: =IFERROR(G19/F19,"-") -> 0.26082228 | I19: =SUM(I13,I14,I18) -> 53.875 | J19: =SUM(J13,J14,J18) -> 0 | K19: =SUM(K13,K14,K18) -> 0 | L19: =SUM(L13,L14,L18) -> 107.75 | M19: =SUM(M13,M14,M18) -> 14.0518 | N19: =IFERROR(M19/L19,"-") -> 0.13041114 | O19: =SUM(O13,O14,O18) -> 138.25 | P19: =SUM(P13,P14,P18) -> 0 | Q19: =SUM(Q13,Q14,Q18) -> 0 | R19: =SUM(R13,R14,R18) -> 221 | S19: =SUM(S13,S14,S18) -> 14.0518 | T19: =IFERROR(S19/R19,"-") -> 0.063582807 | U19: =SUM(U13,U14,U18) -> #VALUE! | V19: =SUM(V13,V14,V18) -> 0 | W19: =SUM(W13,W14,W18) -> 0 | X19: =SUM(X13,X14,X18) -> 0 | Y19: =SUM(Y13,Y14,Y18) -> 0 | Z19: =SUM(Z13,Z14,Z18) -> 0
P20: - | Q20: =IFERROR(P20/O20,"-") -> -
A21: CB Division
A22: 1 | B22: Darshana Patil | C22: CB | D22: FY 26-27 | E22: IC | F22: 3 | G22: =SUMIF('[1]Opportunity Pipeline 1Apr to 21'!$F:$F,"Darshana Patil",'[1]Opportunity Pipeline 1Apr to 21'!$O:$O)/10^7 -> 6.2075615 | H22: =IFERROR(G22/F22,"-") -> 2.0691872 | I22: 4 | J22: - | K22: - | L22: =SUM(F22,I22) -> 7 | M22: =SUMIF('[1]Opportunity Pipeline 1Apr to 21'!$F:$F,"Darshana Patil",'[1]Opportunity Pipeline 1Apr to 21'!$O:$O)/10^7 -> 6.2075615 | N22: =IFERROR(M22/L22,"-") -> 0.8867945 | P22: - | Q22: - | R22: =L22+O22 -> 7 | S22: =SUMIF([3]in!$F$1:$F$27,"Darshana Patil",[3]in!$O$1:$O$27)/10^7 -> #VALUE! | T22: =IFERROR(S22/R22,"-") -> - | U22: =COUNTIF([3]in!$F$1:$F$27,'V1 · Individual'!B22) -> #VALUE! | Z22: =IFERROR(RANK(S22,S22:S66,0),"-") -> -
A23: 2 | B23: Prachi Mayekar | C23: CB | D23: FY 26-27 | E23: IC | F23: =L23/2 -> 7.5 | G23: =SUMIF('[1]Opportunity Pipeline 1Apr to 21'!$F:$F,"Prachi Mayekar",'[1]Opportunity Pipeline 1Apr to 21'!$O:$O)/10^7 -> 12.897684 | H23: =IFERROR(G23/F23,"-") -> 1.7196913 | I23: =L23/2 -> 7.5 | J23: - | K23: - | L23: ='[12]Prachi TARGET LETTER - 26-27'!$D$9/10^7 -> 15 | M23: =SUM(G23,J23) -> 12.897684 | N23: =IFERROR(M23/L23,"-") -> 0.85984563 | O23: ='[12]Prachi TARGET LETTER - 26-27'!$D$10/10^7 -> 18 | P23: - | Q23: - | R23: =L23+O23 -> 33 | S23: =SUMIF([3]in!$F$1:$F$27,"Prachi Mayekar",[3]in!$O$1:$O$27)/10^7 -> #VALUE! | T23: =IFERROR(S23/R23,"-") -> - | U23: =COUNTIF([3]in!$F$1:$F$27,'V1 · Individual'!B23) -> #VALUE! | Z23: =IFERROR(RANK(S23,S23:S67,0),"-") -> -
A24: 3 | B24: Shilpa Kavde | C24: CB | D24: FY 26-27 | E24: IC | F24: =L24/2 -> 7.5 | G24: =SUMIF('[1]Opportunity Pipeline 1Apr to 21'!$F:$F,"Shilpa Kavde",'[1]Opportunity Pipeline 1Apr to 21'!$O:$O)/10^7 -> 2.8171414 | H24: =IFERROR(G24/F24,"-") -> 0.37561885 | I24: =L24/2 -> 7.5 | J24: - | K24: - | L24: ='[13]Shilpa TARGET LETTER - 26-27'!$D$9/10^7 -> 15 | M24: =SUM(G24,J24) -> 2.8171414 | N24: =IFERROR(M24/L24,"-") -> 0.18780942 | O24: ='[13]Shilpa TARGET LETTER - 26-27'!$D$10/10^7 -> 25 | P24: - | Q24: - | R24: =L24+O24 -> 40 | S24: =SUMIF([3]in!$F$1:$F$27,"Shilpa Kavde",[3]in!$O$1:$O$27)/10^7 -> #VALUE! | T24: =IFERROR(S24/R24,"-") -> - | U24: =COUNTIF([3]in!$F$1:$F$27,'V1 · Individual'!B24) -> #VALUE! | Z24: =IFERROR(RANK(S24,S24:S68,0),"-") -> -
A25: 4 | B25: Vidula Chavan | C25: CB | D25: FY 26-27 | E25: IC | F25: =L25/2 -> 1.5 | G25: =SUMIF('[1]Opportunity Pipeline 1Apr to 21'!$F:$F,"Vidula Chavan",'[1]Opportunity Pipeline 1Apr to 21'!$O:$O)/10^7 -> 0 | H25: =IFERROR(G25/F25,"-") -> 0 | I25: =L25/2 -> 1.5 | J25: - | K25: - | L25: ='[14]Vidula TARGET LETTER - 26-27'!$D$9/10^7 -> 3 | M25: =SUM(G25,J25) -> 0 | N25: =IFERROR(M25/L25,"-") -> 0 | O25: ='[14]Vidula TARGET LETTER - 26-27'!$D$10/10^7 -> 6.5 | P25: - | Q25: - | R25: =L25+O25 -> 9.5 | S25: =SUMIF([3]in!$F$1:$F$27,"Vidula Chavan",[3]in!$O$1:$O$27)/10^7 -> #VALUE! | T25: =IFERROR(S25/R25,"-") -> - | U25: =COUNTIF([3]in!$F$1:$F$27,'V1 · Individual'!B25) -> #VALUE! | Z25: =IFERROR(RANK(S25,S25:S69,0),"-") -> -
B26: IC Subtotal — CB | F26: =SUM(F23,F24,F25) -> 16.5 | G26: =SUM(G23,G24,G25) -> 15.714826 | H26: =SUM(H23,H24,H25) -> 2.0953101 | I26: =SUM(I23,I24,I25) -> 16.5 | J26: =SUM(J23,J24,J25) -> 0 | K26: =SUM(K23,K24,K25) -> 0 | L26: =SUM(L23,L24,L25) -> 33 | M26: =SUM(M23,M24,M25) -> 15.714826 | ... U26: =SUM(U23,U24,U25) -> #VALUE! | V26: =IFERROR(SUM(V22:V25),"—") -> 0 | W26: =IFERROR(SUM(W22:W25),"—") -> 0 | X26: =IFERROR(SUM(X22:X25),"—") -> 0 | Y26: =IFERROR(SUM(Y22:Y25),"—") -> 0
A27: # | B27: Jimesh Shah | C27: CB | D27: FY 25-26 | E27: TL | F27: =L27/2 -> 7.5 | G27: =SUMIF('[1]Opportunity Pipeline 1Apr to 21'!$F:$F,B27,'[1]Opportunity Pipeline 1Apr to 21'!$O:$O)/10^7 -> 0.0032 | H27: =IFERROR(G27/F27,"-") -> 0.00042666667 | I27: =L27/2 -> 7.5 | J27: - | K27: - | L27: ='[15]Jimesh TARGET LETTER - 26-27'!$D$9/10^7 -> 15 | M27: 0 | N27: =IFERROR(M27/L27,"-") -> 0 | O27: ='[15]Jimesh TARGET LETTER - 26-27'!$D$13/10^7 -> 30 | P27: - | Q27: - | R27: =L27+O27 -> 45 | S27: 0 | T27: 0 | U27: 0
A29: GB Division
A30: 1 | B30: Atharva Karpe | C30: GB | D30: FY 26-27 | E30: Generalist | F30: =L30/2 -> 2 | G30: =SUMIF('[1]Opportunity Pipeline 1Apr to 21'!$F:$F,"Atharva Karpe",'[1]Opportunity Pipeline 1Apr to 21'!$O:$O)/10^7 -> 4.6396697 | H30: =IFERROR(G30/F30,"-") -> 2.3198348 | I30: =L30/2 -> 2 | J30: - | K30: - | L30: ='[16]Atharva -TARGET LETTER - 26-27'!$D$9/10^7 -> 4 | M30: =SUMIF('[1]Opportunity Pipeline 1Apr to 21'!$F:$F,"Atharva Karpe",'[1]Opportunity Pipeline 1Apr to 21'!$O:$O)/10^7 -> 4.6396697 | N30: =IFERROR(M30/L30,"-") -> 1.1599174 | O30: ='[16]Atharva -TARGET LETTER - 26-27'!$D$10/10^7 -> 4 | P30: - | Q30: - | R30: =L30+O30 -> 8 | S30: =SUMIF([3]in!$F$1:$F$27,"Atharva Karpe",[3]in!$O$1:$O$27)/10^7 -> #VALUE! | T30: =IFERROR(S30/R30,"-") -> - | U30: =COUNTIF([3]in!$F$1:$F$27,'V1 · Individual'!B30) -> #VALUE! | Z30: =IFERROR(RANK(S30,S30:S73,0),"-") -> -
A31: 2 | B31: Jay Rushi | C31: GB | D31: FY 26-27 | E31: Generalist | F31: =L31/2 -> 1.5 | G31: =SUMIF('[1]Opportunity Pipeline 1Apr to 21'!$F:$F,"Jay Rushi",'[1]Opportunity Pipeline 1Apr to 21'!$O:$O)/10^7 -> 1.4900934 | H31: =IFERROR(G31/F31,"-") -> 0.9933956 | I31: =L31/2 -> 1.5 | J31: - | K31: - | L31: ='[17]Jay Rushi TARGET LETTER - 26-27'!$D$9/10^7 -> 3 | M31: =SUMIF('[1]Opportunity Pipeline 1Apr to 21'!$F:$F,"Jay Rushi",'[1]Opportunity Pipeline 1Apr to 21'!$O:$O)/10^7 -> 1.4900934 | N31: =IFERROR(M31/L31,"-") -> 0.4966978 | O31: ='[17]Jay Rushi TARGET LETTER - 26-27'!$D$10/10^7 -> 5 | P31: - | Q31: - | R31: =L31+O31 -> 8 | S31: =SUMIF([3]in!$F$1:$F$27,"Jay Rushi",[3]in!$O$1:$O$27)/10^7 -> #VALUE! | T31: =IFERROR(S31/R31,"-") -> - | U31: =COUNTIF([3]in!$F$1:$F$27,'V1 · Individual'!B31) -> #VALUE! | Z31: =IFERROR(RANK(S31,S31:S74,0),"-") -> -
A32: 3 | B32: Ayushaman | C32: GB, CS | D32: FY 26-27 | E32: Specialist | F32: =L32/2 -> 1.5 | G32: =SUMIF('[1]Opportunity Pipeline 1Apr to 21'!$F:$F,"Ayushaman",'[1]Opportunity Pipeline 1Apr to 21'!$O:$O)/10^7 -> 0 | H32: =IFERROR(G32/F32,"-") -> 0 | I32: =L32/2 -> 1.5 | J32: - | K32: - | L32: ='[18]Ayushman-TARGET LETTER - 26-27'!$D$9/10^7 -> 3 | M32: =SUMIF('[1]Opportunity Pipeline 1Apr to 21'!$F:$F,"Ayushaman",'[1]Opportunity Pipeline 1Apr to 21'!$O:$O)/10^7 -> 0 | N32: =IFERROR(M32/L32,"-") -> 0 | O32: ='[18]Ayushman-TARGET LETTER - 26-27'!$D$10/10^7 -> 9 | P32: - | Q32: - | R32: =L32+O32 -> 12 | S32: =SUMIF([3]in!$F$1:$F$27,"Ayushaman",[3]in!$O$1:$O$27)/10^7 -> #VALUE! | T32: =IFERROR(S32/R32,"-") -> - | U32: =COUNTIF([3]in!$F$1:$F$27,'V1 · Individual'!B32) -> #VALUE! | Z32: =IFERROR(RANK(S32,S32:S75,0),"-") -> -
A33: 4 | B33: Shubhangi | C33: GB, CS | D33: FY 26-27 | E33: Specialist | F33: =L33/2 -> 2.5 | G33: =SUMIF('[1]Opportunity Pipeline 1Apr to 21'!$F:$F,"Shubhangi",'[1]Opportunity Pipeline 1Apr to 21'!$O:$O)/10^7 -> 0 | H33: =IFERROR(G33/F33,"-") -> 0 | I33: =L33/2 -> 2.5 | J33: - | K33: - | L33: ='[19]Shubhangi-TARGET LETTER - 26-27'!$D$9/10^7 -> 5 | M33: =SUMIF('[1]Opportunity Pipeline 1Apr to 21'!$F:$F,"Shubhangi",'[1]Opportunity Pipeline 1Apr to 21'!$O:$O)/10^7 -> 0 | N33: =IFERROR(M33/L33,"-") -> 0 | O33: ='[19]Shubhangi-TARGET LETTER - 26-27'!$D$10/10^7 -> 10 | P33: - | Q33: - | R33: =L33+O33 -> 15 | S33: =SUMIF([3]in!$F$1:$F$27,"Shubhangi",[3]in!$O$1:$O$27)/10^7 -> #VALUE! | T33: =IFERROR(S33/R33,"-") -> - | U33: =COUNTIF([3]in!$F$1:$F$27,'V1 · Individual'!B33) -> #VALUE! | Z33: =IFERROR(RANK(S33,S33:S76,0),"-") -> -
A34: 5 | B34: Bhumi | C34: GB | D34: FY 26-27 | E34: PS ISR/OSR | F34: =L34/2 -> 0.3 | G34: =SUMIF('[1]Opportunity Pipeline 1Apr to 21'!$F:$F,"Bhumi",'[1]Opportunity Pipeline 1Apr to 21'!$O:$O)/10^7 -> 0 | H34: =IFERROR(G34/F34,"-") -> 0 | I34: =L34/2 -> 0.3 | J34: - | K34: - | L34: ='[20]Bhumi Target Letter 26 27 '!$D$9/10^7 -> 0.6 | M34: =SUMIF('[1]Opportunity Pipeline 1Apr to 21'!$F:$F,"Bhumi",'[1]Opportunity Pipeline 1Apr to 21'!$O:$O)/10^7 -> 0 | N34: =IFERROR(M34/L34,"-") -> 0 | O34: ='[20]Bhumi Target Letter 26 27 '!$D$10/10^7 -> 1.4 | P34: - | Q34: - | R34: =L34+O34 -> 2 | S34: =SUMIF([3]in!$F$1:$F$27,"Bhumi",[3]in!$O$1:$O$27)/10^7 -> #VALUE! | T34: =IFERROR(S34/R34,"-") -> - | U34: =COUNTIF([3]in!$F$1:$F$27,'V1 · Individual'!B34) -> #VALUE! | Z34: =IFERROR(RANK(S34,S34:S77,0),"-") -> -
A35: 6 | B35: Suyesh | C35: GB | D35: FY 26-27 | E35: PS ISR/OSR | F35: =L35/2 -> 0.3 | G35: =SUMIF('[1]Opportunity Pipeline 1Apr to 21'!$F:$F,"Suyesh",'[1]Opportunity Pipeline 1Apr to 21'!$O:$O)/10^7 -> 0 | H35: =IFERROR(G35/F35,"-") -> 0 | I35: =L35/2 -> 0.3 | J35: - | K35: - | L35: ='[21]Suvesh- Target Letter 26 27 '!$D$9/10^7 -> 0.6 | M35: =SUMIF('[1]Opportunity Pipeline 1Apr to 21'!$F:$F,"Suyesh",'[1]Opportunity Pipeline 1Apr to 21'!$O:$O)/10^7 -> 0 | N35: =IFERROR(M35/L35,"-") -> 0 | O35: ='[21]Suvesh- Target Letter 26 27 '!$D$10/10^7 -> 1.4 | P35: - | Q35: - | R35: =L35+O35 -> 2 | S35: =SUMIF([3]in!$F$1:$F$27,"Suyesh",[3]in!$O$1:$O$27)/10^7 -> #VALUE! | T35: =IFERROR(S35/R35,"-") -> - | U35: =COUNTIF([3]in!$F$1:$F$27,'V1 · Individual'!B35) -> #VALUE! | Z35: =IFERROR(RANK(S35,S35:S78,0),"-") -> -
A36: 7 | B36: Ashish Singh | C36: GB, Cloud & PS | D36: FY 26-27 | E36: Cloud/PS | F36: =L36/2 -> 2.5 | G36: =SUMIF('[1]Opportunity Pipeline 1Apr to 21'!$F:$F,"Ashish Singh",'[1]Opportunity Pipeline 1Apr to 21'!$O:$O)/10^7 -> 1.3021986 | H36: =IFERROR(G36/F36,"-") -> 0.52087944 | I36: =L36/2 -> 2.5 | J36: - | K36: - | L36: ='[22]Ashish Target Letter 26 27 '!$D$9/10^7 -> 5 | M36: =SUMIF('[1]Opportunity Pipeline 1Apr to 21'!$F:$F,"Ashish Singh",'[1]Opportunity Pipeline 1Apr to 21'!$O:$O)/10^7 -> 1.3021986 | N36: =IFERROR(M36/L36,"-") -> 0.26043972 | O36: ='[22]Ashish Target Letter 26 27 '!$D$10/10^7 -> 10 | P36: - | Q36: - | R36: =L36+O36 -> 15 | S36: =SUMIF([3]in!$F$1:$F$27,"Ashish Singh",[3]in!$O$1:$O$27)/10^7 -> #VALUE! | T36: =IFERROR(S36/R36,"-") -> - | U36: =COUNTIF([3]in!$F$1:$F$27,'V1 · Individual'!B36) -> #VALUE! | Z36: =IFERROR(RANK(S36,S36:S79,0),"-") -> -
A37: 8 | B37: Rizwana | C37: GB | D37: FY 26-27 | E37: Cloud/PS | F37: =L37/2 -> 0.75 | G37: =SUMIF('[1]Opportunity Pipeline 1Apr to 21'!$F:$F,"Rizwana",'[1]Opportunity Pipeline 1Apr to 21'!$O:$O)/10^7 -> 0 | H37: =IFERROR(G37/F37,"-") -> 0 | I37: =L37/2 -> 0.75 | J37: - | K37: - | L37: ='[23]Rizwana Target Letter 26 27 '!$D$9/10^7 -> 1.5 | M37: =SUMIF('[1]Opportunity Pipeline 1Apr to 21'!$F:$F,"Rizwana",'[1]Opportunity Pipeline 1Apr to 21'!$O:$O)/10^7 -> 0 | N37: =IFERROR(M37/L37,"-") -> 0 | O37: ='[23]Rizwana Target Letter 26 27 '!$D$10/10^7 -> 3.5 | P37: - | Q37: - | R37: =L37+O37 -> 5 | S37: =SUMIF([3]in!$F$1:$F$27,"Rizwana",[3]in!$O$1:$O$27)/10^7 -> #VALUE! | T37: =IFERROR(S37/R37,"-") -> - | U37: =COUNTIF([3]in!$F$1:$F$27,'V1 · Individual'!B37) -> #VALUE! | Z37: =IFERROR(RANK(S37,S37:S80,0),"-") -> -
B38: IC Subtotal — GB | F38: =SUM(F30:F37) -> 11.35 | G38: =SUM(G30:G37) -> 7.4319617 | H38: =IFERROR(G38/F38,"-") -> 0.65479839 | I38: =SUM(I30:I37) -> 11.35 | J38: - | K38: - | L38: =SUM(L30:L37) -> 22.7 | M38: =SUM(M30:M37) -> 7.4319617 | N38: =IFERROR(M38/L38,"-") -> 0.32739919 | O38: =SUM(O30:O37) -> 44.3 | P38: - | Q38: - | R38: =SUM(R30:R37) -> 67 | S38: =SUM(S30:S37) -> #VALUE! | T38: =IFERROR(S38/R38,"-") -> - | U38: =IFERROR(SUM(U30:U37),"—") -> — | V38: =IFERROR(SUM(V30:V37),"—") -> 0 | W38: =IFERROR(SUM(W30:W37),"—") -> 0 | X38: =IFERROR(SUM(X30:X37),"—") -> 0 | Y38: =IFERROR(SUM(Y30:Y37),"—") -> 0
A40: South Division
A41: 1 | B41: Abrar Memon | C41: South | D41: FY 26-27 | E41: IC | F41: =L41/2 -> 2 | G41: =SUMIF('[1]Opportunity Pipeline 1Apr to 21'!$F:$F,"Abrar Memon",'[1]Opportunity Pipeline 1Apr to 21'!$O:$O)/10^7 -> 0.041457089 | H41: =IFERROR(G41/F41,"-") -> 0.020728545 | I41: =L41/2 -> 2 | J41: - | K41: - | L41: ='[24]Abrar TARGET LETTER - 26-27'!$D$9/10^7 -> 4 | M41: =SUMIF('[1]Opportunity Pipeline 1Apr to 21'!$F:$F,"Abrar Memon",'[1]Opportunity Pipeline 1Apr to 21'!$O:$O)/10^7 -> 0.041457089 | N41: =IFERROR(M41/L41,"-") -> 0.010364272 | O41: ='[24]Abrar TARGET LETTER - 26-27'!$D$10/10^7 -> 4 | P41: - | Q41: - | R41: =L41+O41 -> 8 | S41: =SUMIF([3]in!$F$1:$F$27,"Abrar Memon",[3]in!$O$1:$O$27)/10^7 -> #VALUE! | T41: =IFERROR(S41/R41,"-") -> - | U41: =COUNTIF([3]in!$F$1:$F$27,'V1 · Individual'!B41) -> #VALUE! | Z41: =IFERROR(RANK(S41,S41:S84,0),"-") -> -
A42: 2 | B42: Sagar TR | C42: South | D42: FY 26-27 | E42: IC | F42: =L42/2 -> 2.5 | G42: =SUMIF('[1]Opportunity Pipeline 1Apr to 21'!$F:$F,"Sagar TR",'[1]Opportunity Pipeline 1Apr to 21'!$O:$O)/10^7 -> 0.91994411 | H42: =IFERROR(G42/F42,"-") -> 0.36797764 | I42: =L42/2 -> 2.5 | J42: - | K42: - | L42: ='[25]Sagar- TARGET LETTER - 26-27'!$D$9/10^7 -> 5 | M42: =SUMIF('[1]Opportunity Pipeline 1Apr to 21'!$F:$F,"Sagar TR",'[1]Opportunity Pipeline 1Apr to 21'!$O:$O)/10^7 -> 0.91994411 | N42: =IFERROR(M42/L42,"-") -> 0.18398882 | O42: ='[25]Sagar- TARGET LETTER - 26-27'!$D$10/10^7 -> 5 | P42: - | Q42: - | R42: =L42+O42 -> 10 | S42: =SUMIF([3]in!$F$1:$F$27,"Sagar TR",[3]in!$O$1:$O$27)/10^7 -> #VALUE! | T42: =IFERROR(S42/R42,"-") -> - | U42: =COUNTIF([3]in!$F$1:$F$27,'V1 · Individual'!B42) -> #VALUE! | Z42: =IFERROR(RANK(S42,S42:S85,0),"-") -> -
A43: 3 | B43: Shahbaz Khan | C43: South | D43: FY 26-27 | E43: IC | F43: =L43/2 -> 3 | G43: =SUMIF('[1]Opportunity Pipeline 1Apr to 21'!$F:$F,"Shahbaz Khan",'[1]Opportunity Pipeline 1Apr to 21'!$O:$O)/10^7 -> 3.8053236 | H43: =IFERROR(G43/F43,"-") -> 1.2684412 | I43: =L43/2 -> 3 | J43: - | K43: - | L43: ='[26]Shahbaz - TARGET LETTER - 26-27'!$D$9/10^7 -> 6 | M43: =SUMIF('[1]Opportunity Pipeline 1Apr to 21'!$F:$F,"Shahbaz Khan",'[1]Opportunity Pipeline 1Apr to 21'!$O:$O)/10^7 -> 3.8053236 | N43: =IFERROR(M43/L43,"-") -> 0.6342206 | O43: ='[26]Shahbaz - TARGET LETTER - 26-27'!$D$10/10^7 -> 6 | P43: - | Q43: - | R43: =L43+O43 -> 12 | S43: =SUMIF([3]in!$F$1:$F$27,"Shahbaz Khan",[3]in!$O$1:$O$27)/10^7 -> #VALUE! | T43: =IFERROR(S43/R43,"-") -> - | U43: =COUNTIF([3]in!$F$1:$F$27,'V1 · Individual'!B43) -> #VALUE! | Z43: =IFERROR(RANK(S43,S43:S87,0),"-") -> -
...

Sheet V2 · Leaders
A1: VIEW 2 — LEADERSHIP CONTRIBUTION | Booking (Revenue) | H1 & Annual
A2: # | B2: Employee Name | C2: Division | D2: FY | E2: Type / Notes | F2: Q1 Quota (₹ Cr) | G2: Q1 Actuals (₹ Cr) | H2: Attainment % (Q1) | I2: Q2 Quota (₹ Cr) | J2: Q2 Actuals (₹ Cr) | K2: Attainment % (Q2) | L2: H1 Quota (₹ Cr) | M2: H1 Actuals (₹ Cr) | N2: Attainment % (H1) | O2: H2 Quota (₹ Cr) | P2: H2 Actuals (₹ Cr) | Q2: Attainment % (H2) | R2: Annual Quota (₹ Cr) | S2: Annual Actuals (₹ Cr) | T2: Attainment % (Annual) | U2: # Deals (Total) | V2: Led-By Deals (count) | W2: Led-By Rev (₹ Cr) | X2: Contributed Deals (count) | Y2: Contributed Rev (₹ Cr) | Z2: Rank (Div.)
A3: 1 | B3: Ajay Patodia | C3: DCG | D3: FY 26-27 | E3: BU HEAD | F3: - | G3: 0.037419355 | H3: - | I3: - | J3: - | K3: - | L3: =SUM(F3,I3) -> 0 | M3: =SUM(G3,J3) -> 0.037419355 | N3: - | O3: - | P3: - | Q3: - | R3: - | S3: 0.037419355 | T3: =IFERROR(S3/R3,"-") -> - | U3: 1
A4: 2 | B4: Jimesh Shah | C4: CB | D4: FY 26-27 | E4: Team Lead | F4: =L4/2 -> 7.5 | G4: - | H4: - | I4: =L4/2 -> 7.5 | J4: - | K4: - | L4: ='[15]Jimesh TARGET LETTER - 26-27'!$D$9/10^7 -> 15 | M4: - | N4: - | O4: ='[15]Jimesh TARGET LETTER - 26-27'!$D$13/10^7 -> 30 | P4: - | Q4: - | R4: =L4+O4 -> 45 | S4: - | T4: - | U4: 0
A5: 3 | B5: Rima Kamalakar Ingle | C5: GB | D5: FY 26-27 | E5: Manager - Sales and Business Development - Cloud/PS - Specialist | F5: =L5/2 -> 1.5 | G5: - | H5: - | I5: =L5/2 -> 1.5 | J5: - | K5: - | L5: ='[27]Rima Target Letter 26 27 '!$D$9/10^7 -> 3 | M5: - | N5: - | O5: ='[27]Rima Target Letter 26 27 '!$D$10/10^7 -> 5 | P5: - | Q5: - | R5: =L5+O5 -> 8 | S5: - | T5: - | U5: 0
A6: 4 | B6: Sana Rashid Bhatkar | C6: GB | D6: FY 26-27 | E6: Team Lead | F6: =L6/2 -> 1.6 | G6: - | H6: - | I6: =L6/2 -> 1.6 | J6: - | K6: - | L6: ='[28]SANA -TARGET LETTER - 26-27'!$D$9/10^7 -> 3.2 | M6: - | N6: - | O6: ='[28]SANA -TARGET LETTER - 26-27'!$D$14/10^7 -> 6.8 | P6: - | Q6: - | R6: =L6+O6 -> 10 | S6: - | T6: - | U6: 0

Sheet V2 · Team Quota
A1: VIEW 2 — TEAM QUOTA | Team Lead vs Company Target | H1 & Annual
A2: TL quotas are AGGREGATES — do not add to IC subtotals. Actuals placeholders in yellow.
A3: # | B3: Team Lead Name | C3: Division | D3: H1 Team Quota (₹ Cr) | E3: H1 Team Actuals (₹ Cr) | F3: H1 vs Co. Target | G3: H1 Flag | H3: Annual Team Quota (₹ Cr) | I3: Annual Team Actuals (₹ Cr) | J3: Annual vs Co. Target | K3: Annual Flag | L3: # Deals (Team) | M3: TL Notes
A4: 1 | B4: Prashant Ramchandra Dudugu | C4: S1 | D4: 48.25 | F4: =IFERROR(E4/459.35,"-") -> 0 | G4: =IF(ISNUMBER(E4),IF(E4>=D4,"✅ Hit","🔴 Behind"),"—") -> — | H4: 120 | J4: =IFERROR(I4/1017.5,"-") -> 0 | K4: =IF(ISNUMBER(I4),IF(I4>=H4,"✅ Hit","🔴 Behind"),"—") -> — | M4: Covers Chirag & Richa (excl. TBH)
A5: 2 | B5: Jimesh Shah | C5: CB | D5: 16.67 | F5: =IFERROR(E5/459.35,"-") -> 0 | G5: =IF(ISNUMBER(E5),IF(E5>=D5,"✅ Hit","🔴 Behind"),"—") -> — | H5: 50 | J5: =IFERROR(I5/1017.5,"-") -> 0 | K5: =IF(ISNUMBER(I5),IF(I5>=H5,"✅ Hit","🔴 Behind"),"—") -> — | M5: Incl. own (40.5 Cr) + Vidula Chavan (9.5 Cr)
A6: 3 | B6: Sanjeev Kohli | C6: GeoX | D6: 7.5 | F6: =IFERROR(E6/459.35,"-") -> 0 | G6: =IF(ISNUMBER(E6),IF(E6>=D6,"✅ Hit","🔴 Behind"),"—") -> — | H6: 20 | J6: =IFERROR(I6/1017.5,"-") -> 0 | K6: =IF(ISNUMBER(I6),IF(I6>=H6,"✅ Hit","🔴 Behind"),"—") -> — | M6: Covers Hrushikesh Bagade only (excl. TBH)
A8: Company Target Reference (all ICs, revenue basis, GeoX excl.)
A9: 1 | B9: Company H1 Target | C9: — | D9: 459.35 | E9: — | F9: — | G9: — | H9: 1017.5 | I9: — | J9: — | K9: — | L9: — | M9: Grand total all IC quota

Sheet V3 · RTM Division level
A1: VIEW 3 — SUMMARY OUTLOOK | BU Roll-up | Revenue + Bottomline (BL) | H1 & Annual
A2: Level / Name | B2: Division | C2: Q1 — Revenue (₹ Cr) | F2: Q1 — Bottomline (₹ Cr) | I2: Q2 — Revenue (₹ Cr) | L2: Q2 — Bottomline (₹ Cr) | O2: H1 — Revenue (₹ Cr) | R2: H1 — Bottomline (₹ Cr) | U2: H1 # Deals | V2: H2 — Revenue (₹ Cr) | Y2: H2 — Bottomline (₹ Cr) | AB2: H2 # Deals | AC2: Annual — Revenue (₹ Cr) | AF2: Annual — Bottomline (₹ Cr) | AI2: Ann # Deals
A3: Level | B3: Div. | C3: Quota | D3: Actuals | E3: Att% | F3: Quota | G3: Actuals | H3: Att% | I3: Quota | J3: Actuals | K3: Att% | L3: Quota | M3: Actuals | N3: Att% | O3: Quota | P3: Actuals | Q3: Att% | R3: Quota | S3: Actuals | T3: Att% | U3: Count | V3: Quota | W3: Actuals | X3: Att% | Y3: Quota | Z3: Actuals | AA3: Att% | AB3: Count | AC3: Quota | AD3: Actuals | AE3: Att% | AF3: Quota | AG3: Actuals | AH3: Att% | AI3: Count
A4: (i) Individual — IC Level
A5: Tasneem Mohammed Atif Ansari | B5: S1 | O5: 130.35 | Q5: =IFERROR(P5/O5,"-") -> 0 | T5: =IFERROR(S5/R5,"-") -> - | V5: 260 | X5: =IFERROR(W5/V5,"-") -> 0 | AA5: =IFERROR(Z5/Y5,"-") -> -
A6: Riya Roshyara | B6: S1 | O6: 58 | Q6: =IFERROR(P6/O6,"-") -> 0 | T6: =IFERROR(S6/R6,"-") -> - | V6: 120 | X6: =IFERROR(W6/V6,"-") -> 0 | AA6: =IFERROR(Z6/Y6,"-") -> -
A7: Chirag Sudhir Palande | B7: S1 | O7: 23 | Q7: =IFERROR(P7/O7,"-") -> 0 | T7: =IFERROR(S7/R7,"-") -> - | V7: 60 | X7: =IFERROR(W7/V7,"-") -> 0 | AA7: =IFERROR(Z7/Y7,"-") -> -
A8: Richa Tiwari | B8: S1 | O8: 25.25 | Q8: =IFERROR(P8/O8,"-") -> 0 | T8: =IFERROR(S8/R8,"-") -> - | V8: 60 | X8: =IFERROR(W8/V8,"-") -> 0 | AA8: =IFERROR(Z8/Y8,"-") -> -
A9: Pratik Vilas Kadam | B9: S1 | O9: 5 | Q9: =IFERROR(P9/O9,"-") -> 0 | T9: =IFERROR(S9/R9,"-") -> - | V9: 10 | X9: =IFERROR(W9/V9,"-") -> 0 | AA9: =IFERROR(Z9/Y9,"-") -> -
A10: Rohit | B10: S2 | O10: 76 | Q10: =IFERROR(P10/O10,"-") -> 0 | T10: =IFERROR(S10/R10,"-") -> - | V10: 135 | X10: =IFERROR(W10/V10,"-") -> 0 | AA10: =IFERROR(Z10/Y10,"-") -> -
A11: Chetna | B11: S2 | O11: 20 | Q11: =IFERROR(P11/O11,"-") -> 0 | T11: =IFERROR(S11/R11,"-") -> - | V11: 69 | X11: =IFERROR(W11/V11,"-") -> 0 | AA11: =IFERROR(Z11/Y11,"-") -> -
A12: Varsha | B12: S2 | O12: 20.3 | Q12: =IFERROR(P12/O12,"-") -> 0 | T12: =IFERROR(S12/R12,"-") -> - | V12: 40.5 | X12: =IFERROR(W12/V12,"-") -> 0 | AA12: =IFERROR(Z12/Y12,"-") -> -
A13: Arpit | B13: S2 | O13: 8 | Q13: =IFERROR(P13/O13,"-") -> 0 | T13: =IFERROR(S13/R13,"-") -> - | V13: 32.5 | X13: =IFERROR(W13/V13,"-") -> 0 | AA13: =IFERROR(Z13/Y13,"-") -> -
A14: Dennis | B14: S2 | O14: 3 | Q14: =IFERROR(P14/O14,"-") -> 0 | T14: =IFERROR(S14/R14,"-") -> - | V14: 6 | X14: =IFERROR(W14/V14,"-") -> 0 | AA14: =IFERROR(Z14/Y14,"-") -> -
A15: Sankeerth | B15: S2 | O15: 6.75 | Q15: =IFERROR(P15/O15,"-") -> 0 | T15: =IFERROR(S15/R15,"-") -> - | V15: 17 | X15: =IFERROR(W15/V15,"-") -> 0 | AA15: =IFERROR(Z15/Y15,"-") -> -
A16: Darshana Patil | B16: CB | O16: 7 | Q16: =IFERROR(P16/O16,"-") -> 0 | T16: =IFERROR(S16/R16,"-") -> - | V16: 16 | X16: =IFERROR(W16/V16,"-") -> 0 | AA16: =IFERROR(Z16/Y16,"-") -> -
... A32: Hrushikesh Bagade | B32: GeoX | O32: 1.05 | Q32: =IFERROR(P32/O32,"-") -> 0 | T32: =IFERROR(S32/R32,"-") -> - | V32: 2.4 | X32: =IFERROR(W32/V32,"-") -> 0 | AA32: =IFERROR(Z32/Y32,"-") -> -
A33: (ii) Team Lead (RTM) Level
A34: Prashant Ramchandra Dudugu | B34: S1 | O34: 48.25 | Q34: =IFERROR(P34/O34,"-") -> 0 | T34: =IFERROR(S34/R34,"-") -> - | V34: 120 | X34: =IFERROR(W34/V34,"-") -> 0 | AA34: =IFERROR(Z34/Y34,"-") -> -
A35: Jimesh Shah | B35: CB | O35: 16.67 | Q35: =IFERROR(P35/O35,"-") -> 0 | T35: =IFERROR(S35/R35,"-") -> - | V35: 50 | X35: =IFERROR(W35/V35,"-") -> 0 | AA35: =IFERROR(Z35/Y35,"-") -> -
A36: Sanjeev Kohli | B36: GeoX | O36: 7.5 | Q36: =IFERROR(P36/O36,"-") -> 0 | T36: =IFERROR(S36/R36,"-") -> - | V36: 20 | X36: =IFERROR(W36/V36,"-") -> 0 | AA36: =IFERROR(Z36/Y36,"-") -> -
A37: (iii) RTM Division Level
A38: S1 Division Total | B38: S1 | C38: ='V1 · Individual'!F9 -> 123.425 | D38: ='V1 · Individual'!G9 -> 26.76276 | E38: =IFERROR(D38/C38,"-") -> 0.21683419 | F38: - | G38: - | H38: - | I38: ='V1 · Individual'!I9 -> 123.425 | J38: - | K38: - | L38: - | M38: - | N38: - | O38: =SUM(C38,I38) -> 246.85 | P38: =+'V1 · Individual'!M9 -> 26.76276 | Q38: =IFERROR(P38/O38,"-") -> 0.10841709 | R38: - | S38: - | T38: - | U38: =+'V1 · Individual'!U9 -> #VALUE! | V38: ='V1 · Individual'!O9 -> 263.15 | W38: - | X38: - | Y38: - | Z38: - | AA38: - | AB38: - | AC38: =O38+V38 -> 510 | AD38: =+'V1 · Individual'!S9 -> 26.76276 | AE38: =IFERROR(AD38/AC38,"-") -> 0.052475999 | AF38: - | AG38: - | AH38: - | AI38: 10
A39: S2 Division Total | B39: S2 | C39: ='V1 · Individual'!F19 -> 53.875 | D39: ='V1 · Individual'!G19 -> 14.0518 | E39: =IFERROR(D39/C39,"-") -> 0.26082228 | F39: - | G39: - | H39: - | I39: ='V1 · Individual'!I19 -> 53.875 | J39: - | K39: - | L39: - | M39: - | N39: - | O39: =SUM(C39,I39) -> 107.75 | P39: =+'V1 · Individual'!M19 -> 14.0518 | Q39: =IFERROR(P39/O39,"-") -> 0.13041114 | R39: - | S39: - | T39: - | U39: =+'V1 · Individual'!U19 -> #VALUE! | V39: ='V1 · Individual'!O19 -> 138.25 | W39: - | X39: - | Y39: - | Z39: - | AA39: - | AB39: - | AC39: =O39+V39 -> 246 | AD39: =+'V1 · Individual'!S19 -> 14.0518 | AE39: =IFERROR(AD39/AC39,"-") -> 0.05712114 | AF39: - | AG39: - | AH39: - | AI39: 2
A40: CB Division Total | B40: CB | C40: ='V1 · Individual'!F26 -> 16.5 | D40: ='V1 · Individual'!G26 -> 15.714826 | E40: =IFERROR(D40/C40,"-") -> 0.95241368 | F40: - | G40: - | H40: - | I40: ='V1 · Individual'!I26 -> 16.5 | J40: - | K40: - | L40: - | M40: - | N40: - | O40: =SUM(C40,I40) -> 33 | P40: =+'V1 · Individual'!M26 -> 15.714826 | Q40: =IFERROR(P40/O40,"-") -> 0.47620684 | R40: - | S40: - | T40: - | U40: =+'V1 · Individual'!U26 -> #VALUE! | V40: ='V1 · Individual'!O26 -> 49.5 | W40: - | X40: - | Y40: - | Z40: - | AA40: - | AB40: - | AC40: =O40+V40 -> 82.5 | AD40: =+'V1 · Individual'!S26 -> #VALUE! | AE40: =IFERROR(AD40/AC40,"-") -> - | AF40: - | AG40: - | AH40: - | AI40: 0
A41: GB Division Total | B41: GB | C41: ='V1 · Individual'!F38 -> 11.35 | D41: ='V1 · Individual'!G38 -> 7.4319617 | E41: =IFERROR(D41/C41,"-") -> 0.65479839 | F41: - | G41: - | H41: - | I41: ='V1 · Individual'!I38 -> 11.35 | J41: - | K41: - | L41: - | M41: - | N41: - | O41: =SUM(C41,I41) -> 22.7 | P41: =+'V1 · Individual'!M38 -> 7.4319617 | Q41: =IFERROR(P41/O41,"-") -> 0.32739919 | R41: - | S41: - | T41: - | U41: =+'V1 · Individual'!U38 -> — | V41: ='V1 · Individual'!O38 -> 44.3 | W41: - | X41: - | Y41: - | Z41: - | AA41: - | AB41: - | AC41: =O41+V41 -> 67 | AD41: =+'V1 · Individual'!S38 -> #VALUE! | AE41: =IFERROR(AD41/AC41,"-") -> - | AF41: - | AG41: - | AH41: - | AI41: 3
A42: South Division Total | B42: South | C42: ='V1 · Individual'!F44 -> 7.5 | D42: ='V1 · Individual'!G44 -> 4.7667248 | E42: =IFERROR(D42/C42,"-") -> 0.63556331 | F42: - | G42: - | H42: - | I42: ='V1 · Individual'!I44 -> 7.5 | J42: - | K42: - | L42: - | M42: - | N42: - | O42: =SUM(C42,I42) -> 15 | P42: =+'V1 · Individual'!M44 -> 4.7667248 | Q42: =IFERROR(P42/O42,"-") -> 0.31778165 | R42: - | S42: - | T42: - | U42: =+'V1 · Individual'!U44 -> — | V42: ='V1 · Individual'!O44 -> 15 | W42: - | X42: - | Y42: - | Z42: - | AA42: - | AB42: - | AC42: =O42+V42 -> 30 | AD42: =+'V1 · Individual'!S44 -> #VALUE! | AE42: =IFERROR(AD42/AC42,"-") -> - | AF42: - | AG42: - | AH42: - | AI42: 5
A43: (iv) Company — Grand Total
A44: COMPANY TOTAL (Revenue IC, excl. GeoX BL) | B44: — | C44: =SUM(C38:C42) -> 212.65 | D44: =SUM(D38:D42) -> 68.728072 | E44: =IFERROR(D44/C44,"-") -> 0.32319808 | I44: =SUM(I38:I42) -> 212.65 | J44: - | K44: - | L44: - | M44: - | N44: - | O44: =SUM(C44,I44) -> 425.3 | P44: =SUM(D44,J44) -> 68.728072 | Q44: =IFERROR(P44/O44,"-") -> 0.16159904 | R44: - | S44: - | T44: - | U44: =SUM(U38:U42) -> #VALUE! | V44: =SUM(V38:V42) -> 510.2 | W44: - | X44: - | Y44: - | Z44: - | AA44: - | AB44: - | AC44: =SUM(AC38:AC42) -> 935.5 | AD44: =SUM(AD38:AD42) -> #VALUE! | AE44: =IFERROR(AD44/AC44,"-") -> - | AF44: - | AG44: - | AH44: =IFERROR(AG44/AF44,"-") -> - | AI44: =SUM(AI38:AI42) -> 20

Sheet V4 · BU Level
A1: VIEW 4 — SERVICE LEVEL CONTRIBUTION | Revenue + Bottomline | H1 & Annual
A3: Service / Sub-category | B3: BU | C3: H1 — Revenue (₹ Cr) | F3: H1 — Bottomline (₹ Cr) | I3: H1 Deals | J3: Annual — Revenue (₹ Cr) | M3: Annual Deals
A4: Service | B4: BU | C4: Quota | D4: Actuals | E4: Att% | F4: Quota | G4: Actuals | H4: Att% | I4: Count | J4: Quota | K4: Actuals | L4: Att% | M4: Count
A5: Data Centre | B5: DCG | C5: 40 | D5: 4.0924 | E5: =IFERROR(D5/C5,"-") -> 0.10231 | H5: =IFERROR(G5/F5,"-") -> - | I5: 5 | J5: 1005 | K5: =SUMIF([3]in!$K$1:$K$27,"Data Centre",[3]in!$O$1:$O$27)/10^7 -> #VALUE! | L5: =IFERROR(K5/J5,"-") -> - | M5: =COUNTIF([3]in!$K$1:$K$27,A5) -> #VALUE!
A6: Cyber Security & Networking | B6: CSN | C6: 38.75 | D6: 4.0481 | E6: =IFERROR(D6/C6,"-") -> 0.1044671 | H6: =IFERROR(G6/F6,"-") -> - | I6: 2 | J6: 310 | K6: =SUMIF([3]in!$K$1:$K$27,"Cyber Security & Networking",[3]in!$O$1:$O$27)/10^7 -> #VALUE! | L6: =IFERROR(K6/J6,"-") -> - | M6: =COUNTIF([3]in!$K$1:$K$27,A6) -> #VALUE!
A7: CSG (EndPoint) | B7: CSG | C7: 18.75 | D7: 2.029 | E7: =IFERROR(D7/C7,"-") -> 0.10821333 | H7: =IFERROR(G7/F7,"-") -> - | I7: 11 | J7: 75 | K7: =SUMIF([3]in!$K$1:$K$27,"CSG (EndPoint)",[3]in!$O$1:$O$27)/10^7 -> #VALUE! | L7: =IFERROR(K7/J7,"-") -> - | M7: =COUNTIF([3]in!$K$1:$K$27,A7) -> #VALUE!
A8: Professional Services | B8: PS | C8: 0 | D8: 0 | E8: =IFERROR(D8/C8,"-") -> - | H8: =IFERROR(G8/F8,"-") -> - | I8: 0 | J8: 22 | K8: =SUMIF([3]in!$K$1:$K$27,"Professional Services",[3]in!$O$1:$O$27)/10^7 -> #VALUE! | L8: =IFERROR(K8/J8,"-") -> - | M8: =COUNTIF([3]in!$K$1:$K$27,A8) -> #VALUE!
A9: Cloud | B9: Cloud | C9: 0 | D9: 0 | E9: =IFERROR(D9/C9,"-") -> - | H9: =IFERROR(G9/F9,"-") -> - | I9: 0 | J9: 21 | K9: =SUMIF([3]in!$K$1:$K$27,"Cloud",[3]in!$O$1:$O$27)/10^7 -> #VALUE! | L9: =IFERROR(K9/J9,"-") -> - | M9: =COUNTIF([3]in!$K$1:$K$27,A9) -> #VALUE!
A10: AI | B10: AI | C10: 0 | D10: 0 | E10: =IFERROR(D10/C10,"-") -> - | H10: =IFERROR(G10/F10,"-") -> - | I10: 0 | J10: 1 | K10: =SUMIF([3]in!$K$1:$K$27,"AI",[3]in!$O$1:$O$27)/10^7 -> #VALUE! | L10: =IFERROR(K10/J10,"-") -> - | M10: =COUNTIF([3]in!$K$1:$K$27,A10) -> #VALUE!
A12: TOTAL — All Services
A13: Grand Total | B13: — | C13: =IFERROR(SUM(C5:C11),"—") -> 97.5 | D13: =IFERROR(SUM(D5:D11),"—") -> 10.1695 | E13: — | F13: =IFERROR(SUM(F5:F11),"—") -> 0 | G13: =IFERROR(SUM(G5:G11),"—") -> 0 | H13: — | I13: =IFERROR(SUM(I5:I11),"—") -> 18 | J13: =IFERROR(SUM(J5:J11),"—") -> 1434 | K13: =IFERROR(SUM(K5:K11),"—") -> — | L13: =IFERROR(K13/J13,"-") -> - | M13: =IFERROR(SUM(M5:M11),"—") -> —

Sheet V5 · DCG
A1: VIEW 5 — RTM CONTRIBUTION | DCG | Booking (Revenue) | H1 & Annual
A2: # | B2: RTM Name | C2: Division | D2: FY | E2: Q1 Quota (₹ Cr) | F2: Q1 Actuals (₹ Cr) | G2: Attainment % (Q1) | H2: Q2 Quota (₹ Cr) | I2: Q2 Actuals (₹ Cr) | J2: Attainment % (Q2) | K2: H1 Quota (₹ Cr) | L2: H1 Actuals (₹ Cr) | M2: Attainment % (H1) | N2: Annual Quota (₹ Cr) | O2: Annual Actuals (₹ Cr) | P2: Attainment % (Annual) | Q2: # Deals (Total) | R2: Led-By Deals (count) | S2: Led-By Rev (₹ Cr) | T2: Contributed Deals (count) | U2: Contributed Rev (₹ Cr) | V2: Rank (Div.)
A3: 1 | B3: S1 Division Total | C3: S1 | D3: FY 25-26 | E3: - | F3: 0.035 | G3: =IFERROR(F3/E3,"-") -> - | H3: - | I3: - | J3: =IFERROR(I3/H3,"-") -> - | K3: - | L3: 0.035 | M3: =IFERROR(L3/K3,"-") -> - | N3: 455 | O3: 0.035 | P3: =IFERROR(O3/N3,"-") -> 7.6923077e-05 | Q3: 1 | R3: - | S3: - | T3: - | U3: - | V3: -
A4: 2 | B4: S2 Division Total | C4: S2 | D4: FY 25-26 | E4: - | F4: 3.9 | G4: =IFERROR(F4/E4,"-") -> - | H4: - | I4: - | J4: =IFERROR(I4/H4,"-") -> - | K4: - | L4: 3.9 | M4: =IFERROR(L4/K4,"-") -> - | N4: 225 | O4: 3.9 | P4: =IFERROR(O4/N4,"-") -> 0.017333333 | Q4: 2 | R4: - | S4: - | T4: - | U4: - | V4: -
A5: 3 | B5: CB Division Total | C5: CB | D5: FY 25-26 | E5: - | F5: 0 | G5: =IFERROR(F5/E5,"-") -> - | H5: - | I5: - | J5: =IFERROR(I5/H5,"-") -> - | K5: - | L5: 0 | M5: =IFERROR(L5/K5,"-") -> - | N5: 40 | O5: 0 | P5: =IFERROR(O5/N5,"-") -> 0 | Q5: 0 | R5: - | S5: - | T5: - | U5: - | V5: -
A6: 4 | B6: GB Division Total | C6: GB | D6: FY 25-26 | E6: - | F6: 0 | G6: =IFERROR(F6/E6,"-") -> - | H6: - | I6: - | J6: =IFERROR(I6/H6,"-") -> - | K6: - | L6: 0 | M6: =IFERROR(L6/K6,"-") -> - | N6: 11 | O6: 0 | P6: =IFERROR(O6/N6,"-") -> 0 | Q6: 0 | R6: - | S6: - | T6: - | U6: - | V6: -
A7: 5 | B7: South Division Total | C7: South | D7: FY 25-26 | E7: - | F7: 0.12 | G7: =IFERROR(F7/E7,"-") -> - | H7: - | I7: - | J7: =IFERROR(I7/H7,"-") -> - | K7: - | L7: 0.12 | M7: =IFERROR(L7/K7,"-") -> - | N7: 14 | O7: 0.12 | P7: =IFERROR(O7/N7,"-") -> 0.0085714286 | Q7: 1 | R7: - | S7: - | T7: - | U7: - | V7: -
A8: 6 | B8: GeoX Division Total | C8: GeoX | D8: FY 25-26 | E8: - | F8: 0 | G8: =IFERROR(F8/E8,"-") -> - | H8: - | I8: - | J8: =IFERROR(I8/H8,"-") -> - | K8: - | L8: 0 | M8: =IFERROR(L8/K8,"-") -> - | N8: 10 | O8: 0 | P8: =IFERROR(O8/N8,"-") -> 0 | Q8: 0 | R8: - | S8: - | T8: - | U8: - | V8: -
B9: RTM Total | E9: - | F9: =SUM(F3:F8) -> 4.055 | G9: =IFERROR(F9/E9,"-") -> - | H9: - | I9: - | J9: =IFERROR(I9/H9,"-") -> - | K9: - | L9: =SUM(L3:L8) -> 4.055 | M9: =IFERROR(L9/K9,"-") -> - | N9: =SUM(N3:N8) -> 755 | O9: =SUM(O3:O8) -> 4.055 | P9: =IFERROR(O9/N9,"-") -> 0.0053708609 | Q9: =SUM(Q3:Q8) -> 4

Sheet V6 · CSN
A1: VIEW 6 — RTM CONTRIBUTION | CSN | Booking (Revenue) | H1 & Annual
A2: # | B2: RTM Name | C2: Division | D2: FY | E2: Q1 Quota (₹ Cr) | F2: Q1 Actuals (₹ Cr) | G2: Attainment % (Q1) | H2: Q2 Quota (₹ Cr) | I2: Q2 Actuals (₹ Cr) | J2: Attainment % (Q2) | K2: H1 Quota (₹ Cr) | L2: H1 Actuals (₹ Cr) | M2: Attainment % (H1) | N2: Annual Quota (₹ Cr) | O2: Annual Actuals (₹ Cr) | P2: Attainment % (Annual) | Q2: # Deals (Total) | R2: Led-By Deals (count) | S2: Led-By Rev (₹ Cr) | T2: Contributed Deals (count) | U2: Contributed Rev (₹ Cr) | V2: Rank (Div.)
A3: 1 | B3: S1 Division Total | C3: S1 | D3: FY 25-26 | E3: - | F3: 4.0480584 | G3: =IFERROR(F3/E3,"-") -> - | H3: - | I3: - | J3: =IFERROR(I3/H3,"-") -> - | K3: - | L3: 4.0480584 | M3: =IFERROR(L3/K3,"-") -> - | N3: 90 | O3: 4.1056984 | P3: =IFERROR(O3/N3,"-") -> 0.045618871 | Q3: 2
A4: 2 | B4: S2 Division Total | C4: S2 | D4: FY 25-26 | E4: - | F4: 0 | G4: =IFERROR(F4/E4,"-") -> - | H4: - | I4: - | J4: =IFERROR(I4/H4,"-") -> - | K4: - | L4: 0 | M4: =IFERROR(L4/K4,"-") -> - | N4: 30 | O4: 0 | P4: =IFERROR(O4/N4,"-") -> 0 | Q4: 0
A5: 3 | B5: CB Division Total | C5: CB | D5: FY 25-26 | E5: - | F5: 0 | G5: =IFERROR(F5/E5,"-") -> - | H5: - | I5: - | J5: =IFERROR(I5/H5,"-") -> - | K5: - | L5: 0 | M5: =IFERROR(L5/K5,"-") -> - | N5: 24 | O5: 0 | P5: =IFERROR(O5/N5,"-") -> 0 | Q5: 0
A6: 4 | B6: GB Division Total | C6: GB | D6: FY 25-26 | E6: - | F6: 0 | G6: =IFERROR(F6/E6,"-") -> - | H6: - | I6: - | J6: =IFERROR(I6/H6,"-") -> - | K6: - | L6: 0 | M6: =IFERROR(L6/K6,"-") -> - | N6: 20 | O6: 0 | P6: =IFERROR(O6/N6,"-") -> 0 | Q6: 0
A7: 5 | B7: South Division Total | C7: South | D7: FY 25-26 | E7: - | F7: 0.059775 | G7: =IFERROR(F7/E7,"-") -> - | H7: - | I7: - | J7: =IFERROR(I7/H7,"-") -> - | K7: - | L7: 0.059775 | M7: =IFERROR(L7/K7,"-") -> - | N7: 1 | O7: 0.059775 | P7: =IFERROR(O7/N7,"-") -> 0.059775 | Q7: 2
A8: 6 | B8: GeoX Division Total | C8: GeoX | D8: FY 25-26 | E8: - | F8: 0 | G8: =IFERROR(F8/E8,"-") -> - | H8: - | I8: - | J8: =IFERROR(I8/H8,"-") -> - | K8: - | L8: 0 | M8: =IFERROR(L8/K8,"-") -> - | N8: 20 | O8: 0 | P8: =IFERROR(O8/N8,"-") -> 0 | Q8: 0
B9: RTM Total | E9: - | F9: =SUM(F3:F8) -> 4.1078334 | G9: =IFERROR(F9/E9,"-") -> - | H9: - | I9: - | J9: =IFERROR(I9/H9,"-") -> - | K9: - | L9: =SUM(L3:L8) -> 4.1078334 | M9: =IFERROR(L9/K9,"-") -> - | N9: =SUM(N3:N8) -> 185 | O9: =SUM(O3:O8) -> 4.1654734 | P9: =IFERROR(O9/N9,"-") -> 0.022516072 | Q9: =SUM(Q3:Q8) -> 4

Sheet V7 · PS
A1: VIEW 7 — RTM CONTRIBUTION | PS | Booking (Revenue) | H1 & Annual
A2: # | B2: RTM Name | C2: Division | D2: FY | E2: Q1 Quota (₹ Cr) | F2: Q1 Actuals (₹ Cr) | G2: Attainment % (Q1) | H2: Q2 Quota (₹ Cr) | I2: Q2 Actuals (₹ Cr) | J2: Attainment % (Q2) | K2: H1 Quota (₹ Cr) | L2: H1 Actuals (₹ Cr) | M2: Attainment % (H1) | N2: Annual Quota (₹ Cr) | O2: Annual Actuals (₹ Cr) | P2: Attainment % (Annual) | Q2: # Deals (Total) | R2: Led-By Deals (count) | S2: Led-By Rev (₹ Cr) | T2: Contributed Deals (count) | U2: Contributed Rev (₹ Cr) | V2: Rank (Div.)
A3: 1 | B3: S1 Division Total | C3: S1 | D3: FY 25-26 | E3: - | F3: 0 | G3: - | H3: - | I3: - | J3: - | K3: - | L3: 0 | M3: - | N3: 2 | O3: 0 | P3: =IFERROR(O3/N3,"-") -> 0 | Q3: 0
A4: 2 | B4: S2 Division Total | C4: S2 | D4: FY 25-26 | E4: - | F4: 0 | G4: - | H4: - | I4: - | J4: - | K4: - | L4: 0 | M4: - | N4: 3 | O4: 0 | P4: =IFERROR(O4/N4,"-") -> 0 | Q4: 0
A5: 3 | B5: CB Division Total | C5: CB | D5: FY 25-26 | E5: - | F5: 0 | G5: - | H5: - | I5: - | J5: - | K5: - | L5: 0 | M5: - | N5: 10 | O5: 0 | P5: =IFERROR(O5/N5,"-") -> 0 | Q5: 0
A6: 4 | B6: GB Division Total | C6: GB | D6: FY 25-26 | E6: - | F6: 0.173108 | G6: - | H6: - | I6: - | J6: - | K6: - | L6: 0.173108 | M6: - | N6: 5 | O6: 0.173108 | P6: =IFERROR(O6/N6,"-") -> 0.0346216 | Q6: 2
A7: 5 | B7: South Division Total | C7: South | D7: FY 25-26 | E7: - | F7: 0 | G7: - | H7: - | I7: - | J7: - | K7: - | L7: 0 | M7: - | N7: 1 | O7: 0 | P7: =IFERROR(O7/N7,"-") -> 0 | Q7: 0
A8: 6 | B8: GeoX Division Total | C8: GeoX | D8: FY 25-26 | E8: - | F8: 0 | G8: - | H8: - | I8: - | J8: - | K8: - | L8: 0 | M8: - | N8: 5 | O8: 0 | P8: =IFERROR(O8/N8,"-") -> 0 | Q8: 0
B9: RTM Total | E9: - | F9: =SUM(F3:F8) -> 0.173108 | G9: - | H9: - | I9: - | J9: - | K9: - | L9: =SUM(L3:L8) -> 0.173108 | M9: - | N9: =SUM(N3:N8) -> 26 | O9: =SUM(O3:O8) -> 0.173108 | P9: =IFERROR(O9/N9,"-") -> 0.006658 | Q9: =SUM(Q3:Q8) -> 2

Sheet V8 · CSG
A1: VIEW 8 — RTM CONTRIBUTION | CSG | Booking (Revenue) | H1 & Annual
A2: # | B2: RTM Name | C2: Division | D2: FY | E2: Q1 Quota (₹ Cr) | F2: Q1 Actuals (₹ Cr) | G2: Attainment % (Q1) | H2: Q2 Quota (₹ Cr) | I2: Q2 Actuals (₹ Cr) | J2: Attainment % (Q2) | K2: H1 Quota (₹ Cr) | L2: H1 Actuals (₹ Cr) | M2: Attainment % (H1) | N2: Annual Quota (₹ Cr) | O2: Annual Actuals (₹ Cr) | P2: Attainment % (Annual) | Q2: # Deals (Total) | R2: Led-By Deals (count) | S2: Led-By Rev (₹ Cr) | T2: Contributed Deals (count) | U2: Contributed Rev (₹ Cr) | V2: Rank (Div.)
A3: 1 | B3: S1 Division Total | C3: S1 | D3: FY 25-26 | E3: - | F3: 1.664405 | G3: - | H3: - | I3: - | J3: - | K3: - | L3: 1.664405 | M3: - | N3: 37 | O3: 1.664405 | P3: =IFERROR(O3/N3,"-") -> 0.044983919 | Q3: 7
A4: 2 | B4: S2 Division Total | C4: S2 | D4: FY 25-26 | E4: - | F4: 0 | G4: - | H4: - | I4: - | J4: - | K4: - | L4: 0 | M4: - | N4: 42 | O4: 0 | P4: =IFERROR(O4/N4,"-") -> 0 | Q4: 0
A5: 3 | B5: CB Division Total | C5: CB | D5: FY 25-26 | E5: - | F5: 0 | G5: - | H5: - | I5: - | J5: - | K5: - | L5: 0 | M5: - | N5: 30 | O5: 0 | P5: =IFERROR(O5/N5,"-") -> 0 | Q5: 0
A6: 4 | B6: GB Division Total | C6: GB | D6: FY 25-26 | E6: - | F6: 0.3125 | G6: - | H6: - | I6: - | J6: - | K6: - | L6: 0.3125 | M6: - | N6: 0 | O6: 0.3125 | P6: =IFERROR(O6/N6,"-") -> - | Q6: 1
A7: 5 | B7: South Division Total | C7: South | D7: FY 25-26 | E7: - | F7: 0.042 | G7: - | H7: - | I7: - | J7: - | K7: - | L7: 0.042 | M7: - | N7: 18 | O7: 0.042 | P7: =IFERROR(O7/N7,"-") -> 0.0023333333 | Q7: 2
A8: 6 | B8: GeoX Division Total | C8: GeoX | D8: FY 25-26 | E8: - | F8: 0.016686 | G8: - | H8: - | I8: - | J8: - | K8: - | L8: 0.016686 | M8: - | N8: 8 | O8: 0.016686 | P8: =IFERROR(O8/N8,"-") -> 0.00208575 | Q8: 1
B9: RTM Total | E9: - | F9: =SUM(F3:F8) -> 2.035591 | G9: - | H9: - | I9: - | J9: - | K9: - | L9: =SUM(L3:L8) -> 2.035591 | M9: - | N9: =SUM(N3:N8) -> 135 | O9: =SUM(O3:O8) -> 2.035591 | P9: =IFERROR(O9/N9,"-") -> 0.015078452 | Q9: =SUM(Q3:Q8) -> 11
