Workbook

Sheet Summary
B3: Annual
B4: Sr.No. | C4: Sales Route | D4: Planned | F4: Mgmt Outlook | H4: Quota Outlook
D5: Revenue | E5: GP | F5: Revenue | G5: GP | H5: Revenue | I5: GP
B6: 1 | C6: S1 | D6: ='S1 '!E8 -> 585 | E6: ='S1 '!E9 -> 29.25 | F6: ='S1 '!F8 -> 510 | G6: ='S1 '!F9 -> 26.5 | H6: ='S1 '!G8 -> 530 | I6: ='S1 '!G9 -> 26.5
B7: 2 | C7: S2 | D7: ='S2 '!D8 -> 300 | E7: ='S2 '!D9 -> 24 | F7: ='S2 '!E8 -> 300 | G7: ='S2 '!E9 -> 23 | H7: ='S2 '!F8 -> 300 | I7: ='S2 '!F9 -> 22.3
B8: 3 | C8: CB | D8: ='CB '!C8 -> 115 | E8: ='CB '!C9 -> 6 | F8: ='CB '!D8 -> 115 | G8: ='CB '!D9 -> 6 | H8: ='CB '!E8 -> 115 | I8: ='CB '!E9 -> 6
B9: 4 | C9: GB | D9: ='GB '!C8 -> 66 | E9: ='GB '!C9 -> 2.97 | F9: ='GB '!D8 -> 50 | G9: ='GB '!D9 -> 2.25 | H9: ='GB '!E8 -> 66 | I9: ='GB '!E9 -> 2.97
B10: 5 | C10: South | D10: ='South '!D10 -> 35 | E10: ='South '!D11 -> 2 | F10: ='South '!E10 -> 35 | G10: ='South '!E11 -> 2 | H10: ='South '!F10 -> 35 | I10: ='South '!F11 -> 2
B11: 6 | C11: GeoX | D11: ='GeoX '!C8 -> 45.5 | E11: ='GeoX '!C9 -> 5 | F11: ='GeoX '!D8 -> 40 | G11: ='GeoX '!D9 -> 4 | H11: ='GeoX '!F8 -> 45.5 | I11: ='GeoX '!F9 -> 5
B12: 7 | C12: DCG Self | D12: =DCG!C37 -> 200 | E12: =5%*D12 -> 10 | F12: =D12 -> 200 | G12: =E12 -> 10 | H12: =F12 -> 200 | I12: =G12 -> 10
C14: Total | D14: =SUM(D6:D13) -> 1346.5 | E14: =SUM(E6:E13) -> 79.22 | F14: =SUM(F6:F13) -> 1250 | G14: =SUM(G6:G13) -> 73.75 | H14: =SUM(H6:H13) -> 1291.5 | I14: =SUM(I6:I13) -> 74.77
B16: H1
B17: Sr.No. | C17: Sales Route | D17: Planned | F17: Mgmt Outlook | H17: Quota Outlook
D18: Revenue | E18: GP | F18: Revenue | G18: GP | H18: Revenue | I18: GP
B19: 1 | C19: S1 | D19: =H19*D6/H6 -> 234 | E19: =I19*E6/I6 -> 11.7 | F19: =H19*F6/H6 -> 204 | G19: =I19*G6/I6 -> 10.6 | H19: ='S1 '!H8+'S1 '!I8 -> 212 | I19: ='S1 '!H9+'S1 '!I9 -> 10.6
B20: 2 | C20: S2 | D20: =H20*D7/H7 -> 139 | E20: =I20*E7/I7 -> 8.6098655 | F20: =H20*F7/H7 -> 139 | G20: =I20*G7/I7 -> 8.2511211 | H20: ='S2 '!G8+'S2 '!H8 -> 139 | I20: ='S2 '!G9+'S2 '!H9 -> 8
B21: 3 | C21: CB | D21: =H21*D8/H8 -> 45 | E21: =I21*E8/I8 -> 2.4 | F21: =H21*F8/H8 -> 45 | G21: =I21*G8/I8 -> 2.4 | H21: ='CB '!F8+'CB '!G8 -> 45 | I21: ='CB '!F9+'CB '!G9 -> 2.4
B22: 4 | C22: GB | D22: =H22*D9/H9 -> 22 | E22: =I22*E9/I9 -> 0.99 | F22: =H22*F9/H9 -> 16.666667 | G22: =I22*G9/I9 -> 0.75 | H22: ='GB '!F8+'GB '!G8 -> 22 | I22: ='GB '!F9+'GB '!G9 -> 0.99
B23: 5 | C23: South | D23: =H23*D10/H10 -> 17.5 | E23: =I23*E10/I10 -> 1 | F23: =H23*F10/H10 -> 17.5 | G23: =I23*G10/I10 -> 1 | H23: ='South '!G10+'South '!H10 -> 17.5 | I23: ='South '!G11+'South '!H11 -> 1
B24: 6 | C24: GeoX | D24: =H24*D11/H11 -> 15 | E24: =I24*E11/I11 -> 1.65 | F24: =H24*F11/H11 -> 13.186813 | G24: =I24*G11/I11 -> 1.32 | H24: ='GeoX '!G8+'GeoX '!H8 -> 15 | I24: ='GeoX '!G9+'GeoX '!H9 -> 1.65
B25: 7 | C25: DCG Self | D25: =H25*D12/H12 -> 80 | E25: =I25*E12/I12 -> 4 | F25: =H25*F12/H12 -> 80 | G25: =I25*G12/I12 -> 4 | H25: 80 | I25: 4
C27: Total | D27: =SUM(D19:D26) -> 552.5 | E27: =SUM(E19:E26) -> 30.349865 | F27: =SUM(F19:F26) -> 515.35348 | G27: =SUM(G19:G26) -> 28.321121 | H27: =SUM(H19:H26) -> 530.5 | I27: =SUM(I19:I26) -> 28.64
B29: H2
B30: Sr.No. | C30: Sales Route | D30: Planned | F30: Mgmt Outlook | H30: Quota Outlook
D31: Revenue | E31: GP | F31: Revenue | G31: GP | H31: Revenue | I31: GP
B32: 1 | C32: S1 | D32: =H32*D6/H6 -> 351 | E32: =I32*E6/I6 -> 17.55 | F32: =H32*F6/H6 -> 306 | G32: =I32*G6/I6 -> 15.9 | H32: ='S1 '!J8+'S1 '!K8 -> 318 | I32: ='S1 '!J9+'S1 '!K9 -> 15.9
B33: 2 | C33: S2 | D33: =H33*D7/H7 -> 161 | E33: =I33*E7/I7 -> 15.390135 | F33: =H33*F7/H7 -> 161 | G33: =I33*G7/I7 -> 14.748879 | H33: ='S2 '!I8+'S2 '!J8 -> 161 | I33: ='S2 '!I9+'S2 '!J9 -> 14.3
B34: 3 | C34: CB | D34: =H34*D8/H8 -> 70 | E34: =I34*E8/I8 -> 3.6 | F34: =H34*F8/H8 -> 70 | G34: =I34*G8/I8 -> 3.6 | H34: ='CB '!H8+'CB '!I8 -> 70 | I34: ='CB '!H9+'CB '!I9 -> 3.6
B35: 4 | C35: GB | D35: =H35*D9/H9 -> 44 | E35: =I35*E9/I9 -> 1.98 | F35: =H35*F9/H9 -> 33.333333 | G35: =I35*G9/I9 -> 1.5 | H35: ='GB '!H8+'GB '!I8 -> 44 | I35: ='GB '!H9+'GB '!I9 -> 1.98
B36: 5 | C36: South | D36: =H36*D10/H10 -> 17.5 | E36: =I36*E10/I10 -> 1 | F36: =H36*F10/H10 -> 17.5 | G36: =I36*G10/I10 -> 1 | H36: ='South '!I10+'South '!J10 -> 17.5 | I36: ='South '!I11+'South '!J11 -> 1
B37: 6 | C37: GeoX | D37: =H37*D11/H11 -> 30.5 | E37: =I37*E11/I11 -> 3.35 | F37: =H37*F11/H11 -> 26.813187 | G37: =I37*G11/I11 -> 2.68 | H37: ='GeoX '!I8+'GeoX '!J8 -> 30.5 | I37: ='GeoX '!I9+'GeoX '!J9 -> 3.35
B38: 7 | C38: DCG Self | D38: =H38*D12/H12 -> 120 | E38: =I38*E12/I12 -> 6 | F38: =H38*F12/H12 -> 120 | G38: =I38*G12/I12 -> 6 | H38: 120 | I38: 6
C40: Total | D40: =SUM(D32:D39) -> 794 | E40: =SUM(E32:E39) -> 48.870135 | F40: =SUM(F32:F39) -> 734.64652 | G40: =SUM(G32:G39) -> 45.428879 | H40: =SUM(H32:H39) -> 761 | I40: =SUM(I32:I39) -> 46.13
B42: Sr.No. | C42: Sales Route | D42: DCG | F42: CSN | H42: PS | J42: Cloud | L42: AI | N42: CSG
D43: Planned | E43: MGMT Outlook | F43: Planned | G43: MGMT Outlook | H43: Planned | I43: MGMT Outlook | J43: Planned | K43: MGMT Outlook | L43: Planned | M43: MGMT Outlook | N43: Planned | O43: MGMT Outlook
B44: 1 | C44: S1 | D44: ='S1 '!E124 -> 455 | E44: ='S1 '!F124 -> 396.66667 | F44: ='S1 '!E125 -> 90 | G44: ='S1 '!F125 -> 78.461538 | H44: ='S1 '!E126 -> 2 | I44: ='S1 '!F126 -> 1.7435897 | J44: ='S1 '!E127 -> 1 | K44: ='S1 '!F127 -> 0.87179487 | L44: ='S1 '!E128 -> 0 | M44: ='S1 '!F128 -> 0 | N44: ='S1 '!E129 -> 37 | O44: ='S1 '!F129 -> 32.25641
B45: 2 | C45: S2 | D45: ='S2 '!D50 -> 225 | E45: ='S2 '!E50 -> 225 | F45: ='S2 '!D51 -> 30 | G45: ='S2 '!E51 -> 30 | H45: ='S2 '!D52 -> 3 | I45: ='S2 '!E52 -> 3 | J45: 0 | K45: 0 | L45: 0 | M45: 0 | N45: ='S2 '!D53 -> 42 | O45: ='S2 '!E53 -> 42
B46: 3 | C46: CB | D46: ='CB '!C27 -> 40 | E46: =D46 -> 40 | F46: ='CB '!C28 -> 24 | G46: =F46 -> 24 | H46: ='CB '!C29 -> 10 | I46: ='CB '!D29 -> 10 | J46: ='CB '!C30 -> 10 | K46: ='CB '!D30 -> 10 | L46: ='CB '!C31 -> 1 | M46: ='CB '!D31 -> 1 | N46: ='CB '!C32 -> 30 | O46: =N46 -> 30
B47: 4 | C47: GB | D47: ='GB '!C40 -> 20 | E47: ='GB '!D40 -> 15.151515 | F47: ='GB '!C41 -> 11 | G47: ='GB '!D41 -> 8.3333333 | H47: ='GB '!C42 -> 5 | I47: ='GB '!D42 -> 3.7878788 | J47: ='GB '!C43 -> 10 | K47: ='GB '!D43 -> 7.5757576 | L47: 0 | M47: 0 | N47: ='GB '!B35 -> 20 | O47: ='GB '!C35 -> 15.151515
B48: 5 | C48: South | D48: ='South '!D26 -> 14 | E48: =D48 -> 14 | F48: ='South '!D27 -> 1 | G48: =F48 -> 1 | H48: ='South '!D28 -> 1 | I48: =H48 -> 1 | J48: ='South '!D29 -> 1 | K48: =J48 -> 1 | L48: 0 | M48: 0 | N48: ='South '!D31 -> 18 | O48: =N48 -> 18
...

Sheet DCG
A2: Specility Type | B2: DCG
A4: Plan | B4: 2026-27
A6: Master Revenue & Bottomline Objective
A7: Sr.No. | B7: Details | C7: Amount (in Crores)
B8: Revenue Goal | C8: 1005
B9: Bottomline Goal (%) | C9: 0.05
B10: Services Attached Goal (Value) | C10: 15
A12: OEM Wise Revenue Objective
A13: Sr.No. | B13: OEM Name | C13: Category (RAD) | D13: Revenue Goal (in Crores) | E13: Tier Level Objective | F13: Benchmarch Tier | G13: Galaxy Q1 | H13: Galaxy Q2 | I13: Galaxy Q3 | J13: Galaxy Q4
A14: 1 | B14: Dell | C14: Retention | D14: 500
A15: 2 | B15: Hitachi vantara | C15: Acquiation | D15: 40 | G15: 5 | H15: 10 | I15: 12.5 | J15: 12.5
A16: 3 | B16: Lenovo | C16: Development | D16: 50 | G16: 10 | H16: 5 | I16: 12.5 | J16: 12.5
A17: 4 | B17: NetApp | C17: Development | D17: 40 | G17: 8 | H17: 5 | I17: 12.5 | J17: 14.5
A18: 5 | B18: Broadcom | C18: Retention | D18: 100
A19: 6 | B19: RedHat | C19: Development | D19: 10 | G19: 2.5 | H19: 2.5 | I19: 2.5 | J19: 2.5
A20: 7 | B20: HPe | C20: Development | D20: 40 | G20: 5 | H20: 12.5 | I20: 10 | J20: 12.5
A21: 8 | B21: Nutanix | C21: Development | D21: 7 | G21: 1 | H21: 2 | I21: 2 | J21: 2
A22: 9 | B22: IBM India | C22: Development | D22: 30 | G22: 0 | H22: 10 | I22: 10 | J22: 10
A23: 10 | B23: NetWeb Technologies | C23: Development | D23: 40 | G23: 8 | H23: 10 | I23: 12 | J23: 10
A24: 11 | B24: Commvalut | C24: Development | D24: 5 | G24: 1 | H24: 1 | I24: 1.5 | J24: 1.5
B25: Total | D25: =SUM(D14:D24) -> 862
A28: Optional -Prefered to fill
A29: Sr.No | B29: Sales team | C29: Estimated Revenue in Crores
B30: Strategic 1 | C30: 500
B31: Strategic 2 | C31: 225
B32: Commercial | C32: 30
B33: Growth | C33: 10
B34: North | C34: 10
B35: Pune | C35: 10
B36: South | C36: 35
B37: Self | C37: 200
B38: Total | C38: =SUM(C30:C37) -> 1020
A41: Self owned Customers
A42: Sr.No | B42: Customer Name | C42: Revenue (In Crores)
A43: 1 | B43: Tata Communication
A44: 2 | B44: Amdocs
A45: 3 | B45: IDBI Bank
A46: 4 | B46: Disney World
A47: 5 | B47: DBS
A48: 6 | B48: SBI Life Insurance
...

Sheet CS
A2: CSN - FY2026-27
A3: OEM | D3: Amt (INR-CR)
A4: Revenue Goal | D4: 310
A5: Bottomline Goal (%) | D5: =D4*8% -> 24.8
A6: Services Attached Goal (Value) | D6: =D4*2% -> 6.2
K8: Focus Area
A9: Sno | B9: OEM | C9: Cat (RAD) | D9: Rev Goal (INR-CR) | E9: Q1 | F9: Q2 | G9: Q3 | H9: Q4 | I9: LEVEL | J9: BENCHMARK | K9: CORE TECH 01 | L9: CORE TECH 02 | M9: CORE TECH 03
A10: 1 | B10: Akamai | C10: D | D10: 5 | E10: =D10*0.15 -> 0.75 | F10: =D10*0.2 -> 1 | G10: =D10*0.4 -> 2 | H10: =D10*0.25 -> 1.25 | I10: Premier | J10: Premier | K10: Micro segmentation | L10: API Security | M10: WAF
A11: 2 | B11: Algosec | C11: A | D11: 2.5 | E11: =D11*0.15 -> 0.375 | F11: =D11*0.2 -> 0.5 | G11: =D11*0.4 -> 1 | H11: =D11*0.25 -> 0.625 | I11: Unregistered | J11: Referral | K11: Fireflow | L11: Firewall analyzer
A12: 3 | B12: Arista | C12: D | D12: 5 | E12: =D12*0.15 -> 0.75 | F12: =D12*0.2 -> 1 | G12: =D12*0.3 -> 1.5 | H12: =D12*0.35 -> 1.75 | I12: Authorised | J12: Elite | K12: DC Networking | L12: SDWAN
A13: 4 | B13: Aruba | C13: R | D13: 15 | E13: =D13*0.15 -> 2.25 | F13: =D13*0.2 -> 3 | G13: =D13*0.3 -> 4.5 | H13: =D13*0.35 -> 5.25 | I13: Silver | J13: Gold | K13: SDWAN | L13: Access Point
A14: 5 | B14: Checkpoint | C14: R | D14: 50 | E14: =D14*0.15 -> 7.5 | F14: =D14*0.2 -> 10 | G14: =D14*0.3 -> 15 | H14: =D14*0.35 -> 17.5 | I14: Premier | J14: Premier | K14: Firewall | L14: Email security | M14: SASE
A15: 6 | B15: CISCO | C15: D | D15: 30 | E15: =D15*0.15 -> 4.5 | F15: =D15*0.2 -> 6 | G15: =D15*0.3 -> 9 | H15: =D15*0.35 -> 10.5 | I15: Preffered | J15: Preffered | K15: Routing and Switching | L15: Firewall | M15: SASE
A16: 7 | B16: Crowdstrike | C16: A | D16: 20 | E16: =D16*0.15 -> 3 | F16: =D16*0.2 -> 4 | G16: =D16*0.4 -> 8 | H16: =D16*0.25 -> 5 | I16: Associate | J16: Focus | K16: EDR | L16: NGSIEM
A17: 8 | B17: CyberArk | C17: A | D17: 5 | E17: =D17*0.15 -> 0.75 | F17: =D17*0.2 -> 1 | G17: =D17*0.4 -> 2 | H17: =D17*0.25 -> 1.25 | I17: Unregistered | J17: Authorised | K17: PAM | L17: Cloud security | M17: Identity
A18: 9 | B18: F5 | C18: A | D18: 10 | E18: =D18*0.15 -> 1.5 | F18: =D18*0.25 -> 2.5 | G18: =D18*0.25 -> 2.5 | H18: =D18*0.35 -> 3.5 | I18: Authorised | J18: Silver | K18: Load Balancers | L18: CDN | M18: WAF
A19: 10 | B19: Forcepoint | C19: D | D19: 15 | E19: =D19*0.15 -> 2.25 | F19: =D19*0.2 -> 3 | G19: =D19*0.4 -> 6 | H19: =D19*0.25 -> 3.75 | I19: Authorised | J19: Platinum | K19: DLP | L19: DSPM
A20: 11 | B20: Fortinet | C20: D | D20: 10 | E20: =D20*0.15 -> 1.5 | F20: =D20*0.2 -> 2 | G20: =D20*0.4 -> 4 | H20: =D20*0.25 -> 2.5 | I20: Select | J20: Select | K20: Firewall | L20: WAF | M20: Email security
A21: 12 | B21: Keysight | C21: D | D21: 10 | E21: =D21*0.15 -> 1.5 | F21: =D21*0.2 -> 2 | G21: =D21*0.3 -> 3 | H21: =D21*0.35 -> 3.5 | I21: Standard | J21: Strategic | K21: Network Monitoring
A22: 13 | B22: Manage Engine | C22: R | D22: 10 | E22: =D22*0.15 -> 1.5 | F22: =D22*0.2 -> 2 | G22: =D22*0.3 -> 3 | H22: =D22*0.35 -> 3.5 | I22: Silver | J22: Silver | K22: Patch Mgmt | L22: Endpoint Central | M22: Ad Manager plus
A23: 14 | B23: Netskope | C23: A | D23: 15 | E23: =D23*0.15 -> 2.25 | F23: =D23*0.2 -> 3 | G23: =D23*0.4 -> 6 | H23: =D23*0.25 -> 3.75 | I23: Authorised | J23: Gold | K23: SASE | L23: CASB
A24: 15 | B24: Palo Alto | C24: A | D24: 20 | E24: =D24*0.15 -> 3 | F24: =D24*0.3 -> 6 | G24: =D24*0.2 -> 4 | H24: =D24*0.35 -> 7 | I24: Innovator | J24: Innovator | K24: Firewall | L24: EDR | M24: SASE
A25: 16 | B25: Proofpoint | C25: A | D25: 15 | E25: =D25*0.15 -> 2.25 | F25: =D25*0.2 -> 3 | G25: =D25*0.4 -> 6 | H25: =D25*0.25 -> 3.75 | I25: Unregistered | J25: Core | K25: Email security | L25: AI security
A26: 17 | B26: RSA | C26: R | D26: 5 | E26: =D26*0.15 -> 0.75 | F26: =D26*0.2 -> 1 | G26: =D26*0.3 -> 1.5 | H26: =D26*0.35 -> 1.75 | I26: Gold | J26: Gold | K26: MFA | L26: Governance & Lifecycle.
A27: 18 | B27: Seclore | C27: D | D27: 5 | E27: =D27*0.15 -> 0.75 | F27: =D27*0.2 -> 1 | G27: =D27*0.3 -> 1.5 | H27: =D27*0.35 -> 1.75 | I27: Silver | J27: Gold | K27: Data security | L27: Classification
A28: 19 | B28: SentinelOne | C28: A | D28: 10 | E28: =D28*0.15 -> 1.5 | F28: =D28*0.2 -> 2 | G28: =D28*0.4 -> 4 | H28: =D28*0.25 -> 2.5 | I28: Associate | J28: Advanced | K28: EDR | L28: SIEM
A29: 20 | B29: Thales | C29: A | D29: 2.5 | E29: =D29*0.15 -> 0.375 | F29: =D29*0.2 -> 0.5 | G29: =D29*0.3 -> 0.75 | H29: =D29*0.35 -> 0.875 | I29: Associate | J29: Enrolled | K29: Data security | L29: App security
A30: 21 | B30: Trend Micro | C30: D | D30: 15 | E30: =D30*0.15 -> 2.25 | F30: =D30*0.2 -> 3 | G30: =D30*0.4 -> 6 | H30: =D30*0.25 -> 3.75 | I30: Silver | J30: Silver | K30: EDR | L30: CSPM | M30: MDR
A31: 22 | B31: Varonis | C31: A | D31: 5 | E31: =D31*0.15 -> 0.75 | F31: =D31*0.2 -> 1 | G31: =D31*0.4 -> 2 | H31: =D31*0.25 -> 1.25 | I31: Unregistered | J31: Silver | K31: DSPM | L31: DAM
A32: 23 | B32: Zscaler | C32: A | D32: 10 | E32: =D32*0.15 -> 1.5 | F32: =D32*0.3 -> 3 | G32: =D32*0.2 -> 2 | H32: =D32*0.35 -> 3.5 | I32: Authorised | J32: Base | K32: SASE | L32: ZTNA | M32: DSPM
A33: 24 | B33: Saffron | C33: A | D33: 10 | E33: =D33*0.15 -> 1.5 | F33: =D33*0.3 -> 3 | G33: =D33*0.2 -> 2 | H33: =D33*0.35 -> 3.5 | I33: Registered | J33: Base | K33: NTP | L33: NTP | M33: NTP
A34: 25 | B34: Others | C34: A | D34: 10 | E34: =D34*0.15 -> 1.5 | F34: =D34*0.2 -> 2 | G34: =D34*0.3 -> 3 | H34: =D34*0.35 -> 3.5 | I34: NA | J34: NA | K34: A1 Security | L34: Identity Governance | M34: CTEM
A35: Total | D35: =SUM(D10:D34) -> 310 | E35: =SUM(E10:E34) -> 46.5 | F35: =SUM(F10:F34) -> 66.5 | G35: =SUM(G10:G34) -> 100.25 | H35: =SUM(H10:H34) -> 96.75
A38: SBU | D38: Rev Goal (INR-CR)
A39: Strategic 1 | D39: 100
A40: Strategic 2 | D40: 90
A41: Commercial | D41: 50
A42: Growth | D42: 30
A43: Geo - North | D43: 13
A44: Geo - Pune | D44: 15
...

Sheet PS
A1: Professional Services | B1: H1 | C1: H2 | D1: Total
A2: Strategy 1 | B2: 8400000 | C2: 15600000 | D2: =SUM(B2:C2) -> 24000000
A3: Strategy 2 | B3: 18000000 | C3: 18000000 | D3: =SUM(B3:C3) -> 36000000
A4: Commercial | B4: 14400000 | C4: 21600000 | D4: =SUM(B4:C4) -> 36000000
A5: GeoX | B5: 7200000 | C5: 10800000 | D5: =SUM(B5:C5) -> 18000000
A6: Growth | B6: 14400000 | C6: 21600000 | D6: =SUM(B6:C6) -> 36000000
A7: Existing Revenue | B7: 35000000 | C7: 35000000 | D7: =SUM(B7:C7) -> 70000000
A8: PS Total OB Target - (Annual Contract Value) | B8: 97400000 | C8: 122600000 | D8: =SUM(B8:C8) -> 220000000
A10: Primary Focus Areas
A11: Managed Services - Remote
A12: Managed Services - Hybrid
A13: SOC Services
A14: Cloud Services
A15: Automation & Tools
A17: Secondary Focus Areas
A18: Residency Services
A19: Multi-vendor Support (3rd party AMC)
A20: Day-2 Services (Onsite Support) with Product/ Solution Sale
A22: ** The projected numbers are calculated only basis the primary focus areas

Sheet S1 
C2: Strategic 1
C4: 2026-27
H6: Quota Split H1 (In Crs.) | J6: Quota Split H2 (In Crs.)
C7: Details | E7: Amount (in Crores) | F7: MGMT Plan ( In Crores) | G7: Quota (In Crores) | H7: Q1 | I7: Q2 | J7: Q3 | K7: Q4
C8: Revenue Goal | E8: 585 | F8: 510 | G8: 530 | H8: 100 | I8: 112 | J8: 140 | K8: 178
C9: Bottomline Goal | E9: =E8*5% -> 29.25 | F9: 26.5 | G9: 26.5 | H9: =H8*5% -> 5 | I9: =I8*5% -> 5.6 | J9: =J8*5% -> 7 | K9: =K8*5% -> 8.9
H11: Quota Split H1 (In Crs.) | J11: Quota Split H2 (In Crs.) | L11: Remark
A12: Sr. No. | B12: Acount Manager Name | C12: Customer Name | E12: Category (RAD) | F12: Revenue Goal (in Crores) | G12: Annual Quota | H12: Q1 | I12: Q2 | J12: Q3 | K12: Q4
A13: 1 | B13: Tasneem Khatri | C13: Bank Of Baroda | E13: Retention | F13: 180 | G13: =F13 -> 180
A14: 2 | B14: Tasneem Khatri | D14: Bank of Baroda | H14: 25 | I14: 64.5 | J14: 44.75 | K14: 44.75
A15: 3 | B15: Tasneem Khatri | D15: Baroda U.P. Bank | L15: Part of BOB , Po are released from BOB
A16: 4 | B16: Tasneem Khatri | D16: Baroda Rajasthan Kshetriya Gramin Bank | L16: Part of BOB , Po are released from BOB
A17: 5 | B17: Tasneem Khatri | D17: Baroda Gujarat Gramin Bank | L17: Part of BOB , Po are released from BOB
A18: 6 | B18: Tasneem Khatri | D18: Baroda Global Shared Services Ltd. | H18: 0.05 | I18: 0.75 | J18: 0.05 | K18: 0.05
A19: 7 | B19: Tasneem Khatri | D19: Baroda Financial Services | L19: Part of BOB , Po are released from BOB
A20: 8 | B20: Tasneem Khatri | D20: BOB Capital Markets Limited | H20: 0.025 | I20: 0.025 | J20: 0.025 | K20: 0.025
A21: 9 | B21: Tasneem Khatri | D21: Gujarat Gramin Bank | L21: Part of BOB , Po are released from BOB
A22: 10 | B22: Tasneem Khatri | D22: Baroda Asset Management India Limited | L22: Part of BOB , Po are released from BOB
A23: 11 | B23: Tasneem Khatri | C23: BOI | D23: BOI | E23: Development | F23: 15 | G23: =F23 -> 15 | H23: 3.75 | I23: 3.75 | J23: 3.75 | K23: 3.75
A24: 12 | B24: Tasneem Khatri | C24: CBIBank | D24: CBIBank | E24: Acquisition | F24: 10 | G24: =F24 -> 10 | H24: 0 | I24: 5 | J24: 0 | K24: 5
A25: 13 | B25: Tasneem Khatri | C25: SBIBank | D25: SBIBank | E25: Acquisition | F25: 20 | G25: =F25 -> 20 | H25: 5 | I25: 5 | J25: 5 | K25: 5
A26: 14 | B26: Tasneem Khatri | C26: HDFC Entities | E26: Acquisition | F26: 30 | G26: =F26 -> 30
A27: 15 | B27: Tasneem Khatri | D27: HDBFS | H27: 0 | I27: 2.5 | J27: 1.25 | K27: 1.25
A28: 16 | B28: Tasneem Khatri | D28: HDFC Life | H28: 0 | I28: 6.5 | J28: 2.75 | K28: 2.75
A29: 17 | B29: Tasneem Khatri | D29: HDFC Securities | H29: 0 | I29: 1 | J29: 1 | K29: 1
A30: 18 | B30: Tasneem Khatri | D30: HDFC Ergo | H30: 0 | I30: 2.5 | J30: 1.25 | K30: 1.25
A31: 19 | B31: Tasneem Khatri | D31: HDFC AMC | H31: 1.25 | I31: 1.25 | J31: 1.25 | K31: 1.25
A32: 20 | B32: Tasneem Khatri | C32: Stock Holding | D32: Stock Holding | E32: Acquisition | F32: 5 | G32: =F32 -> 5 | H32: 0 | I32: 2.5 | J32: 1.25 | K32: 1.25
A33: 21 | B33: Riya Roshyara | C33: UBI | D33: UBI | E33: Acquisition | F33: 5 | G33: =F33 -> 5 | H33: 0 | I33: 1 | J33: 2 | K33: 2
A34: 22 | B34: Riya Roshyara | C34: IBA | D34: IBA | E34: Acquisition | F34: 5 | G34: =F34 -> 5 | H34: 0 | I34: 0 | J34: 2.5 | K34: 2.5
A35: 23 | B35: Riya Roshyara | C35: BPCL | D35: BPCL | E35: Development | F35: 40 | G35: =F35 -> 40 | H35: 10 | I35: 10 | J35: 10 | K35: 10
A36: 24 | B36: Riya Roshyara | C36: SBI Entities | E36: Development | F36: 30 | G36: =F36 -> 30
A37: 25 | B37: Riya Roshyara | D37: SBI GENERAL INSURANCE COMPANY LIMITED | I37: 2.5 | J37: 3 | K37: 3
A38: 26 | B38: Riya Roshyara | D38: SBI CAPITAL MARKETS LIMITED | I38: 1 | J38: 2 | K38: 2
A39: 27 | B39: Riya Roshyara | D39: SBICAP Securities Ltd (SSL) | I39: 1 | J39: 2 | K39: 2
A40: 28 | B40: Riya Roshyara | D40: SBI FUNDS MANAGEMENT LIMITED | I40: 1 | J40: 2 | K40: 2
A41: 29 | B41: Riya Roshyara | D41: SBI mutual | I41: 1.5 | J41: 2.5 | K41: 2.5
A42: 30 | B42: Riya Roshyara | C42: NPCI | D42: NPCI | E42: Retention | F42: 40 | G42: =F42 -> 40 | H42: 10 | I42: 20 | J42: 10
A43: 31 | B43: Chirag Palande | C43: MCX | D43: MCX | E43: Acquisition | F43: 10 | G43: =F43 -> 10 | H43: 1.25 | I43: 1.25 | J43: 2 | K43: 3.5
A44: 32 | B44: Chirag Palande | D44: MCXCCL | E44: Acquisition | H44: 0.25 | I44: 0.25 | J44: 0.75 | K44: 0.75
...

Sheet S2 
A2: Sales Unit | C2: Strategic 2
A4: Business Plan | C4: 2026-27
A6: Master Revenue & Bottomline Objective | G6: Quota Split H1 (In Crs.) | I6: Quota Split H2 (In Crs.)
A7: Sr.No. | C7: Details | D7: Amount (in Crores) | E7: MGMT Plan ( In Crores) | F7: Quota (In Crores) | G7: Q1 | H7: Q2 | I7: Q3 | J7: Q4
C8: Revenue Goal | D8: 300 | E8: 300 | F8: 300 | G8: 54.85 | H8: 84.15 | I8: 70.45 | J8: 90.55
C9: Bottomline Goal | D9: 24 | E9: 23 | F9: 22.3 | G9: 3 | H9: 5 | I9: 7 | J9: 7.3
A11: Customer Wise Revenue Objective | G11: Quota Split H1 (In Crs.) | I11: Quota Split H2 (In Crs.)
A12: Sr.No. | B12: Account Mangers | C12: Customer Name | D12: Category (RAD) | E12: Revenue Goal (in Crores) Anually | F12: Annual Quota | G12: Q1 | H12: Q2 | I12: Q3 | J12: Q4
A13: 1 | B13: Rohit | C13: Axis Bank | D13: Retention | E13: 120 | F13: =E13 -> 120 | G13: 25 | H13: 50 | I13: 20 | J13: 25
A14: 2 | B14: Rohit | C14: Tata Motors | D14: Retention | E14: 15 | F14: =E14 -> 15 | G14: 4 | H14: 3 | I14: 3 | J14: 5
A15: 3 | B15: Chetna | C15: Axis Finance | D15: Development | E15: 2 | F15: =E15 -> 2 | G15: 0.3 | H15: 0.7 | I15: 0.5 | J15: 0.5
A16: 4 | B16: Chetna | C16: Axis Securities | D16: Development | E16: 2 | F16: =E16 -> 2 | G16: 0.6 | H16: 0.4 | I16: 0.5 | J16: 0.5
A17: 5 | B17: Chetna | C17: Axis Capital | D17: Development | E17: 2 | F17: =E17 -> 2 | G17: 0.6 | H17: 0.4 | I17: 0.5 | J17: 0.5
A18: 6 | B18: Chetna | C18: HDFC Bank | D18: Accquisition | E18: 28 | F18: =E18 -> 28 | G18: 1 | H18: 5 | I18: 5 | J18: 17
A19: 7 | B19: Chetna | C19: Yes Bank | D19: Development | E19: 25 | F19: =E19 -> 25 | G19: 3 | H19: 2 | I19: 10 | J19: 10
A20: 8 | B20: Chetna | C20: Yes securitites | D20: Development | E20: 5 | F20: =E20 -> 5 | G20: 1.5 | H20: 0.5 | I20: 1.5 | J20: 1.5
A21: 9 | B21: Chetna | C21: Mahindra & Mahindra | D21: Accquisition | E21: 5 | F21: =E21 -> 5 | G21: 1 | H21: 1 | I21: 1.5 | J21: 1.5
A22: 10 | B22: Varsha | C22: Kotak Bank | D22: Accquisition | E22: 5 | F22: =E22 -> 5 | G22: 0.5 | H22: 0.5 | I22: 2 | J22: 2
A23: 11 | B23: Varsha | C23: Kotak Mahindra AMC Company Ltd | D23: Accquisition | E23: 1 | F23: =E23 -> 1 | G23: 0.2 | H23: 0.2 | I23: 0.3 | J23: 0.3
A24: 12 | B24: Varsha | C24: Kotak Mahindra Life Insurance- | D24: Accquisition | E24: 2 | F24: =E24 -> 2 | G24: 0.5 | H24: 0.5 | I24: 0.5 | J24: 0.5
... A45: 33 | B45: Sankeerth | C45: IDFC | D45: Accquisition | E45: 5 | F45: =E45 -> 5 | G45: 1 | H45: 1 | I45: 1 | J45: 2
D46: Total | E46: =SUM(E13:E45) -> 300 | F46: =SUM(F13:F45) -> 300 | G46: =SUM(G13:G45) -> 54.85 | H46: =SUM(H13:H45) -> 84.15 | I46: =SUM(I13:I45) -> 70.45 | J46: =SUM(J13:J45) -> 90.55
A49: Sr.No | C49: Product Line | D49: Estimated Revenue in Crores | E49: MGMT Plan in Crores
C50: DCG | D50: 225 | E50: =D50 -> 225
C51: CSN | D51: 30 | E51: =D51 -> 30
C52: PS/cloud | D52: 3 | E52: =D52 -> 3
C53: CSG | D53: 42 | E53: =D53 -> 42
C54: Total | D54: =SUM(D50:D53) -> 300 | E54: =SUM(E50:E53) -> 300
A56: Non Revenue
A57: Sr.No | C57: Details | D57: Objective
C58: New Logos Per Quarter | D58: 2
C59: Team size (excluding Leader) | D59: 7
C60: Revenue per team member | D60: =D54/6 -> 50
C61: Pipeline/Revenue Ratio | D61: 5X
A63: Sr.No. | B63: Account Mangers | C63: Customer Name | D63: Category (RAD) | E63: Account nos | F63: H1 | G63: H2 | H63: Variable
A64: 1 | B64: Rohit | C64: Axis Bank | D64: Retention | E64: 120 | F64: 70 | G64: 50 | H64: 569250
A65: 2 | B65: Rohit | C65: Tata Motors | D65: Retention | E65: 15 | F65: 6 | G65: 9
D66: Total | E66: 135
A68: 3 | B68: Chetna | C68: Axis Finance | D68: Development | E68: 2 | F68: 1 | G68: 1 | H68: 1018900
A69: 4 | B69: Chetna | C69: Axis Securities | D69: Development | E69: 2 | F69: 1 | G69: 1
...

Sheet CB 
A2: Sales Unit | B2: Commercial
A4: Business Plan | B4: 2026-27
A6: Master Revenue & Bottomline Objective | F6: Quota Split H1 (In Crs.) | H6: Quota Split H2 (In Crs.)
A7: Sr.No. | B7: Details | C7: Amount (in Crores) | D7: MGMT Plan ( In Crores) | E7: Quota (In Crores) | F7: Q1 | G7: Q2 | H7: Q3 | I7: Q4
B8: Revenue Goal | C8: 115 | D8: 115 | E8: 115 | F8: 20 | G8: 25 | H8: 30 | I8: 40
B9: Bottomline Goal | C9: 6 | D9: 6 | E9: 6 | F9: 1 | G9: 1.4 | H9: 1.6 | I9: 2
C11: Quota Split H1 (In Crs.) | E11: Quota Split H2 (In Crs.)
A12: AE | B12: Quota (In Crores) | C12: Q1 | D12: Q2 | E12: Q3 | F12: Q4
A13: Darshana Patil | B13: 16 | C13: 3 | D13: 4 | E13: 3 | F13: 6
A14: Prachi Mayekar | B14: 33 | C14: 7.5 | D14: 7.5 | E14: 8 | F14: 10
A15: Shilpa Kavde | B15: 40 | C15: 5 | D15: 10 | E15: 10 | F15: 15
A16: Jimesh Shah & Team | B16: 45 | C16: 5 | D16: 10 | E16: 10 | F16: 20
A17: Total | B17: =SUM(B13:B16) -> 134 | C17: =SUM(C13:C16) -> 20.5 | D17: =SUM(D13:D16) -> 31.5 | E17: =SUM(E13:E16) -> 31 | F17: =SUM(F13:F16) -> 51
A19: Jimesh & Team | B19: Quota (In Crores) | C19: Quota Split H1 (In Crs.) | E19: Quota Split H2 (In Crs.)
C20: Q1 | D20: Q2 | E20: Q3 | F20: Q4
A21: Vidula Chavan | B21: 9.5 | C21: 1 | D21: 2 | E21: 3 | F21: 3.5
A22: TBH | B22: 9.5 | C22: 1 | D22: 2 | E22: 3 | F22: 3.5
A25: BU wise Plan
A26: Sr.No | B26: Product Line | C26: Estimated Revenue in Crores | D26: MGMT Plan in Crores
A27: 1 | B27: DCG | C27: 40 | D27: 40
A28: 2 | B28: CSN | C28: 24 | D28: 24
A29: 3 | B29: PS | C29: 10 | D29: 10
A30: 4 | B30: Cloud | C30: 10 | D30: 10
A31: 5 | B31: AI | C31: 1 | D31: 1
A32: 6 | B32: CSG | C32: 30 | D32: 30
B33: Total | C33: =SUM(C27:C32) -> 115 | D33: =SUM(D27:D32) -> 115
A35: Non Revenue
A36: Sr.No | B36: Details | C36: Objective
A37: 1 | B37: New Logos Per Month | C37: 2
A38: 2 | B38: Team size (excluding Leader) | C38: 7
A39: 3 | B39: Revenue per team member (in Cr) | C39: 20
B41: Total Planned Team Size | C41: 7
B42: Current Team Size | C42: 5
H43: FY -26-27
A44: AE | B44: Target | C44: Current CTC | D44: Proposal Appraisal | E44: New CTC | F44: Date of joining | G44: Remarks | H44: Varaiable
A45: Darshana Patil | B45: 160000000 | C45: 1280850 | D45: 0.1 | E45: =C45*1.1 -> 1408935 | F45: 45691 | G45: Conditional after target achivement of H1 on prorata | H45: 563600
A46: Prachi Mayekar | B46: 330000000 | C46: 3000000 | D46: 0.1 | E46: =C46*1.1 -> 3300000 | F46: 45761 | G46: Conditional after target achivement of H1 on prorata | H46: 1320000
A47: Shilpa Kavde | B47: 400000000 | C47: 3500000 | D47: 0.2 | E47: =C47*1.2 -> 4200000 | F47: 45810 | G47: Pro-rate basis to be effective once 12 mths completed | H47: 1680000
A48: Jimesh Shah & Team | B48: 500000000 | C48: 2212506 | D48: 0.25 | E48: =C48*1.25+C52+C53 -> 4665632.5 | F48: 44564 | H48: 1106000
A49: Total | B49: =SUM(B45:B48) -> 1390000000 | E49: =SUM(E45:E48) -> 13574568 | H49: =SUM(H45:H48) -> 4669600
...

Sheet GB 
A2: Sales Unit | B2: Growth
A4: Business Plan | B4: 2026-27
A6: Master Revenue & Bottomline Objective | F6: Quota Split H1 (In Crs.) | H6: Quota Split H2 (In Crs.)
A7: Sr.No. | B7: Details | C7: Amount (in Crores) | D7: Mgmt Plan in Crores | E7: Quota in Crores | F7: Q1 | G7: Q2 | H7: Q3 | I7: Q4
B8: Revenue Goal | C8: 66 | D8: 50 | E8: 66 | F8: 9 | G8: 13 | H8: 20 | I8: 24
B9: Bottomline Goal | C9: =C8*4.5% -> 2.97 | D9: 2.25 | E9: 2.97 | F9: 0.4 | G9: 0.59 | H9: 0.9 | I9: 1.08
A11: H1 | B11: H2
A13: 26 | B13: 40
C15: Quota Split H1 (In Crs.) | E15: Quota Split H2 (In Crs.) | H15: Variable
B16: Quota in Crores | C16: Q1 | D16: Q2 | E16: Q3 | F16: Q4 | G16: Remark | H16: FY -26-27
A17: Atharva Kapre | B17: 8 | C17: 3 | D17: 1 | E17: 1 | F17: 3 | G17: Generalist Team | H17: 100000
A18: Jay Rushi | B18: 8 | C18: 1 | D18: 2 | E18: 2 | F18: 3 | G18: Generalist Team | H18: 90000
A19: TBH | B19: 8 | G19: Generalist Team | H19: 0
A20: TBH | B20: 8 | G20: Generalist Team | H20: 0
A21: Ayushaman | B21: 12 | C21: 1 | D21: 2 | E21: 4 | F21: 5 | G21: Specialist Team | H21: 800000
A22: Shubhangi | B22: 15 | C22: 2 | D22: 3 | E22: 5 | F22: 6 | G22: Specialist Team | H22: 857000
A23: Bhumi | B23: 2 | C23: 0.1 | D23: 0.5 | E23: 0.5 | F23: 0.9 | G23: PS ISR /OSR | H23: 100000
A24: Suyesh | B24: 2 | C24: 0.1 | D24: 0.5 | E24: 0.5 | F24: 0.9 | G24: PS ISR /OSR | H24: 100000
A25: ISR Lead | B25: 5 | G25: PS ISR /OSR | H25: 0
A26: Ashish | B26: 15 | C26: 2 | D26: 3 | E26: 5 | F26: 5 | G26: Cloud/PS | H26: 838501
A27: Rizwana (ISR/OSR) | B27: 5 | C27: 0.5 | D27: 1 | E27: 1.5 | F27: 2 | G27: Cloud/PS | H27: 100000
A28: TBH | B28: 5 | G28: Cloud/PS | H28: 0
A29: Total | B29: =SUM(B17:B28) -> 93 | C29: =SUM(C17:C28) -> 9.7 | D29: =SUM(D17:D28) -> 13 | E29: =SUM(E17:E28) -> 19.5 | F29: =SUM(F17:F28) -> 25.8
A33: Route 1
A34: Sr.No | B34: Estimated Revenue in Crores | C34: Management Plan in Crores | D34: Remark
A35: ISR & OSR Revenue in Crores | B35: 20 | C35: =B35/$C$52*$D$8 -> 15.151515 | D35: CSG & IT pehiperials
A36: Team Size | B36: 5
A38: Route 2
A39: Sr.No | B39: Speciality Type | C39: Estimated Revenue in Crores | D39: Management Plan in Crores
A40: 1 | B40: Cyber security | C40: 20 | D40: =C40/$C$52*$D$8 -> 15.151515
A41: 2 | B41: DCG | C41: 11 | D41: =C41/$C$52*$D$8 -> 8.3333333
A42: 3 | B42: PS | C42: 5 | D42: =C42/$C$52*$D$8 -> 3.7878788
A43: 4 | B43: Cloud | C43: 10 | D43: =C43/$C$52*$D$8 -> 7.5757576
B45: Total | C45: =SUM(C40:C44) -> 46 | D45: =SUM(D40:D44) -> 34.848485
A47: Summary
A48: Sr.No | B48: Route Type | C48: Estimated Revenue in Crores | D48: Management Plan in Crores
A49: 1 | B49: R1 | C49: =B35 -> 20 | D49: =C35 -> 15.151515
A50: 2 | B50: R2 | C50: =C45 -> 46 | D50: =D45 -> 34.848485
B52: Total | C52: =SUM(C49:C51) -> 66 | D52: =SUM(D49:D51) -> 50
A54: Non Revenue
...

Sheet South 
B3: Sales Unit | C3: South Sales
B5: Business Plan | C5: 2026-27
B8: Master Revenue & Bottomline Objective | G8: Quota Split H1 (In Crs.) | I8: Quota Split H2 (In Crs.)
B9: Sr.No. | C9: Details | D9: Amount (in Crores) | E9: Mgmt Plan in Crores | F9: Quota in Crores | G9: Q1 | H9: Q2 | I9: Q3 | J9: Q4
B10: 1 | C10: Revenue Goal | D10: 35 | E10: 35 | F10: 35 | G10: =F10/4 -> 8.75 | H10: 8.75 | I10: 8.75 | J10: 8.75
B11: 2 | C11: Bottomline Goal | D11: 2 | E11: 2 | F11: 2 | G11: 0.5 | H11: 0.5 | I11: 0.5 | J11: 0.5
D14: Quota Split H1 (In Crs.) | F14: Quota Split H2 (In Crs.) | H14: Variable
B15: Sales Person Name | C15: Quota in Crores | D15: Q1 | E15: Q2 | F15: Q3 | G15: Q4 | H15: FY -26-27
B16: Abrar Altaf Menon | C16: 8 | D16: 2 | E16: 2 | F16: 2 | G16: 2 | H16: 302400
B17: Sagar TR | C17: 10 | D17: 2.5 | E17: 2.5 | F17: 2.5 | G17: 2.5 | H17: 421200
B18: Shaikh Kadar | C18: 12 | D18: 3 | E18: 3 | F18: 3 | G18: 3 | H18: 1060000
B19: Shahbaz Khan | C19: 12 | D19: 3 | E19: 3 | F19: 3 | G19: 3 | H19: 819020
B20: TBH - | C20: 8 | D20: 2 | E20: 2 | F20: 2 | G20: 2 | H20: 0
B22: Total | C22: =SUM(C16:C20) -> 50 | D22: =SUM(D16:D20) -> 12.5 | E22: =SUM(E16:E20) -> 12.5 | F22: =SUM(F16:F20) -> 12.5 | G22: =SUM(G16:G20) -> 12.5 | H22: =SUM(H16:H20) -> 2602620
B25: Sr.No | C25: Product Line | D25: Estimated Revenue in Crores | E25: Mgmt Plan in Crores
C26: DCG | D26: 14 | E26: =D26 -> 14
C27: CSN | D27: 1 | E27: =D27 -> 1
C28: PS | D28: 1 | E28: =D28 -> 1
C29: Cloud | D29: 1 | E29: =D29 -> 1
C30: AI | E30: =D30 -> 0
C31: CSG | D31: 18 | E31: =D31 -> 18
C32: Total | D32: =SUM(D26:D31) -> 35 | E32: =SUM(E26:E31) -> 35
B34: Non Revenue
B35: Sr.No | C35: Details | D35: Objective
C36: New Logos Per Month | D36: 3
C37: Team size (excluding Leader) | D37: 4
C38: Revenue per team member

Sheet GeoX 
A2: Sales Unit | B2: GeoX
A4: Business Plan | B4: 2026-27
A6: Master Revenue & Bottomline Objective | E6: With Additional Team Members | F6: With Existing Team & Self | G6: Quota Split H1 (In Crs.) | I6: Quota Split H2 (In Crs.)
A7: Sr.No. | B7: Details | C7: Amount (in Crores) | D7: MGMT Plan in Crores | E7: Quota Aspirational Nos (in Crores) | F7: Quota in Crores | G7: Q1 | H7: Q2 | I7: Q3 | J7: Q4
A8: Target | B8: Revenue Goal | C8: =C27 -> 45.5 | D8: 40 | E8: 60 | F8: 45.5 | G8: 5 | H8: 10 | I8: 15 | J8: 15.5
B9: Bottomline Goal | C9: 5 | D9: 4 | E9: 6 | F9: 5 | G9: 0.5 | H9: 1.15 | I9: 1.65 | J9: 1.7
C12: Quota Split H1 (In Crs.) | E12: Quota Split H2 (In Crs.) | H12: Quota Split H1 (In Crs.) | J12: Quota Split H2 (In Crs.) | L12: Variable
A13: Name | B13: Revenue Quota in Crores | C13: Q1 | D13: Q2 | E13: Q3 | F13: Q4 | G13: Bottomline Quota in Crores | H13: Q1 | I13: Q2 | J13: Q3 | K13: Q4 | L13: FY -26-27
A14: Sanjeev Kohli | B14: 25.5 | C14: 2.5 | D14: 5 | E14: 9 | F14: 9 | G14: 2.6 | H14: 0.1 | I14: 0.5 | J14: 1 | K14: 1 | L14: 0
A15: Hrushikesh Bagade | B15: 20 | C15: 2.5 | D15: 5 | E15: 6.5 | F15: 6 | G15: 2.4 | H15: 0.4 | I15: 0.65 | J15: 0.65 | K15: 0.7 | L15: 855470
A16: TBH | B16: 14.5 | C16: 0.5 | D16: 3 | E16: 5 | F16: 6 | G16: 1 | H16: 0 | I16: 0.2 | J16: 0.4 | K16: 0.4 | L16: 0
A17: Total | B17: =SUM(B14:B16) -> 60 | C17: =SUM(C14:C16) -> 5.5 | D17: =SUM(D14:D16) -> 13 | E17: =SUM(E14:E16) -> 20.5 | F17: =SUM(F14:F16) -> 21 | G17: =SUM(G14:G16) -> 6 | H17: =SUM(H14:H16) -> 0.5 | I17: =SUM(I14:I16) -> 1.35 | ... K17: =SUM(K14:K16) -> 2.1
A20: Sr.No | B20: Product Line | C20: Estimated Revenue in Crores | D20: MGMT Plan in Crores | E20: Aspirational Quota in Crores
B21: DCG | C21: 10 | D21: =C21/$C$27*$D$8 -> 8.7912088 | E21: 15
B22: CSN | C22: 20 | D22: =C22/$C$27*$D$8 -> 17.582418 | E22: 20
B23: PS | C23: 5 | D23: =C23/$C$27*$D$8 -> 4.3956044 | E23: 8
B24: Cloud | C24: 2 | D24: =C24/$C$27*$D$8 -> 1.7582418 | E24: 3
B25: AI | C25: 0.5 | D25: =C25/$C$27*$D$8 -> 0.43956044 | E25: 0.5
B26: CSG | C26: 8 | D26: =C26/$C$27*$D$8 -> 7.032967 | E26: 13.5
B27: Total | C27: =SUM(C21:C26) -> 45.5 | D27: =SUM(D21:D26) -> 40 | E27: =SUM(E21:E26) -> 60
B29: Aspiration Quote is after adding team as below
B30: Total Planned Team Size | C30: 5
B31: Current Team Size | C31: 1
A33: Non Revenue
A34: Sr.No | B34: Details | C34: Objective
B35: New Logos Per Month | C35: 1 | D35: 1
B36: Team size (excluding Leader) | C36: 5 | D36: 6
B37: Revenue per team member
B38: Pipeline/Revenue Ratio | C38: 3.5 | D38: 4
B40: Targeted
A41: Name | B41: Revenue Goal | C41: Bottomline Goal
A42: Hrushikesh Bagade | B42: 20 | C42: =B42*5/45.5 -> 2.1978022
A43: Sanjeev Kohli | B43: 25.5 | C43: =B43*5/45.5 -> 2.8021978
A44: TBH | B44: 14.5 | C44: 1
A45: Total | B45: =SUM(B42:B44) -> 60 | C45: =SUM(C42:C44) -> 6

Sheet Sales Plan T&C
B1: Terms & Conditions
A3: 1 | B3: Payout Structure
B4: H1 | C4: 0.35 | D4: As per Details
B5: H2 | C5: 0.35 | D5: As per Details
B6: Annual Accoun based | C6: 0.1 | D6: As per Details
B7: Annual base overall Achievement | C7: 0.15 | D7: As per Details
B8: Company | C8: 0.05 | D8: For Company Incentive applicable only if Individula Annual base number applicable for Incentive is Achieved and Company Annual Goal for 26-27 of Rs.1250 Crores (Excluding Blue Bird* Deals) is Achieved in Billing Revenue of FY 26-27
A10: 2 | B10: A Blue Bird Deal is a deal driven by Management at its level with a value above Rs.50 Crores
A12: 3 | B12: Order booking will be Consider from 1H :-1st April 2026 to 30th September 2026, 2H :- 1st October 2026 to 31st March 2027, Annual :-1st April 2026 to 31st March 2027
A14: 4 | B14: Multiplier
B15: PS Revenue | C15: 2X
B16: CSN Revenue | C16: 1.3X
B17: DCG (Backup, Storage) Revenue | C17: 1.2X
A19: 5 | B19: PS Revenue for Multiplier is as under :-
B20: Primary Focus Areas | C20: Multiplier
B21: Managed Services - Remote | C21: Included
B22: Managed Services - Hybrid | C22: Included
B23: SOC Services | C23: Included
B24: Cloud Services | C24: Included
B25: Automation & Tools | C25: Included
B26: Secondary Focus Areas | C26: Multiplier
B27: Residency Services | C27: Not Included
B28: Multi-vendor Support (3rd party AMC) | C28: Not Included
B29: Day-2 Services (Onsite Support) with Product/ Solution Sale | C29: Not Included
B30: Day-2 Services (Onsite Support) without Product/ Solution Sale | C30: Not Included
A32: 6 | B32: For DCG & CSN Multiplier applicable for qualified products would be same multiplier for bundled PS and Services
A34: 7 | B34: Mandatory Bundling of Managed Services as under
B35: Category | C35: Charges | D35: Remark
B36: Basic | C36: Refer Sheet | D36: To be bundled with every Deal , In case it is not a separate line item , customer will get it free and charges will be deducted @2X of Basic PS Charges from deal value
B37: Standard | C37: Refer Sheet
B38: Advance | C38: Refer Sheet
B39: Customised | C39: As per SOW & SLA | D39: To be worked by BU Presales based on Customer Requirement's
A41: 8 | B41: Quota Variable Table
B42: Slab | C42: Variable Payout
B43: 0% to 50% | C43: No Payout
B44: 51% to 100% | C44: 2% of Variable on every 1% above 50% Achievement
B45: 100% to 200% | C45: 1% of Variable on every 1% above 100% Achievement
B46: 200% to 300% | C46: 0.5% of Variable on every 1% above 200% Achievement
B47: Above 300 % | C47: 0.25% of ariable on every 1 % above 300% Achievement
A49: 9 | B49: All the Targets / Quota is on Revenue (Topline)
...

Sheet Marketing
B2: Sr.No | C2: Marketing Activities
B3: 1 | C3: Techday Offsite/onsite
B4: 2 | C4: EBC -NOC-SOC Visit
B5: 3 | C5: Enablement, training & Certification
B6: 4 | C6: Round table
C8: Remark
B9: 1 | C9: Atleast 1 activity of the above in every Customer including Child Accounts in a Quarter S1&S2
B10: 2 | C10: All Three Mandatory Activity has to happen in a year in every Customer including Child Accounts for S1 & S2
B11: 3 | C11: Atleast 6 activities in a each half for Individual set of customer in a Quarter CB & GB
B12: 4 | C12: All four Mandatory Activity has to happen in a year for Individual set of Customer for CB & GB

Sheet DC Service Packs 
D3: Description | E3: Basic | F3: Standard | G3: Advanced | H3: Customised
D4: Service Window (hr x Days) | E4: 8x5 | F4: 16x5 / 24x5 | G4: 24x7x365 | H4: Advanced + Customised SOW
D5: Support Model | E5: Reactive | F5: Proactive | G5: Predictive | H5: Advanced + Customised SOW
D6: Service Levels (Response SLA)
D7: P1 | E7: 1h | F7: 1h | G7: 1h | H7: 30 mins
D8: P2 | E8: 2h | F8: 2h | G8: 2h | H8: 1 hr
D9: P3 | E9: 4h | F9: 4h | G9: 4h | H9: 2 hr
D10: Service Coverage & Inclusions
D11: OEM Support | E11: Call Logging + follow-up till resolution | F11: Call Logging + follow-up till resolution | G11: Call Logging + follow-up till resolution | H11: Customised Support as desired
D12: Galaxy L1 Support | E12: Basic HW | F12: Basic HW + OS | G12: Basic HW + OS
D13: Patch Deployment | F13: As required | G13: Tracking + Deployment
D14: Monitoring | F14: Proactive | G14: Predictive
D15: Break-Fix Support - L1/L2 | F15: As required | G15: As required
D16: Proactive Health-Check | G16: Quarterly
D17: Configuration Change | G17: upto 4 changes per year
D18: No of Tickets / Device | E18: 10 | F18: 15 | G18: 20 | H18: Unlimited
D19: Pricing (Annual ticket packs) Pricing in INR
D20: Server | E20: =700*$E$18 -> 7000 | F20: =675*$F$18 -> 10125 | G20: =650*$G$18 -> 13000 | H20: Contact Pre-Sales for pricing
D21: Storage | E21: =600*$E$18 -> 6000 | F21: =575*$F$18 -> 8625 | G21: =550*$G$18 -> 11000
D22: Backup | E22: =600*$E$18 -> 6000 | F22: =575*$F$18 -> 8625 | G22: =550*$G$18 -> 11000
D23: Vmware | E23: =1000*$E$18 -> 10000 | F23: =950*$F$18 -> 14250 | G23: =$G$18*900 -> 18000
D24: Nutanix | E24: =1000*$E$18 -> 10000 | F24: =950*$F$18 -> 14250 | G24: =$G$18*900 -> 18000

Sheet NW Service Packs
D3: Service Area | E3: Basic | F3: Standard | G3: Advanced | H3: Customised
D4: Service Window (hr x Days) | E4: Mon - Fri (9AM - 6PM) | F4: Mon - Sat (7AM - 11PM) | G4: 24x7x365 | H4: Advanced + Customised SOW
D5: Support Model | E5: Reactive | F5: Proactive | G5: Predictive | H5: Advanced + Customised SOW
D6: Service Levels (Response)
D7: P1 | E7: 2h | F7: 1h | G7: 1h | H7: 30 mins
D8: P2 | E8: 4h | F8: 2h | G8: 2h | H8: 1 hr
D9: P3 | E9: 8h | F9: 4h | G9: 4h | H9: 2 hr
D10: Service Coverage & Inclusions
D11: OEM Support | E11: OEM Call Logging + follow-up till resolution | F11: OEM Call Logging + follow-up till resolution | G11: OEM Call Logging + follow-up till resolution | H11: Customised Support as desired
D12: Galaxy L1 Support | E12: Basic HW | F12: Basic HW + Firmware | G12: Basic HW + Firmware
D13: Patch Deployment | F13: As required | G13: Tracking + Deployment
D14: Monitoring | F14: Proactive | G14: Predictive
D15: Break-Fix Support - L1/L2 | F15: As required | G15: As required
D16: Proactive Health-Check | G16: Quarterly
D17: Configuration Change | G17: upto 4 changes per year
D18: Reporting | F18: Monthly Performance | G18: Monthly with Analytics
D19: Tickets (Yearly) | E19: 25 | F19: 50 | G19: 100 | H19: Unlimited
D20: Pricing (Annual ticket packs) Pricing in INR
D21: Switch / Router | E21: =500*$E$19 -> 12500 | F21: =450*$F$19 -> 22500 | G21: =420*$G$19 -> 42000 | H21: Contact BU Pre-Sales
D22: SD-WAN | E22: =500*$E$19 -> 12500 | F22: =450*$F$19 -> 22500 | G22: =420*$G$19 -> 42000
D23: Wireless Access Points | E23: =300*$E$19 -> 7500 | F23: =270*$F$19 -> 13500 | G23: =250*$G$19 -> 25000
D24: NAC | E24: =800*$E$19 -> 20000 | F24: =750*$F$19 -> 37500 | G24: =700*$G$19 -> 70000
D25: Network Firewalls | E25: =700*$E$19 -> 17500 | F25: =600*$F$19 -> 30000 | G25: =550*$G$19 -> 55000
D26: HW Web Application Firewall | E26: =1000*$E$19 -> 25000 | F26: =900*$F$19 -> 45000 | G26: =800*$G$19 -> 80000
D27: Network Load Balancers | E27: =800*$E$19 -> 20000 | F27: =700*$F$19 -> 35000 | G27: =650*$G$19 -> 65000

Sheet CySec Service Packs
D2: Service Area | E2: Basic | F2: Standard | G2: Advanced | H2: Customised
D3: Service Window (hr x Days) | E3: Mon - Fri (9AM - 6PM) | F3: Mon - Sat (7AM - 11PM) | G3: 24x7x365 | H3: Advanced + Customised SOW
D4: Support Model | E4: Reactive | F4: Proactive | G4: Predictive | H4: Advanced + Customised SOW
D5: Service Levels (Response)
D6: P1 | E6: 2h | F6: 1h | G6: 1h | H6: 30 mins
D7: P2 | E7: 4h | F7: 2h | G7: 2h | H7: 1 hr
D8: P3 | E8: 8h | F8: 4h | G8: 4h | H8: 2 hr
D9: Service Coverage & Inclusions (Ticket basis)
D10: OEM Support | E10: OEM Call Logging + follow-up till resolution | F10: OEM Call Logging + follow-up till resolution | G10: OEM Call Logging + follow-up till resolution | H10: Customised Support as desired
D11: Galaxy L1 Support | E11: Product Navigation | F11: Product Navigation | G11: Product Navigation
D12: Patch Deployment | F12: As required | G12: As required
D13: Product Support - L1/L2 | F13: As required | G13: As required
D14: Proactive Health-Check | G14: Quarterly
D15: Configuration Change | F15: upto 4 changes per year | G15: upto 12 changes per year
D16: Tickets (Yearly) | E16: 25 | F16: 50 | G16: 100 | H16: Unlimited
D17: Pricing (Annual ticket packs) Pricing in INR
D18: Cloud Firewalls | E18: =500*$E$16 -> 12500 | F18: =480*$F$16 -> 24000 | G18: =460*$G$16 -> 46000 | H18: Contact BU Pre-Sales
D19: CSPM / CNAP | E19: =1000*$E$16 -> 25000 | F19: =800*$F$16 -> 40000 | G19: =750*$G$16 -> 75000
D20: Web Application Firewall | E20: =500*$E$16 -> 12500 | F20: =480*$F$16 -> 24000 | G20: =460*$G$16 -> 46000
D21: EDR / XDR | E21: =300*$E$16 -> 7500 | F21: =290*$F$16 -> 14500 | G21: =280*$G$16 -> 28000
D22: IAM / PAM | E22: =500*$E$16 -> 12500 | F22: =480*$F$16 -> 24000 | G22: =460*$G$16 -> 46000
D23: DLP | E23: =500*$E$16 -> 12500 | F23: =480*$F$16 -> 24000 | G23: =460*$G$16 -> 46000
D24: E-mail Security | E24: =500*$E$16 -> 12500 | F24: =480*$F$16 -> 24000 | G24: =460*$G$16 -> 46000
D25: Encryption | E25: =500*$E$16 -> 12500 | F25: =480*$F$16 -> 24000 | G25: =460*$G$16 -> 46000
D26: SASE (CASB, DNS Sec, SWG, ZTNA etc.) | E26: =500*$E$16 -> 12500 | F26: =480*$F$16 -> 24000 | G26: =460*$G$16 -> 46000
