Workbook

Sheet V1 · Individual
A1: VIEW 1 — INDIVIDUAL CONTRIBUTION | Booking (Revenue) | H1 & Annual
A2: # | B2: Employee Name | C2: Division | D2: FY | E2: Type / Notes | F2: Q1 Quota (₹ Cr) | G2: Q1 Actuals (₹ Cr) | H2: Attainment % (Q1) | I2: Q2 Quota (₹ Cr) | J2: Q2 Actuals (₹ Cr) | K2: Attainment % (Q2) | L2: H1 Quota (₹ Cr) | M2: H1 Actuals (₹ Cr) | N2: Attainment % (H1) | O2: H2 Quota (₹ Cr) | P2: H2 Actuals (₹ Cr) | Q2: Attainment % (H2) | R2: Annual Quota (₹ Cr) | S2: Annual Actuals (₹ Cr) | T2: Attainment % (Annual) | U2: # Deals (Total) | V2: Led-By Deals (count) | W2: Led-By Rev (₹ Cr) | X2: Contributed Deals (count) | Y2: Contributed Rev (₹ Cr) | Z2: Rank (Div.)
A3: S1 Division
A4: 1 | B4: Tasneem K | C4: S1 | D4: FY 25-26 | E4: IC | F4: =SUMIF('[1]S1 '!$B:$B,"Tasneem khatri",'[1]S1 '!$H:$H) -> 35.075 | G4: =SUMIF('[2]Opportunity Pipeline'!$F:$F, "Tasneem k",'[2]Opportunity Pipeline'!$O:$O)/10^7 -> 15.920587 | H4: =IFERROR(G4/F4,"-") -> 0.45390128 | I4: =SUMIF('[1]S1 '!$B:$B,"Tasneem khatri",'[1]S1 '!$I:$I) -> 95.275 | J4: =SUMIF('[3]Opportunity Pipeline '!$F:$F,"Tasneem K",'[3]Opportunity Pipeline '!$O:$O)/10^7 -> 1.909654 | K4: =IFERROR(J4/I4,"-") -> 0.0200436 | L4: ='[4]Tasneem- TARGET LETTER - 26-27'!$D$9/10^7 -> 130.35 | M4: =SUM(G4,J4) -> 17.830241 | N4: =IFERROR(M4/L4,"-") -> 0.13678743 | O4: ='[4]Tasneem- TARGET LETTER - 26-27'!$D$16/10^7 -> 129.65 | P4: - | Q4: =IFERROR(P4/O4,"-") -> - | R4: =SUM(L4,O4) -> 260 | S4: =SUM(M4,P4) -> 17.830241 | T4: =IFERROR(S4/R4,"-") -> 0.068577852 | U4: =COUNTIF('[2]Opportunity Pipeline'!$F:$F,"Tasneem K")+ COUNTIF('[3]Opportunity Pipeline '!$F:$F,"Tasneem K") -> 12
A5: 2 | B5: Riya Bhatt | C5: S1 | D5: FY 25-26 | E5: IC | F5: =SUMIF('[1]S1 '!$B:$B,"Riya Roshyara",'[1]S1 '!$H:$H) -> 20 | G5: =SUMIF('[2]Opportunity Pipeline'!$F:$F, "Riya Bhatt",'[2]Opportunity Pipeline'!$O:$O)/10^7 -> 0.5798 | H5: =IFERROR(G5/F5,"-") -> 0.02899 | I5: =SUMIF('[1]S1 '!$B:$B,"Riya Roshyara",'[1]S1 '!$I:$I) -> 38 | J5: =SUMIF('[3]Opportunity Pipeline '!$F:$F,"Riya Bhatt",'[3]Opportunity Pipeline '!$O:$O)/10^7 -> 0 | K5: =IFERROR(J5/I5,"-") -> 0 | L5: ='[5]RIYA- TARGET LETTER - 26-27'!$D$9/10^7 -> 59 | M5: =SUM(G5,J5) -> 0.5798 | N5: =IFERROR(M5/L5,"-") -> 0.0098271186 | O5: ='[5]RIYA- TARGET LETTER - 26-27'!$D$15/10^7 -> 61 | P5: - | Q5: =IFERROR(P5/O5,"-") -> - | R5: =SUM(L5,O5) -> 120 | S5: =SUM(M5,P5) -> 0.5798 | T5: =IFERROR(S5/R5,"-") -> 0.0048316667 | U5: =COUNTIF('[2]Opportunity Pipeline'!$F:$F,"Riya Bhatt")+ COUNTIF('[3]Opportunity Pipeline '!$F:$F,"Riya Bhatt") -> 2
A6: 3 | B6: Pratik Kadam | C6: S1 | D6: FY 25-26 | E6: IC | F6: =SUMIF('[1]S1 '!$B:$B,"Pratik Kadam",'[1]S1 '!$H:$H) -> 3 | G6: =SUMIF('[2]Opportunity Pipeline'!$F:$F, "Pratik Kadam",'[2]Opportunity Pipeline'!$O:$O)/10^7 -> 1.400457 | H6: =IFERROR(G6/F6,"-") -> 0.46681901 | I6: =SUMIF('[1]S1 '!$B:$B,"Pratik Kadam",'[1]S1 '!$I:$I) -> 2 | J6: =SUMIF('[3]Opportunity Pipeline '!$F:$F,"Pratik Kadam",'[3]Opportunity Pipeline '!$O:$O)/10^7 -> 1.2977674 | K6: =IFERROR(J6/I6,"-") -> 0.64888371 | L6: ='[6]Pratik- TARGET LETTER - 26-27'!$D$9/10^7 -> 5 | M6: =SUM(G6,J6) -> 2.6982245 | N6: =IFERROR(M6/L6,"-") -> 0.53964489 | O6: ='[6]Pratik- TARGET LETTER - 26-27'!$D$10/10^7 -> 5 | P6: - | Q6: =IFERROR(P6/O6,"-") -> - | R6: =SUM(L6,O6) -> 10 | S6: =SUM(M6,P6) -> 2.6982245 | T6: =IFERROR(S6/R6,"-") -> 0.26982245 | U6: =COUNTIF('[2]Opportunity Pipeline'!$F:$F,"Pratik Kadam")+ COUNTIF('[3]Opportunity Pipeline '!$F:$F,"Pratik Kadam") -> 50
A7: 4 | B7: Prashant Ddugu | C7: S1 | D7: FY 25-26 | E7: TL | F7: =SUM(F8:F9,7.5) -> 28.8 | G7: =SUM(G8:G9) -> 19.016648 | H7: =IFERROR(G7/F7,"-") -> 0.66030028 | I7: =SUM(I8:I9,5) -> 31.95 | J7: =SUMIF('[3]Opportunity Pipeline '!$F:$F,"Prashant Ddugu",'[3]Opportunity Pipeline '!$O:$O)/10^7 -> 0 | K7: =IFERROR(J7/I7,"-") -> 0 | L7: ='[7]Prashant- TARGET LETTER - 26-27'!$D$9/10^7 -> 60.5 | M7: =SUM(G7,J7) -> 19.016648 | N7: =IFERROR(M7/L7,"-") -> 0.31432476 | O7: ='[7]Prashant- TARGET LETTER - 26-27'!$D$13/10^7 -> 89.5 | P7: - | Q7: =IFERROR(P7/O7,"-") -> - | R7: =SUM(L7,O7) -> 150 | S7: =SUM(M7,P7) -> 19.016648 | T7: =IFERROR(S7/R7,"-") -> 0.12677765 | U7: =COUNTIF('[2]Opportunity Pipeline'!$F:$F,"Prashant Ddugu")+ COUNTIF('[3]Opportunity Pipeline '!$F:$F,"Prashant Ddugu") -> 0
A8: 5 | B8: Chirag Palande | C8: S1 | D8: FY 25-26 | E8: IC | F8: =SUMIF('[1]S1 '!$B:$B,"Chirag Palande",'[1]S1 '!$H:$H) -> 13 | G8: =SUMIF('[2]Opportunity Pipeline'!$F:$F, "Chirag Palande",'[2]Opportunity Pipeline'!$O:$O)/10^7 -> 0.1286674 | H8: =IFERROR(G8/F8,"-") -> 0.0098974923 | I8: =SUMIF('[1]S1 '!$B:$B,"Chirag Palande",'[1]S1 '!$I:$I) -> 10 | J8: =SUMIF('[3]Opportunity Pipeline '!$F:$F,"Chirag Palande",'[3]Opportunity Pipeline '!$O:$O)/10^7 -> 10.8801 | K8: =IFERROR(J8/I8,"-") -> 1.08801 | L8: ='[8]Chirag- TARGET LETTER - 26-27'!$D$9/10^7 -> 27.5 | M8: =SUM(G8,J8) -> 11.008767 | N8: =IFERROR(M8/L8,"-") -> 0.40031881 | O8: ='[8]Chirag- TARGET LETTER - 26-27'!$D$14/10^7 -> 32.5 | P8: - | Q8: =IFERROR(P8/O8,"-") -> - | R8: =SUM(L8,O8) -> 60 | S8: =SUM(M8,P8) -> 11.008767 | T8: =IFERROR(S8/R8,"-") -> 0.18347946 | U8: =COUNTIF('[2]Opportunity Pipeline'!$F:$F,"Chirag Palande")+ COUNTIF('[3]Opportunity Pipeline '!$F:$F,"Chirag Palande") -> 8
A9: 6 | B9: Richa Tiwari | C9: S1 | D9: FY 25-26 | E9: IC | F9: =SUMIF('[1]S1 '!$B:$B,"Richa Tiwari",'[1]S1 '!$H:$H) -> 8.3 | G9: =SUMIF('[2]Opportunity Pipeline'!$F:$F, "RICHA TIWARI",'[2]Opportunity Pipeline'!$O:$O)/10^7 -> 18.887981 | H9: =IFERROR(G9/F9,"-") -> 2.2756603 | I9: =SUMIF('[1]S1 '!$B:$B,"Richa Tiwari",'[1]S1 '!$I:$I) -> 16.95 | J9: =SUMIF('[3]Opportunity Pipeline '!$F:$F,"Richa Tiwari",'[3]Opportunity Pipeline '!$O:$O)/10^7 -> 6.1642152 | K9: =IFERROR(J9/I9,"-") -> 0.36367051 | L9: ='[9]Richa- TARGET LETTER - 26-27'!$D$9/10^7 -> 25 | M9: =SUM(G9,J9) -> 25.052196 | N9: =IFERROR(M9/L9,"-") -> 1.0020878 | O9: ='[9]Richa- TARGET LETTER - 26-27'!$D$12/10^7 -> 35 | P9: - | Q9: =IFERROR(P9/O9,"-") -> - | R9: =SUM(L9,O9) -> 60 | S9: =SUM(M9,P9) -> 25.052196 | T9: =IFERROR(S9/R9,"-") -> 0.4175366 | U9: =COUNTIF('[2]Opportunity Pipeline'!$F:$F,"Richa Tiwari")+ COUNTIF('[3]Opportunity Pipeline '!$F:$F,"Richa Tiwari") -> 67
A10: 7 | B10: Raj Matondkar | C10: S1 | D10: FY 26-27 | E10: IC | F10: =SUMIF('[1]S1 '!$B:$B,"Raj Matondkar",'[1]S1 '!$H:$H) -> 0 | G10: =SUMIF('[2]Opportunity Pipeline'!$F:$F, "Raj Matondkar",'[2]Opportunity Pipeline'!$O:$O)/10^7 -> 0 | H10: =IFERROR(G10/F10,"-") -> - | I10: =SUMIF('[1]S1 '!$B:$B,"Raj Matondkar",'[1]S1 '!$I:$I) -> 0 | J10: =SUMIF('[3]Opportunity Pipeline '!$F:$F,"Raj Matondkar",'[3]Opportunity Pipeline '!$O:$O)/10^7 -> 0.31928 | K10: =IFERROR(J10/I10,"-") -> - | M10: =SUM(G10,J10) -> 0.31928 | N10: =IFERROR(M10/L10,"-") -> - | P10: - | Q10: =IFERROR(P10/O10,"-") -> - | R10: =SUM(L10,O10) -> 0 | S10: =SUM(M10,P10) -> 0.31928 | T10: =IFERROR(S10/R10,"-") -> - | U10: =COUNTIF('[2]Opportunity Pipeline'!$F:$F,"Raj Matondkar")+ COUNTIF('[3]Opportunity Pipeline '!$F:$F,"Raj Matondkar") -> 1
B11: IC Subtotal — S1 | F11: =SUM(F4:F9) -> 108.175 | G11: =SUM(G4,G5,G6,G8,G9) -> 36.917493 | H11: =G11/F11 -> 0.34127564 | I11: =SUM(I4:I9) -> 194.175 | J11: =SUM(J4,J5,J6,J8,J9,J10) -> 20.571017 | K11: =J11/I11 -> 0.1059406 | L11: =SUM(L4:L9) -> 307.35 | M11: =SUM(M4,M5,M6,M8,M9,M10) -> 57.488509 | N11: =M11/L11 -> 0.18704574 | O11: =SUM(O4:O9) -> 352.65 | P11: =SUM(P4:P9) -> 0 | Q11: =P11/O11 -> 0 | R11: =SUM(R4:R9) -> 660 | S11: =SUM(S4,S5,S6,S8,S9,S10) -> 57.488509 | T11: =S11/R11 -> 0.087103802 | U11: =SUM(U4:U10) -> 140
A13: S2 Division
A14: 1 | B14: Rohit Deshmukh | C14: S2 | D14: FY 25-26 | E14: IC | F14: =SUMIF('[1]S2 '!$B$1:$B$45,"Rohit",'[1]S2 '!$G$1:$G$45) -> 29 | G14: =SUMIF('[2]Opportunity Pipeline'!$F:$F, "Rohit Deshmukh",'[2]Opportunity Pipeline'!$O:$O)/10^7 -> 2.2971172 | H14: =IFERROR(G14/F14,"-") -> 0.079210936 | I14: =SUMIF('[1]S2 '!$B$1:$B$45,"Rohit",'[1]S2 '!$H$1:$H$45) -> 53 | J14: =SUMIF('[3]Opportunity Pipeline '!$F:$F,"Rohit Deshmukh",'[3]Opportunity Pipeline '!$O:$O)/10^7 -> 30.822696 | K14: =IFERROR(J14/I14,"-") -> 0.58156031 | L14: ='[10]Rohit- TARGET LETTER - 26-27'!$D$9/10^7 -> 76 | M14: =SUM(G14,J14) -> 33.119813 | N14: =IFERROR(M14/L14,"-") -> 0.43578702 | O14: ='[10]Rohit- TARGET LETTER - 26-27'!$D$12/10^7 -> 59 | P14: - | Q14: =IFERROR(P14/O14,"-") -> - | R14: =SUM(L14,O14) -> 135 | S14: =SUM(M14,P14) -> 33.119813 | T14: =IFERROR(S14/R14,"-") -> 0.24533195 | U14: =COUNTIF('[2]Opportunity Pipeline'!$F:$F,"Rohit Deshmukh")+ COUNTIF('[3]Opportunity Pipeline '!$F:$F,"Rohit Deshmukh") -> 20
A15: 2 | B15: Chetna Sharma | C15: S2 | D15: FY 25-26 | E15: IC | F15: =SUMIF('[1]S2 '!$B$1:$B$45,"Chetna",'[1]S2 '!$G$1:$G$45) -> 8 | G15: =SUMIF('[2]Opportunity Pipeline'!$F:$F, "Chetna Sharma",'[2]Opportunity Pipeline'!$O:$O)/10^7 -> 11.771069 | H15: =IFERROR(G15/F15,"-") -> 1.4713836 | I15: =SUMIF('[1]S2 '!$B$1:$B$45,"Chetna",'[1]S2 '!$H$1:$H$45) -> 10 | J15: =SUMIF('[3]Opportunity Pipeline '!$F:$F,"Chetna Sharma",'[3]Opportunity Pipeline '!$O:$O)/10^7 -> 8.5199639 | K15: =IFERROR(J15/I15,"-") -> 0.85199639 | L15: ='[11]Chetna- TARGET LETTER - 26-27'!$D$9/10^7 -> 20 | M15: =SUM(G15,J15) -> 20.291033 | N15: =IFERROR(M15/L15,"-") -> 1.0145516 | O15: ='[11]Chetna- TARGET LETTER - 26-27'!$D$17/10^7 -> 49 | P15: - | Q15: =IFERROR(P15/O15,"-") -> - | R15: =SUM(L15,O15) -> 69 | S15: =SUM(M15,P15) -> 20.291033 | T15: =IFERROR(S15/R15,"-") -> 0.29407293 | U15: =COUNTIF('[2]Opportunity Pipeline'!$F:$F,"Chetna Sharma")+ COUNTIF('[3]Opportunity Pipeline '!$F:$F,"Chetna Sharma") -> 11
A16: 3 | B16: Sankeerth Bhargav | C16: S2 | D16: FY 25-26 | E16: IC | F16: =SUMIF('[1]S2 '!$B$1:$B$45,"Sankeerth",'[1]S2 '!$G$1:$G$45) -> 2.75 | G16: =SUMIF('[2]Opportunity Pipeline'!$F:$F, "Sankeerth Bhargav",'[2]Opportunity Pipeline'!$O:$O)/10^7 -> 0.21652 | H16: =IFERROR(G16/F16,"-") -> 0.078734545 | I16: =SUMIF('[1]S2 '!$B$1:$B$45,"Sankeerth",'[1]S2 '!$H$1:$H$45) -> 2.75 | J16: =SUMIF('[3]Opportunity Pipeline '!$F:$F,"Sankeerth Bhargav",'[3]Opportunity Pipeline '!$O:$O)/10^7 -> 4.0192631 | K16: =IFERROR(J16/I16,"-") -> 1.4615502 | L16: ='[12]Sankeerth TARGET LETTER - 26-27'!$D$9/10^7 -> 11.75 | M16: =SUM(G16,J16) -> 4.2357831 | N16: =IFERROR(M16/L16,"-") -> 0.36049218 | O16: ='[12]Sankeerth TARGET LETTER - 26-27'!$D$15/10^7 -> 30.25 | P16: - | Q16: =IFERROR(P16/O16,"-") -> - | R16: =SUM(L16,O16) -> 42 | S16: =SUM(M16,P16) -> 4.2357831 | T16: =IFERROR(S16/R16,"-") -> 0.10085198 | U16: =COUNTIF('[2]Opportunity Pipeline'!$F:$F,"Sankeerth Bhargav")+ COUNTIF('[3]Opportunity Pipeline '!$F:$F,"Sankeerth Bhargav") -> 8
A17: 4 | B17: TBH (Varsha) | C17: S2 | D17: FY 25-26 | E17: IC | F17: =SUMIF('[1]S2 '!$B$1:$B$45,"Varsha",'[1]S2 '!$G$1:$G$45) -> 7.3 | G17: =SUMIF('[2]Opportunity Pipeline'!$F:$F, "Varsha Ray",'[2]Opportunity Pipeline'!$O:$O)/10^7 -> 1.055469 | H17: =IFERROR(G17/F17,"-") -> 0.14458479 | I17: =SUMIF('[1]S2 '!$B$1:$B$45,"Varsha",'[1]S2 '!$H$1:$H$45) -> 9.8 | J17: =SUMIF('[3]Opportunity Pipeline '!$F:$F,"Varsha Ray",'[3]Opportunity Pipeline '!$O:$O)/10^7 -> 0 | K17: =IFERROR(J17/I17,"-") -> 0 | L17: =IFERROR(K17/J17,"-") -> - | M17: =SUM(G17,J17) -> 1.055469 | N17: =IFERROR(M17/L17,"-") -> - | O17: =IFERROR(N17/M17,"-") -> - | P17: - | Q17: =IFERROR(P17/O17,"-") -> - | R17: =SUM(L17,O17) -> 0 | S17: =SUM(M17,P17) -> 1.055469 | T17: =IFERROR(S17/R17,"-") -> - | U17: =COUNTIF('[2]Opportunity Pipeline'!$F:$F,"Varsha Ray")+ COUNTIF('[3]Opportunity Pipeline '!$F:$F,"Varsha Ray") -> 4
A18: 5 | B18: TBH (Arpit) | C18: S2 | D18: FY 25-26 | E18: IC | F18: =SUMIF('[1]S2 '!$B$1:$B$45,"Arpit",'[1]S2 '!$G$1:$G$45) -> 6.75 | G18: =SUMIF('[2]Opportunity Pipeline'!$F:$F, "Arpit Srivastava",'[2]Opportunity Pipeline'!$O:$O)/10^7 -> 0.056395833 | H18: =IFERROR(G18/F18,"-") -> 0.0083549382 | I18: =SUMIF('[1]S2 '!$B$1:$B$45,"Arpit",'[1]S2 '!$H$1:$H$45) -> 6.75 | J18: =SUMIF('[3]Opportunity Pipeline '!$F:$F,"Arpit Srivastava",'[3]Opportunity Pipeline '!$O:$O)/10^7 -> 0 | K18: =IFERROR(J18/I18,"-") -> 0 | L18: =IFERROR(K18/J18,"-") -> - | M18: =SUM(G18,J18) -> 0.056395833 | N18: =IFERROR(M18/L18,"-") -> - | O18: =IFERROR(N18/M18,"-") -> - | P18: - | Q18: =IFERROR(P18/O18,"-") -> - | R18: =SUM(L18,O18) -> 0 | S18: =SUM(M18,P18) -> 0.056395833 | T18: =IFERROR(S18/R18,"-") -> - | U18: =COUNTIF('[2]Opportunity Pipeline'!$F:$F,"Arpit Srivastava")+ COUNTIF('[3]Opportunity Pipeline '!$F:$F,"Arpit Srivastava") -> 2
A19: 6 | B19: TBH (Dennis) | C19: S2 | D19: FY 25-26 | E19: IC | F19: =SUMIF('[1]S2 '!$B$1:$B$45,"Dennis",'[1]S2 '!$G$1:$G$45) -> 1.05 | G19: =SUMIF('[2]Opportunity Pipeline'!$F:$F, "Dennis",'[2]Opportunity Pipeline'!$O:$O)/10^7 -> 0 | H19: =IFERROR(G19/F19,"-") -> 0 | I19: =SUMIF('[1]S2 '!$B$1:$B$45,"Dennis",'[1]S2 '!$H$1:$H$45) -> 1.85 | J19: =SUMIF('[3]Opportunity Pipeline '!$F:$F,"Dennis",'[3]Opportunity Pipeline '!$O:$O)/10^7 -> 0 | K19: =IFERROR(J19/I19,"-") -> 0 | L19: =IFERROR(K19/J19,"-") -> - | M19: =SUM(G19,J19) -> 0 | N19: =IFERROR(M19/L19,"-") -> - | O19: =IFERROR(N19/M19,"-") -> - | P19: - | Q19: =IFERROR(P19/O19,"-") -> - | R19: =SUM(L19,O19) -> 0 | S19: =SUM(M19,P19) -> 0 | T19: =IFERROR(S19/R19,"-") -> - | U19: =COUNTIF('[2]Opportunity Pipeline'!$F:$F,"Dennis")+ COUNTIF('[3]Opportunity Pipeline '!$F:$F,"Dennis") -> 0
B20: IC Subtotal — S2 | F20: =SUM(F14:F19) -> 54.85 | G20: =SUM(G14:G19) -> 15.396571 | H20: =G20/F20 -> 0.2807032 | I20: =SUM(I14:I19) -> 84.15 | J20: =SUM(J14:J19) -> 43.361923 | K20: =J20/I20 -> 0.51529321 | L20: =SUM(L14:L19) -> 107.75 | M20: =SUM(M14:M19) -> 58.758494 | N20: =M20/L20 -> 0.54532245 | O20: =SUM(O14:O19) -> 138.25 | P20: =SUM(P14:P19) -> 0 | Q20: =P20/O20 -> 0 | R20: =SUM(R14:R19) -> 246 | S20: =SUM(S14:S19) -> 58.758494 | T20: =S20/R20 -> 0.23885567 | U20: =SUM(U14:U19) -> 45
A22: CB Division
A23: 1 | B23: Prachi Mayekar | C23: CB | D23: FY 26-27 | E23: IC | F23: =SUMIF('[1]CB '!$A$1:$A$16,"Prachi Mayekar",'[1]CB '!$C$1:$C$16) -> 7.5 | G23: =SUMIF('[2]Opportunity Pipeline'!$F:$F, "Prachi Mayekar",'[2]Opportunity Pipeline'!$O:$O)/10^7 -> 12.897684 | H23: =IFERROR(G23/F23,"-") -> 1.7196913 | I23: =SUMIF('[1]CB '!$A$1:$A$16,"Prachi Mayekar",'[1]CB '!$D$1:$D$22) -> 7.5 | J23: =SUMIF('[3]Opportunity Pipeline '!$F:$F,"Prachi Mayekar",'[3]Opportunity Pipeline '!$O:$O)/10^7 -> 8.2155 | K23: =IFERROR(J23/I23,"-") -> 1.0954 | L23: ='[13]Prachi TARGET LETTER - 26-27'!$D$9/10^7 -> 15 | M23: =SUM(G23,J23) -> 21.113184 | N23: =IFERROR(M23/L23,"-") -> 1.4075456 | O23: ='[13]Prachi TARGET LETTER - 26-27'!$D$10/10^7 -> 18 | P23: - | Q23: =IFERROR(P23/O23,"-") -> - | R23: =SUM(L23,O23) -> 33 | S23: =SUM(M23,P23) -> 21.113184 | T23: =IFERROR(S23/R23,"-") -> 0.63979347 | U23: =COUNTIF('[2]Opportunity Pipeline'!$F:$F,"Prachi Mayekar")+ COUNTIF('[3]Opportunity Pipeline '!$F:$F,"Prachi Mayekar") -> 40
A24: 2 | B24: Shilpa Kavde | C24: CB | D24: FY 26-27 | E24: IC | F24: =SUMIF('[1]CB '!$A$1:$A$16,"Shilpa Kavde",'[1]CB '!$C$1:$C$16) -> 5 | G24: =SUMIF('[2]Opportunity Pipeline'!$F:$F, "Shilpa Kavde",'[2]Opportunity Pipeline'!$O:$O)/10^7 -> 2.9018714 | H24: =IFERROR(G24/F24,"-") -> 0.58037427 | I24: =SUMIF('[1]CB '!$A$1:$A$16,"Shilpa Kavde",'[1]CB '!$D$1:$D$22) -> 10 | J24: =SUMIF('[3]Opportunity Pipeline '!$F:$F,"Shilpa Kavde",'[3]Opportunity Pipeline '!$O:$O)/10^7 -> 0.227021 | K24: =IFERROR(J24/I24,"-") -> 0.0227021 | L24: ='[14]Shilpa TARGET LETTER - 26-27'!$D$9/10^7 -> 15 | M24: =SUM(G24,J24) -> 3.1288924 | N24: =IFERROR(M24/L24,"-") -> 0.20859282 | O24: ='[14]Shilpa TARGET LETTER - 26-27'!$D$10/10^7 -> 25 | P24: - | Q24: =IFERROR(P24/O24,"-") -> - | R24: =SUM(L24,O24) -> 40 | S24: =SUM(M24,P24) -> 3.1288924 | T24: =IFERROR(S24/R24,"-") -> 0.078222309 | U24: =COUNTIF('[2]Opportunity Pipeline'!$F:$F,"Shilpa Kavde")+ COUNTIF('[3]Opportunity Pipeline '!$F:$F,"Shilpa Kavde") -> 33
A25: 3 | B25: Vidula Chawan | C25: CB | D25: FY 26-27 | E25: IC | F25: =SUMIF('[1]CB '!$A$1:$A$22,"Vidula Chavan",'[1]CB '!$C$1:$C$22) -> 1 | G25: =SUMIF('[2]Opportunity Pipeline'!$F:$F, "Vidula Chawan",'[2]Opportunity Pipeline'!$O:$O)/10^7 -> 0.00384 | H25: =IFERROR(G25/F25,"-") -> 0.00384 | I25: =SUMIF('[1]CB '!$A$1:$A$22,"Vidula Chavan",'[1]CB '!$D$1:$D$22) -> 2 | J25: =SUMIF('[3]Opportunity Pipeline '!$F:$F,"Vidula Chavan",'[3]Opportunity Pipeline '!$O:$O)/10^7 -> 0 | K25: =IFERROR(J25/I25,"-") -> 0 | L25: ='[15]Vidula TARGET LETTER - 26-27'!$D$9/10^7 -> 3 | M25: =SUM(G25,J25) -> 0.00384 | N25: =IFERROR(M25/L25,"-") -> 0.00128 | O25: ='[15]Vidula TARGET LETTER - 26-27'!$D$10/10^7 -> 6.5 | P25: - | Q25: =IFERROR(P25/O25,"-") -> - | R25: =SUM(L25,O25) -> 9.5 | S25: =SUM(M25,P25) -> 0.00384 | T25: =IFERROR(S25/R25,"-") -> 0.00040421053 | U25: =COUNTIF('[2]Opportunity Pipeline'!$F:$F,"Vidula Chawan")+ COUNTIF('[3]Opportunity Pipeline '!$F:$F,"Vidula Chawan") -> 4
A26: 4 | B26: Jimesh Shah | C26: CB | D26: FY 26-27 | E26: TL | F26: 5 | G26: =SUMIF('[2]Opportunity Pipeline'!$F:$F, "Jimesh Shah",'[2]Opportunity Pipeline'!$O:$O)/10^7 -> 0.0227272 | H26: =IFERROR(G26/F26,"-") -> 0.00454544 | I26: 10 | J26: =SUMIF('[3]Opportunity Pipeline '!$F:$F,"Jimesh Shah",'[3]Opportunity Pipeline '!$O:$O)/10^7 -> 0.02524 | K26: =IFERROR(J26/I26,"-") -> 0.002524 | L26: ='[16]Jimesh TARGET LETTER - 26-27'!$D$9/10^7 -> 15 | M26: =SUM(G26,J26) -> 0.0479672 | N26: =IFERROR(M26/L26,"-") -> 0.0031978133 | O26: ='[16]Jimesh TARGET LETTER - 26-27'!$D$13/10^7 -> 30 | P26: - | Q26: =IFERROR(P26/O26,"-") -> - | R26: =SUM(L26,O26) -> 45 | S26: =SUM(M26,P26) -> 0.0479672 | T26: =IFERROR(S26/R26,"-") -> 0.0010659378 | U26: =COUNTIF('[2]Opportunity Pipeline'!$F:$F,"Jimesh Shah")+ COUNTIF('[3]Opportunity Pipeline '!$F:$F,"Jimesh Shah") -> 8
B27: IC Subtotal — CB | F27: =SUM(F21:F26) -> 18.5 | G27: =SUM(G23:G25) -> 15.803396 | H27: =G27/F27 -> 0.85423761 | I27: =SUM(I21:I26) -> 29.5 | J27: =SUM(J23:J25) -> 8.442521 | K27: =J27/I27 -> 0.28618715 | L27: =SUM(L21:L26) -> 48 | M27: =SUM(M21:M25) -> 24.245917 | N27: =M27/L27 -> 0.50512327 | O27: =SUM(O21:O26) -> 79.5 | P27: =SUM(P21:P26) -> 0 | Q27: =P27/O27 -> 0 | R27: =SUM(R21:R26) -> 127.5 | S27: =SUM(S21:S25) -> 24.245917 | T27: =S27/R27 -> 0.19016405 | U27: =SUM(U21:U25) -> 77
A29: GB Division
A30: 1 | B30: Ashish Singh | C30: GB | D30: FY 26-27 | E30: IC, Cloud | F30: =SUMIF('[1]GB '!$A$1:$A$28,"Ashish",'[1]GB '!$C$1:$C$28) -> 2 | G30: =SUMIF('[2]Opportunity Pipeline'!$F:$F, "Ashish Singh",'[2]Opportunity Pipeline'!$O:$O)/10^7 -> 1.3458431 | H30: =IFERROR(G30/F30,"-") -> 0.67292153 | I30: =SUMIF('[1]GB '!$A$1:$A$28,"Ashish",'[1]GB '!$D$1:$D$28) -> 3 | J30: =SUMIF('[3]Opportunity Pipeline '!$F:$F,"Ashish Singh",'[3]Opportunity Pipeline '!$O:$O)/10^7 -> 0.078503 | K30: =IFERROR(J30/I30,"-") -> 0.026167667 | L30: ='[17]Ashish Target Letter 26 27 '!$D$9/10^7 -> 5 | M30: =SUM(G30,J30) -> 1.4243461 | N30: =IFERROR(M30/L30,"-") -> 0.28486921 | O30: ='[17]Ashish Target Letter 26 27 '!$D$10/10^7 -> 10 | P30: - | Q30: =IFERROR(P30/O30,"-") -> - | R30: =SUM(L30,O30) -> 15 | S30: =SUM(M30,P30) -> 1.4243461 | T30: =IFERROR(S30/R30,"-") -> 0.094956404 | U30: =COUNTIF('[2]Opportunity Pipeline'!$F:$F,"Ashish Singh")+ COUNTIF('[3]Opportunity Pipeline '!$F:$F,"Ashish Singh") -> 12
A31: 2 | B31: Rima Kamalakar Ingle | C31: GB | D31: FY 26-27 | E31: IC, Cloud | F31: ='[18]Rima Target Letter 26 27 '!$D$9/10^7 -> 3 | G31: =SUMIF('[2]Opportunity Pipeline'!$F:$F, "Rima Ingle",'[2]Opportunity Pipeline'!$O:$O)/10^7 -> 0 | H31: =IFERROR(G31/F31,"-") -> 0 | I31: ='[18]Rima Target Letter 26 27 '!$D$10/10^7 -> 5 | J31: =SUMIF('[3]Opportunity Pipeline '!$F:$F,"Rima Ingle",'[3]Opportunity Pipeline '!$O:$O)/10^7 -> 11.929471 | K31: =IFERROR(J31/I31,"-") -> 2.3858942 | L31: ='[18]Rima Target Letter 26 27 '!$D$9/10^7 -> 3 | M31: =SUM(G31,J31) -> 11.929471 | N31: =IFERROR(M31/L31,"-") -> 3.9764903 | O31: ='[18]Rima Target Letter 26 27 '!$D$10/10^7 -> 5 | P31: - | Q31: =IFERROR(P31/O31,"-") -> - | R31: =SUM(L31,O31) -> 8 | S31: =SUM(M31,P31) -> 11.929471 | T31: =IFERROR(S31/R31,"-") -> 1.4911839 | U31: =COUNTIF('[2]Opportunity Pipeline'!$F:$F,"Rima Ingle")+ COUNTIF('[3]Opportunity Pipeline '!$F:$F,"Rima Ingle") -> 3
A32: 3 | B32: Ayushman Singh | C32: GB | D32: FY 26-27 | E32: IC, Cyber security | F32: =SUMIF('[1]GB '!$A$1:$A$28,"Ayushaman",'[1]GB '!$C$1:$C$28) -> 1 | G32: =SUMIF('[2]Opportunity Pipeline'!$F:$F, "Ayushman Singh",'[2]Opportunity Pipeline'!$O:$O)/10^7 -> 0.3020589 | H32: =IFERROR(G32/F32,"-") -> 0.3020589 | I32: =SUMIF('[1]GB '!$A$1:$A$28,"Ayushaman",'[1]GB '!$D$1:$D$28) -> 2 | J32: =SUMIF('[3]Opportunity Pipeline '!$F:$F,"Ayushman Singh",'[3]Opportunity Pipeline '!$O:$O)/10^7 -> 0.0444874 | K32: =IFERROR(J32/I32,"-") -> 0.0222437 | L32: ='[19]Ayushman-TARGET LETTER - 26-27'!$D$9/10^7 -> 3 | M32: =SUM(G32,J32) -> 0.3465463 | N32: =IFERROR(M32/L32,"-") -> 0.11551543 | O32: ='[19]Ayushman-TARGET LETTER - 26-27'!$D$10/10^7 -> 9 | P32: - | Q32: =IFERROR(P32/O32,"-") -> - | R32: =SUM(L32,O32) -> 12 | S32: =SUM(M32,P32) -> 0.3465463 | T32: =IFERROR(S32/R32,"-") -> 0.028878858 | U32: =COUNTIF('[2]Opportunity Pipeline'!$F:$F,"Ayushman Singh")+ COUNTIF('[3]Opportunity Pipeline '!$F:$F,"Ayushman Singh") -> 5
A33: 4 | B33: Shubhangi Srinivasan | C33: GB | D33: FY 26-27 | E33: IC, Cyber security | F33: =SUMIF('[1]GB '!$A$1:$A$28,"Shubhangi",'[1]GB '!$C$1:$C$28) -> 2 | G33: =SUMIF('[2]Opportunity Pipeline'!$F:$F, "Shubhangi Srinivasan",'[2]Opportunity Pipeline'!$O:$O)/10^7 -> 5.5185176 | H33: =IFERROR(G33/F33,"-") -> 2.7592588 | I33: =SUMIF('[1]GB '!$A$1:$A$28,"Shubhangi",'[1]GB '!$D$1:$D$28) -> 3 | J33: =SUMIF('[3]Opportunity Pipeline '!$F:$F,"Shubhangi Srinivasan",'[3]Opportunity Pipeline '!$O:$O)/10^7 -> 0.9112125 | K33: =IFERROR(J33/I33,"-") -> 0.3037375 | L33: ='[20]Shubhangi-TARGET LETTER - 26-27'!$D$9/10^7 -> 5 | M33: =SUM(G33,J33) -> 6.4297301 | N33: =IFERROR(M33/L33,"-") -> 1.285946 | O33: ='[20]Shubhangi-TARGET LETTER - 26-27'!$D$10/10^7 -> 10 | P33: - | Q33: =IFERROR(P33/O33,"-") -> - | R33: =SUM(L33,O33) -> 15 | S33: =SUM(M33,P33) -> 6.4297301 | T33: =IFERROR(S33/R33,"-") -> 0.42864867 | U33: =COUNTIF('[2]Opportunity Pipeline'!$F:$F,"Shubhangi Srinivasan")+ COUNTIF('[3]Opportunity Pipeline '!$F:$F,"Shubhangi Srinivasan") -> 16
A34: 5 | B34: Atharva Karpe | C34: GB | D34: FY 26-27 | E34: IC | F34: =SUMIF('[1]GB '!$A$1:$A$28,"Atharva Kapre",'[1]GB '!$C$1:$C$28) -> 3 | G34: =SUMIF('[2]Opportunity Pipeline'!$F:$F, "Atharva Karpe",'[2]Opportunity Pipeline'!$O:$O)/10^7 -> 6.4578697 | H34: =IFERROR(G34/F34,"-") -> 2.1526232 | I34: =SUMIF('[1]GB '!$A$1:$A$28,"Atharva Kapre",'[1]GB '!$D$1:$D$28) -> 1 | J34: =SUMIF('[3]Opportunity Pipeline '!$F:$F,"Atharva Karpe",'[3]Opportunity Pipeline '!$O:$O)/10^7 -> 0.001802 | K34: =IFERROR(J34/I34,"-") -> 0.001802 | L34: ='[21]Atharva -TARGET LETTER - 26-27'!$D$9/10^7 -> 4 | M34: =SUM(G34,J34) -> 6.4596717 | N34: =IFERROR(M34/L34,"-") -> 1.6149179 | O34: ='[21]Atharva -TARGET LETTER - 26-27'!$D$10/10^7 -> 4 | P34: - | Q34: =IFERROR(P34/O34,"-") -> - | R34: =SUM(L34,O34) -> 8 | S34: =SUM(M34,P34) -> 6.4596717 | T34: =IFERROR(S34/R34,"-") -> 0.80745896 | U34: =COUNTIF('[2]Opportunity Pipeline'!$F:$F,"Atharva Karpe")+ COUNTIF('[3]Opportunity Pipeline '!$F:$F,"Atharva Karpe") -> 13
A35: 6 | B35: Jay Rushi | C35: GB | D35: FY 26-27 | E35: IC | F35: =SUMIF('[1]GB '!$A$1:$A$28,"Jay Rushi",'[1]GB '!$C$1:$C$28) -> 1 | G35: =SUMIF('[2]Opportunity Pipeline'!$F:$F, "Jay Rushi",'[2]Opportunity Pipeline'!$O:$O)/10^7 -> 1.4900934 | H35: =IFERROR(G35/F35,"-") -> 1.4900934 | I35: =SUMIF('[1]GB '!$A$1:$A$28,"Jay Rushi",'[1]GB '!$D$1:$D$28) -> 2 | J35: =SUMIF('[3]Opportunity Pipeline '!$F:$F,"Jay Rushi",'[3]Opportunity Pipeline '!$O:$O)/10^7 -> 0.2900441 | K35: =IFERROR(J35/I35,"-") -> 0.14502205 | L35: ='[22]Jay Rushi TARGET LETTER - 26-27'!$D$9/10^7 -> 3 | M35: =SUM(G35,J35) -> 1.7801375 | N35: =IFERROR(M35/L35,"-") -> 0.59337917 | O35: ='[22]Jay Rushi TARGET LETTER - 26-27'!$D$10/10^7 -> 5 | P35: - | Q35: =IFERROR(P35/O35,"-") -> - | R35: =SUM(L35,O35) -> 8 | S35: =SUM(M35,P35) -> 1.7801375 | T35: =IFERROR(S35/R35,"-") -> 0.22251719 | U35: =COUNTIF('[2]Opportunity Pipeline'!$F:$F,"Jay Rushi")+ COUNTIF('[3]Opportunity Pipeline '!$F:$F,"Jay Rushi") -> 18
A36: 7 | B36: Sana Rashid Bhatkar | C36: GB | D36: FY 26-27 | E36: TL | F36: - | G36: =SUMIF('[2]Opportunity Pipeline'!$F:$F, "Sana",'[2]Opportunity Pipeline'!$O:$O)/10^7 -> 0 | H36: =IFERROR(G36/F36,"-") -> - | I36: - | J36: =SUMIF('[3]Opportunity Pipeline '!$F:$F,"Sana",'[3]Opportunity Pipeline '!$O:$O)/10^7 -> 0 | K36: =IFERROR(J36/I36,"-") -> - | L36: ='[23]SANA -TARGET LETTER - 26-27'!$D$9/10^7 -> 3.2 | M36: =SUM(G36,J36) -> 0 | N36: =IFERROR(M36/L36,"-") -> 0 | O36: ='[23]SANA -TARGET LETTER - 26-27'!$D$14/10^7 -> 6.8 | P36: - | Q36: =IFERROR(P36/O36,"-") -> - | R36: =SUM(L36,O36) -> 10 | S36: =SUM(M36,P36) -> 0 | T36: =IFERROR(S36/R36,"-") -> 0 | U36: =COUNTIF('[2]Opportunity Pipeline'!$F:$F,"Sana")+ COUNTIF('[3]Opportunity Pipeline '!$F:$F,"Sana") -> 0
A37: 8 | B37: Bhumi Karelia | C37: GB | D37: FY 26-27 | E37: IC | F37: =SUMIF('[1]GB '!$A$1:$A$28,"Bhumi ",'[1]GB '!$C$1:$C$28) -> 0.1 | G37: =SUMIF('[2]Opportunity Pipeline'!$F:$F, "Bhumi",'[2]Opportunity Pipeline'!$O:$O)/10^7 -> 0 | H37: =IFERROR(G37/F37,"-") -> 0 | I37: =SUMIF('[1]GB '!$A$1:$A$28,"Bhumi ",'[1]GB '!$D$1:$D$28) -> 0.5 | J37: =SUMIF('[3]Opportunity Pipeline '!$F:$F,"Bhumi Karelia",'[3]Opportunity Pipeline '!$O:$O)/10^7 -> 0 | K37: =IFERROR(J37/I37,"-") -> 0 | L37: ='[24]Bhumi Target Letter 26 27 '!$D$9/10^7 -> 0.6 | M37: =SUM(G37,J37) -> 0 | N37: =IFERROR(M37/L37,"-") -> 0 | O37: ='[24]Bhumi Target Letter 26 27 '!$D$10/10^7 -> 1.4 | P37: - | Q37: =IFERROR(P37/O37,"-") -> - | R37: =SUM(L37,O37) -> 2 | S37: =SUM(M37,P37) -> 0 | T37: =IFERROR(S37/R37,"-") -> 0 | U37: =COUNTIF('[2]Opportunity Pipeline'!$F:$F,"Bhumi Karelia")+ COUNTIF('[3]Opportunity Pipeline '!$F:$F,"Bhumi Karelia") -> 0
A38: 9 | B38: Rizwana Khan | C38: GB | D38: FY 26-27 | E38: IC | F38: =SUMIF('[1]GB '!$A$1:$A$28,"Rizwana (ISR/OSR)",'[1]GB '!$C$1:$C$28) -> 0.5 | G38: =SUMIF('[2]Opportunity Pipeline'!$F:$F, "Rizwana",'[2]Opportunity Pipeline'!$O:$O)/10^7 -> 0 | H38: =IFERROR(G38/F38,"-") -> 0 | I38: =SUMIF('[1]GB '!$A$1:$A$28,"Rizwana (ISR/OSR)",'[1]GB '!$D$1:$D$28) -> 1 | J38: =SUMIF('[3]Opportunity Pipeline '!$F:$F,"Rizwana Khan",'[3]Opportunity Pipeline '!$O:$O)/10^7 -> 0 | K38: =IFERROR(J38/I38,"-") -> 0 | L38: ='[25]Rizwana Target Letter 26 27 '!$D$9/10^7 -> 1.5 | M38: =SUM(G38,J38) -> 0 | N38: =IFERROR(M38/L38,"-") -> 0 | O38: ='[25]Rizwana Target Letter 26 27 '!$D$10/10^7 -> 3.5 | P38: - | Q38: =IFERROR(P38/O38,"-") -> - | R38: =SUM(L38,O38) -> 5 | S38: =SUM(M38,P38) -> 0 | T38: =IFERROR(S38/R38,"-") -> 0 | U38: =COUNTIF('[2]Opportunity Pipeline'!$F:$F,"Rizwana Khan")+ COUNTIF('[3]Opportunity Pipeline '!$F:$F,"Rizwana Khan") -> 0
A39: 10 | B39: Suvesh Malakar | C39: GB | D39: FY 26-27 | E39: IC | F39: =SUMIF('[1]GB '!$A$1:$A$28,"Suyesh",'[1]GB '!$C$1:$C$28) -> 0.1 | G39: =SUMIF('[2]Opportunity Pipeline'!$F:$F, "Suvesh Malakar",'[2]Opportunity Pipeline'!$O:$O)/10^7 -> 0 | H39: =IFERROR(G39/F39,"-") -> 0 | I39: =SUMIF('[1]GB '!$A$1:$A$28,"Suyesh",'[1]GB '!$D$1:$D$28) -> 0.5 | J39: =SUMIF('[3]Opportunity Pipeline '!$F:$F,"Suvesh Malakar",'[3]Opportunity Pipeline '!$O:$O)/10^7 -> 0 | K39: =IFERROR(J39/I39,"-") -> 0 | L39: ='[26]Suvesh- Target Letter 26 27 '!$D$9/10^7 -> 0.6 | M39: =SUM(G39,J39) -> 0 | N39: =IFERROR(M39/L39,"-") -> 0 | O39: ='[26]Suvesh- Target Letter 26 27 '!$D$10/10^7 -> 1.4 | P39: - | Q39: =IFERROR(P39/O39,"-") -> - | R39: =SUM(L39,O39) -> 2 | S39: =SUM(M39,P39) -> 0 | T39: =IFERROR(S39/R39,"-") -> 0 | U39: =COUNTIF('[2]Opportunity Pipeline'!$F:$F,"Suvesh Malakar")+ COUNTIF('[3]Opportunity Pipeline '!$F:$F,"Suvesh Malakar") -> 0
A40: 11 | B40: Varunkumar Mishra | C40: GB | D40: FY 26-27 | E40: IC | F40: =SUMIF('[1]GB '!$A$1:$A$28,"Varunkumar Mishra",'[1]GB '!$C$1:$C$28) -> 0 | G40: =SUMIF('[2]Opportunity Pipeline'!$F:$F, "Varunkumar Mishra",'[2]Opportunity Pipeline'!$O:$O)/10^7 -> 0 | H40: =IFERROR(G40/F40,"-") -> - | I40: =SUMIF('[1]GB '!$A$1:$A$28,"Varunkumar Mishra",'[1]GB '!$D$1:$D$28) -> 0 | J40: =SUMIF('[3]Opportunity Pipeline '!$F:$F,"Varunkumar Mishra",'[3]Opportunity Pipeline '!$O:$O)/10^7 -> 0.0955628 | K40: =IFERROR(J40/I40,"-") -> - | L40: - | M40: =SUM(G40,J40) -> 0.0955628 | N40: =IFERROR(M40/L40,"-") -> - | O40: ='[26]Suvesh- Target Letter 26 27 '!$D$10/10^7 -> 1.4 | P40: - | Q40: =IFERROR(P40/O40,"-") -> - | R40: =SUM(L40,O40) -> 1.4 | S40: =SUM(M40,P40) -> 0.0955628 | T40: =IFERROR(S40/R40,"-") -> 0.068259143 | U40: =COUNTIF('[2]Opportunity Pipeline'!$F:$F,"Varunkumar Mishra")+ COUNTIF('[3]Opportunity Pipeline '!$F:$F,"Varunkumar Mishra") -> 2
B41: IC Subtotal — GB | F41: =SUM(F34:F39) -> 4.7 | G41: =SUM(G30:G40) -> 15.114383 | H41: =G41/F41 -> 3.2158261 | I41: =SUM(I34:I39) -> 5 | J41: =SUM(J30:J40) -> 13.351083 | K41: =J41/I41 -> 2.6702166 | L41: =SUM(L34:L39) -> 12.9 | M41: =SUM(M30:M40) -> 28.465465 | N41: =M41/L41 -> 2.2066252 | O41: =SUM(O34:O39) -> 22.1 | P41: =SUM(P34:P39) -> 0 | Q41: =P41/O41 -> 0 | R41: =SUM(R34:R39) -> 35 | S41: =SUM(S30:S40) -> 28.465465 | T41: =S41/R41 -> 0.81329901 | U41: =SUM(U30:U40) -> 69
A43: South Division
A44: 1 | B44: Abrar Memon | C44: South | D44: FY 26-27 | E44: IC | F44: =SUMIF('[1]South '!$B$1:$B$28,"Abrar Altaf Menon",'[1]South '!$D$1:$D$28) -> 2 | G44: =SUMIF('[2]Opportunity Pipeline'!$F:$F, "Abrar Memon",'[2]Opportunity Pipeline'!$O:$O)/10^7 -> 0.041457089 | H44: =IFERROR(G44/F44,"-") -> 0.020728545 | I44: =SUMIF('[1]South '!$B$1:$B$28,"Abrar Altaf Menon",'[1]South '!$E$1:$E$28) -> 2 | J44: =SUMIF('[3]Opportunity Pipeline '!$F:$F,"Abrar Memon",'[3]Opportunity Pipeline '!$O:$O)/10^7 -> 0.4878 | K44: =IFERROR(J44/I44,"-") -> 0.2439 | L44: ='[27]Abrar TARGET LETTER - 26-27'!$D$9/10^7 -> 4 | M44: =SUM(G44,J44) -> 0.52925709 | N44: =IFERROR(M44/L44,"-") -> 0.13231427 | O44: ='[27]Abrar TARGET LETTER - 26-27'!$D$10/10^7 -> 4 | P44: - | Q44: =IFERROR(P44/O44,"-") -> - | R44: =SUM(L44,O44) -> 8 | S44: =SUM(M44,P44) -> 0.52925709 | T44: =IFERROR(S44/R44,"-") -> 0.066157136 | U44: =COUNTIF('[2]Opportunity Pipeline'!$F:$F,"Abrar Memon")+ COUNTIF('[3]Opportunity Pipeline '!$F:$F,"Abrar Memon") -> 9
...

Sheet V2 · Leadership
A1: VIEW 2 —LEADERSHIP | Booking (Revenue) | H1 & Annual | Bottomline
A2: # | B2: Employee Name | C2: Division | D2: FY | E2: Type / Notes | F2: Q1 Quota (₹ Cr) | G2: Q1 Actuals (₹ Cr) | H2: Attainment % (Q1) | I2: Q2 Quota (₹ Cr) | J2: Q2 Actuals (₹ Cr) | K2: Attainment % (Q2) | L2: H1 Quota (₹ Cr) | M2: H1 Actuals (₹ Cr) | N2: Attainment % (H1) | O2: H2 Quota (₹ Cr) | P2: H2 Actuals (₹ Cr) | Q2: Attainment % (H2) | R2: Annual Quota (₹ Cr) | S2: Annual Actuals (₹ Cr) | T2: Attainment % (Annual) | U2: # Deals (Total)
A3: 1 | B3: Ajay Patodia | C3: DCG | D3: FY 25-26 | E3: Head | G3: =SUMIF('[2]Opportunity Pipeline'!$F:$F,"Ajay Patodia",'[2]Opportunity Pipeline'!$P:$P)/10^7 -> 0.301487 | J3: =SUMIF('[3]Opportunity Pipeline '!$F:$F,"Ajay Patodia",'[3]Opportunity Pipeline '!$P:$P)/10^7 -> 2.353 | L3: =(SUMIF('[2]Opportunity Pipeline'!$F:$F,"Ajay Patodia",'[2]Opportunity Pipeline'!$P:$P)+SUMIF('[3]Opportunity Pipeline '!$F:$F,"Ajay Patodia",'[3]Opportunity Pipeline '!$P:$P))/10^7 -> 2.654487 | S3: =SUM(L3,P3) -> 2.654487 | U3: =COUNTIF('[2]Opportunity Pipeline'!$F:$F,"Ajay Patodia")+ COUNTIF('[3]Opportunity Pipeline '!$F:$F,"Ajay Patodia") -> 39
A4: 2 | B4: Dipti Karpe | C4: S2 | D4: FY 25-26 | E4: AVP | G4: =SUMIF('[2]Opportunity Pipeline'!$F:$F,"Dipti Karpe",'[2]Opportunity Pipeline'!$P:$P)/10^7 -> 0 | J4: =SUMIF('[3]Opportunity Pipeline '!$F:$F,"Dipti Karpe",'[3]Opportunity Pipeline '!$P:$P)/10^7 -> 0 | L4: =(SUMIF('[2]Opportunity Pipeline'!$F:$F,"Dipti Karpe",'[2]Opportunity Pipeline'!$P:$P)+SUMIF('[3]Opportunity Pipeline '!$F:$F,"Dipti Karpe",'[3]Opportunity Pipeline '!$P:$P))/10^7 -> 0 | S4: =SUM(L4,P4) -> 0 | U4: =COUNTIF('[2]Opportunity Pipeline'!$F:$F,"Dipti Karpe")+ COUNTIF('[3]Opportunity Pipeline '!$F:$F,"Dipti Karpe") -> 0
A5: 3 | B5: Ishwari Santosh Kadam | C5: S1 | D5: FY 25-26 | E5: AVP | G5: =SUMIF('[2]Opportunity Pipeline'!$F:$F,"Ishwari Kadam",'[2]Opportunity Pipeline'!$P:$P)/10^7 -> 0.47134 | J5: =SUMIF('[3]Opportunity Pipeline '!$F:$F,"Ishwari Kadam",'[3]Opportunity Pipeline '!$P:$P)/10^7 -> 0 | L5: =(SUMIF('[2]Opportunity Pipeline'!$F:$F,"Ishwari Kadam",'[2]Opportunity Pipeline'!$P:$P)+SUMIF('[3]Opportunity Pipeline '!$F:$F,"Ishwari Kadam",'[3]Opportunity Pipeline '!$P:$P))/10^7 -> 0.47134 | S5: =SUM(L5,P5) -> 0.47134 | U5: =COUNTIF('[2]Opportunity Pipeline'!$F:$F,"Ishwari Kadam")+ COUNTIF('[3]Opportunity Pipeline '!$F:$F,"Ishwari Kadam") -> 4
A6: 4 | B6: Vineet Gadia | C6: CB | D6: FY 25-26 | E6: Head | G6: =SUMIF('[2]Opportunity Pipeline'!$F:$F,"Vineet Gadia",'[2]Opportunity Pipeline'!$P:$P)/10^7 -> 0 | J6: =SUMIF('[3]Opportunity Pipeline '!$F:$F,"Vineet Gadia",'[3]Opportunity Pipeline '!$P:$P)/10^7 -> 0 | L6: =(SUMIF('[2]Opportunity Pipeline'!$F:$F,"Vineet Gadia",'[2]Opportunity Pipeline'!$P:$P)+SUMIF('[3]Opportunity Pipeline '!$F:$F,"Vineet Gadia",'[3]Opportunity Pipeline '!$P:$P))/10^7 -> 0 | S6: =SUM(L6,P6) -> 0 | U6: =COUNTIF('[2]Opportunity Pipeline'!$F:$F,"Vineet Gadia")+ COUNTIF('[3]Opportunity Pipeline '!$F:$F,"Vineet Gadia") -> 0
A7: 5 | B7: Sanjeev Kohli | C7: GeoX | D7: FY 25-26 | E7: Head | G7: =SUMIF('[2]Opportunity Pipeline'!$F:$F,"Sanjeev Kohli",'[2]Opportunity Pipeline'!$P:$P)/10^7 -> 0.02 | J7: =SUMIF('[3]Opportunity Pipeline '!$F:$F,"Sanjeev Kohli",'[3]Opportunity Pipeline '!$P:$P)/10^7 -> 0.75 | L7: =(SUMIF('[2]Opportunity Pipeline'!$F:$F,"Sanjeev Kohli",'[2]Opportunity Pipeline'!$P:$P)+SUMIF('[3]Opportunity Pipeline '!$F:$F,"Sanjeev Kohli",'[3]Opportunity Pipeline '!$P:$P))/10^7 -> 0.77 | S7: =SUM(L7,P7) -> 0.77 | U7: =COUNTIF('[2]Opportunity Pipeline'!$F:$F,"Sanjeev Kohli")+ COUNTIF('[3]Opportunity Pipeline '!$F:$F,"Sanjeev Kohli") -> 2
A8: 6 | B8: Yogesh Bhatia | C8: GB | D8: FY 25-26 | E8: Head | G8: =SUMIF('[2]Opportunity Pipeline'!$F:$F,"Yogesh Bhatia",'[2]Opportunity Pipeline'!$P:$P)/10^7 -> 0 | J8: =SUMIF('[3]Opportunity Pipeline '!$F:$F,"Yogesh Bhatia",'[3]Opportunity Pipeline '!$P:$P)/10^7 -> 0.0025 | L8: =(SUMIF('[2]Opportunity Pipeline'!$F:$F,"Yogesh Bhatia",'[2]Opportunity Pipeline'!$P:$P)+SUMIF('[3]Opportunity Pipeline '!$F:$F,"Yogesh Bhatia",'[3]Opportunity Pipeline '!$P:$P))/10^7 -> 0.0025 | S8: =SUM(L8,P8) -> 0.0025 | U8: =COUNTIF('[2]Opportunity Pipeline'!$F:$F,"Yogesh Bhatia")+ COUNTIF('[3]Opportunity Pipeline '!$F:$F,"Yogesh Bhatia") -> 1
A9: 7 | B9: Jitesh Rajput | C9: Cloud | D9: FY 25-26 | E9: Head | G9: =SUMIF('[2]Opportunity Pipeline'!$F:$F,"Jitesh Rajput",'[2]Opportunity Pipeline'!$P:$P)/10^7 -> 0.001333 | J9: =SUMIF('[3]Opportunity Pipeline '!$F:$F,"Jitesh Rajput",'[3]Opportunity Pipeline '!$P:$P)/10^7 -> 0 | L9: =(SUMIF('[2]Opportunity Pipeline'!$F:$F,"Jitesh Rajput",'[2]Opportunity Pipeline'!$P:$P)+SUMIF('[3]Opportunity Pipeline '!$F:$F,"Jitesh Rajput",'[3]Opportunity Pipeline '!$P:$P))/10^7 -> 0.001333 | S9: =SUM(L9,P9) -> 0.001333 | U9: =COUNTIF('[2]Opportunity Pipeline'!$F:$F,"Jitesh Rajput")+ COUNTIF('[3]Opportunity Pipeline '!$F:$F,"Jitesh Rajput") -> 3
A10: 8 | B10: Rocky Braganza | C10: CSN | D10: FY 25-26 | E10: Head | G10: =SUMIF('[2]Opportunity Pipeline'!$F:$F,"Rocky Braganza",'[2]Opportunity Pipeline'!$P:$P)/10^7 -> 0 | J10: =SUMIF('[3]Opportunity Pipeline '!$F:$F,"Rocky Braganza",'[3]Opportunity Pipeline '!$P:$P)/10^7 -> 0 | L10: =(SUMIF('[2]Opportunity Pipeline'!$F:$F,"Rocky Braganza",'[2]Opportunity Pipeline'!$P:$P)+SUMIF('[3]Opportunity Pipeline '!$F:$F,"Rocky Braganza",'[3]Opportunity Pipeline '!$P:$P))/10^7 -> 0 | S10: =SUM(L10,P10) -> 0 | U10: =COUNTIF('[2]Opportunity Pipeline'!$F:$F,"Rocky Braganza")+ COUNTIF('[3]Opportunity Pipeline '!$F:$F,"Rocky Braganza") -> 0
L11: =SUM(L3:L10) -> 3.89966 | S11: =SUM(S3:S10) -> 3.89966 | U11: =SUM(U3:U10) -> 49
A13: VIEW 2 —LEADERSHIP | Booking (Revenue) | H1 & Annual | Topline
A14: # | B14: Employee Name | C14: Division | D14: FY | E14: Type / Notes | F14: Q1 Quota (₹ Cr) | G14: Q1 Actuals (₹ Cr) | H14: Attainment % (Q1) | I14: Q2 Quota (₹ Cr) | J14: Q2 Actuals (₹ Cr) | K14: Attainment % (Q2) | L14: H1 Quota (₹ Cr) | M14: H1 Actuals (₹ Cr) | N14: Attainment % (H1) | O14: H2 Quota (₹ Cr) | P14: H2 Actuals (₹ Cr) | Q14: Attainment % (H2) | R14: Annual Quota (₹ Cr) | S14: Annual Actuals (₹ Cr) | T14: Attainment % (Annual) | U14: # Deals (Total)
A15: 1 | B15: Ajay Patodia | C15: DCG | D15: FY 25-26 | E15: Head | G15: =SUMIF('[2]Opportunity Pipeline'!$F:$F,"Ajay Patodia",'[2]Opportunity Pipeline'!$O:$O)/10^7 -> 9.4460406 | J15: =SUMIF('[3]Opportunity Pipeline '!$F:$F,"Ajay Patodia",'[3]Opportunity Pipeline '!$O:$O)/10^7 -> 25.866097 | L15: =(SUMIF('[2]Opportunity Pipeline'!$F:$F,"Ajay Patodia",'[2]Opportunity Pipeline'!$O:$O)+SUMIF('[3]Opportunity Pipeline '!$F:$F,"Ajay Patodia",'[3]Opportunity Pipeline '!$O:$O))/10^7 -> 35.312138 | S15: =SUM(L15,P15) -> 35.312138 | U15: =COUNTIF('[2]Opportunity Pipeline'!$F:$F,"Ajay Patodia")+ COUNTIF('[3]Opportunity Pipeline '!$F:$F,"Ajay Patodia") -> 39
A16: 2 | B16: Dipti Karpe | C16: S2 | D16: FY 25-26 | E16: AVP | G16: =SUMIF('[2]Opportunity Pipeline'!$F:$F,"Dipti Karpe",'[2]Opportunity Pipeline'!$O:$O)/10^7 -> 0 | J16: =SUMIF('[3]Opportunity Pipeline '!$F:$F,"Dipti Karpe",'[3]Opportunity Pipeline '!$O:$O)/10^7 -> 0 | L16: =(SUMIF('[2]Opportunity Pipeline'!$F:$F,"Dipti Karpe",'[2]Opportunity Pipeline'!$O:$O)+SUMIF('[3]Opportunity Pipeline '!$F:$F,"Dipti Karpe",'[3]Opportunity Pipeline '!$O:$O))/10^7 -> 0 | S16: =SUM(L16,P16) -> 0 | U16: =COUNTIF('[2]Opportunity Pipeline'!$F:$F,"Dipti Karpe")+ COUNTIF('[3]Opportunity Pipeline '!$F:$F,"Dipti Karpe") -> 0
A17: 3 | B17: Ishwari Santosh Kadam | C17: S1 | D17: FY 25-26 | E17: AVP | G17: =SUMIF('[2]Opportunity Pipeline'!$F:$F,"Ishwari Kadam",'[2]Opportunity Pipeline'!$O:$O)/10^7 -> 6.26694 | J17: =SUMIF('[3]Opportunity Pipeline '!$F:$F,"Ishwari Kadam",'[3]Opportunity Pipeline '!$O:$O)/10^7 -> 0 | L17: =(SUMIF('[2]Opportunity Pipeline'!$F:$F,"Ishwari Kadam",'[2]Opportunity Pipeline'!$O:$O)+SUMIF('[3]Opportunity Pipeline '!$F:$F,"Ishwari Kadam",'[3]Opportunity Pipeline '!$O:$O))/10^7 -> 6.26694 | S17: =SUM(L17,P17) -> 6.26694 | U17: =COUNTIF('[2]Opportunity Pipeline'!$F:$F,"Ishwari Kadam")+ COUNTIF('[3]Opportunity Pipeline '!$F:$F,"Ishwari Kadam") -> 4
A18: 4 | B18: Vineet Gadia | C18: CB | D18: FY 25-26 | E18: Head | G18: =SUMIF('[2]Opportunity Pipeline'!$F:$F,"Vineet Gadia",'[2]Opportunity Pipeline'!$O:$O)/10^7 -> 0 | J18: =SUMIF('[3]Opportunity Pipeline '!$F:$F,"Vineet Gadia",'[3]Opportunity Pipeline '!$O:$O)/10^7 -> 0 | L18: =(SUMIF('[2]Opportunity Pipeline'!$F:$F,"Vineet Gadia",'[2]Opportunity Pipeline'!$O:$O)+SUMIF('[3]Opportunity Pipeline '!$F:$F,"Vineet Gadia",'[3]Opportunity Pipeline '!$O:$O))/10^7 -> 0 | S18: =SUM(L18,P18) -> 0 | U18: =COUNTIF('[2]Opportunity Pipeline'!$F:$F,"Vineet Gadia")+ COUNTIF('[3]Opportunity Pipeline '!$F:$F,"Vineet Gadia") -> 0
A19: 5 | B19: Sanjeev Kohli | C19: GeoX | D19: FY 25-26 | E19: Head | G19: =SUMIF('[2]Opportunity Pipeline'!$F:$F,"Sanjeev Kohli",'[2]Opportunity Pipeline'!$O:$O)/10^7 -> 2.19665 | J19: =SUMIF('[3]Opportunity Pipeline '!$F:$F,"Sanjeev Kohli",'[3]Opportunity Pipeline '!$O:$O)/10^7 -> 17.005643 | L19: =(SUMIF('[2]Opportunity Pipeline'!$F:$F,"Sanjeev Kohli",'[2]Opportunity Pipeline'!$O:$O)+SUMIF('[3]Opportunity Pipeline '!$F:$F,"Sanjeev Kohli",'[3]Opportunity Pipeline '!$O:$O))/10^7 -> 19.202293 | S19: =SUM(L19,P19) -> 19.202293 | U19: =COUNTIF('[2]Opportunity Pipeline'!$F:$F,"Sanjeev Kohli")+ COUNTIF('[3]Opportunity Pipeline '!$F:$F,"Sanjeev Kohli") -> 2
A20: 6 | B20: Yogesh Bhatia | C20: GB | D20: FY 25-26 | E20: Head | G20: =SUMIF('[2]Opportunity Pipeline'!$F:$F,"Yogesh Bhatia",'[2]Opportunity Pipeline'!$O:$O)/10^7 -> 0 | J20: =SUMIF('[3]Opportunity Pipeline '!$F:$F,"Yogesh Bhatia",'[3]Opportunity Pipeline '!$O:$O)/10^7 -> 0.0465 | L20: =(SUMIF('[2]Opportunity Pipeline'!$F:$F,"Yogesh Bhatia",'[2]Opportunity Pipeline'!$O:$O)+SUMIF('[3]Opportunity Pipeline '!$F:$F,"Yogesh Bhatia",'[3]Opportunity Pipeline '!$O:$O))/10^7 -> 0.0465 | S20: =SUM(L20,P20) -> 0.0465 | U20: =COUNTIF('[2]Opportunity Pipeline'!$F:$F,"Yogesh Bhatia")+ COUNTIF('[3]Opportunity Pipeline '!$F:$F,"Yogesh Bhatia") -> 1
A21: 7 | B21: Jitesh Rajput | C21: Cloud | D21: FY 25-26 | E21: Head | G21: =SUMIF('[2]Opportunity Pipeline'!$F:$F,"Jitesh Rajput",'[2]Opportunity Pipeline'!$O:$O)/10^7 -> 0.001548 | J21: =SUMIF('[3]Opportunity Pipeline '!$F:$F,"Jitesh Rajput",'[3]Opportunity Pipeline '!$O:$O)/10^7 -> 0 | L21: =(SUMIF('[2]Opportunity Pipeline'!$F:$F,"Jitesh Rajput",'[2]Opportunity Pipeline'!$O:$O)+SUMIF('[3]Opportunity Pipeline '!$F:$F,"Jitesh Rajput",'[3]Opportunity Pipeline '!$O:$O))/10^7 -> 0.001548 | S21: =SUM(L21,P21) -> 0.001548 | U21: =COUNTIF('[2]Opportunity Pipeline'!$F:$F,"Jitesh Rajput")+ COUNTIF('[3]Opportunity Pipeline '!$F:$F,"Jitesh Rajput") -> 3
A22: 8 | B22: Rocky Braganza | C22: CSN | D22: FY 25-26 | E22: Head | G22: =SUMIF('[2]Opportunity Pipeline'!$F:$F,"Rocky Braganza",'[2]Opportunity Pipeline'!$O:$O)/10^7 -> 0 | J22: =SUMIF('[3]Opportunity Pipeline '!$F:$F,"Rocky Braganza",'[3]Opportunity Pipeline '!$O:$O)/10^7 -> 0 | L22: =(SUMIF('[2]Opportunity Pipeline'!$F:$F,"Rocky Braganza",'[2]Opportunity Pipeline'!$O:$O)+SUMIF('[3]Opportunity Pipeline '!$F:$F,"Rocky Braganza",'[3]Opportunity Pipeline '!$O:$O))/10^7 -> 0 | S22: =SUM(L22,P22) -> 0 | U22: =COUNTIF('[2]Opportunity Pipeline'!$F:$F,"Rocky Braganza")+ COUNTIF('[3]Opportunity Pipeline '!$F:$F,"Rocky Braganza") -> 0
S23: =SUM(S15:S22) -> 60.829419 | U23: =SUM(U15:U22) -> 49

Sheet V3 · RTM Division level
A1: VIEW 3 — SUMMARY OUTLOOK | BU Roll-up | Revenue + Bottomline (BL) | H1 & Annual
A2: Level / Name | B2: Division | C2: Q1 — Revenue (₹ Cr) | F2: Q1 # Deals | G2: Q1 — Bottomline (₹ Cr) | J2: Q2 — Revenue (₹ Cr) | M2: Q2 # Deals | N2: Q2 — Bottomline (₹ Cr) | Q2: H1 — Revenue (₹ Cr) | T2: H1 — Bottomline (₹ Cr) | W2: H1 # Deals | X2: H2 — Revenue (₹ Cr) | AA2: H2 — Bottomline (₹ Cr) | AD2: H2 # Deals | AE2: Annual — Revenue (₹ Cr) | AH2: Annual — Bottomline (₹ Cr) | AK2: Ann # Deals
A3: Level | B3: Div. | C3: Quota | D3: Actuals | E3: Att% | F3: Count | G3: Quota | H3: Actuals | I3: Att% | J3: Quota | K3: Actuals | L3: Att% | M3: Count | N3: Quota | O3: Actuals | P3: Att% | Q3: Quota | R3: Actuals | S3: Att% | T3: Quota | U3: Actuals | V3: Att% | W3: Count | X3: Quota | Y3: Actuals | Z3: Att% | AA3: Quota | AB3: Actuals | AC3: Att% | AD3: Count | AE3: Quota | AF3: Actuals | AG3: Att% | AH3: Quota | AI3: Actuals | AJ3: Att% | AK3: Count
A4: RTM Division Level
A5: S1 Division Total | B5: S1 | C5: ='V1 · Individual'!F11 -> 108.175 | D5: ='V1 · Individual'!G11 -> 36.917493 | E5: =IFERROR(D5/C5,"-") -> 0.34127564 | F5: =COUNTIF('[2]Opportunity Pipeline'!$Z:$Z,"S1") -> 91 | G5: - | H5: - | I5: - | J5: ='V1 · Individual'!I11 -> 194.175 | K5: ='V1 · Individual'!J11 -> 20.571017 | L5: - | M5: =COUNTIF('[3]Opportunity Pipeline '!$Z:$Z,"S1") -> 49 | N5: - | O5: - | P5: - | Q5: ='V1 · Individual'!L11 -> 307.35 | R5: ='V1 · Individual'!M11 -> 57.488509 | S5: =IFERROR(R5/Q5,"-") -> 0.18704574 | T5: - | U5: - | V5: - | W5: ='V1 · Individual'!U11 -> 140 | X5: ='V1 · Individual'!O11 -> 352.65 | Y5: - | Z5: - | AA5: - | AB5: - | AC5: - | AD5: - | AE5: ='V1 · Individual'!R11 -> 660 | AF5: ='V1 · Individual'!S11 -> 57.488509 | AG5: =AF5/AE5 -> 0.087103802 | AH5: - | AI5: - | AJ5: - | AK5: =SUM(W5,AD5) -> 140
A6: S2 Division Total | B6: S2 | C6: ='V1 · Individual'!F20 -> 54.85 | D6: ='V1 · Individual'!G20 -> 15.396571 | E6: =IFERROR(D6/C6,"-") -> 0.2807032 | F6: =COUNTIF('[2]Opportunity Pipeline'!$Z:$Z,"S2") -> 25 | G6: - | H6: - | I6: - | J6: ='V1 · Individual'!I20 -> 84.15 | K6: ='V1 · Individual'!J20 -> 43.361923 | L6: - | M6: =COUNTIF('[3]Opportunity Pipeline '!$Z:$Z,"S2") -> 20 | N6: - | O6: - | P6: - | Q6: ='V1 · Individual'!L20 -> 107.75 | R6: ='V1 · Individual'!M20 -> 58.758494 | S6: =IFERROR(R6/Q6,"-") -> 0.54532245 | T6: - | U6: - | V6: - | W6: ='V1 · Individual'!U20 -> 45 | X6: ='V1 · Individual'!O20 -> 138.25 | Y6: - | Z6: - | AA6: - | AB6: - | AC6: - | AD6: - | AE6: ='V1 · Individual'!R20 -> 246 | AF6: ='V1 · Individual'!S20 -> 58.758494 | AG6: =AF6/AE6 -> 0.23885567 | AH6: - | AI6: - | AJ6: - | AK6: =SUM(W6,AD6) -> 45
A7: CB Division Total | B7: CB | C7: ='V1 · Individual'!F27 -> 18.5 | D7: ='V1 · Individual'!G27 -> 15.803396 | E7: =IFERROR(D7/C7,"-") -> 0.85423761 | F7: =COUNTIF('[2]Opportunity Pipeline'!$Z:$Z,"CB") -> 41 | G7: - | H7: - | I7: - | J7: ='V1 · Individual'!I27 -> 29.5 | K7: ='V1 · Individual'!J27 -> 8.442521 | L7: - | M7: =COUNTIF('[3]Opportunity Pipeline '!$Z:$Z,"CB") -> 36 | N7: - | O7: - | P7: - | Q7: ='V1 · Individual'!L27 -> 48 | R7: ='V1 · Individual'!M27 -> 24.245917 | S7: =IFERROR(R7/Q7,"-") -> 0.50512327 | T7: - | U7: - | V7: - | W7: ='V1 · Individual'!U27 -> 77 | X7: ='V1 · Individual'!O27 -> 79.5 | Y7: - | Z7: - | AA7: - | AB7: - | AC7: - | AD7: - | AE7: ='V1 · Individual'!R27 -> 127.5 | AF7: ='V1 · Individual'!S27 -> 24.245917 | AG7: =AF7/AE7 -> 0.19016405 | AH7: - | AI7: - | AJ7: - | AK7: =SUM(W7,AD7) -> 77
A8: GB Division Total | B8: GB | C8: ='V1 · Individual'!F41 -> 4.7 | D8: ='V1 · Individual'!G41 -> 15.114383 | E8: =IFERROR(D8/C8,"-") -> 3.2158261 | F8: =COUNTIF('[2]Opportunity Pipeline'!$Z:$Z,"GB") -> 50 | G8: - | H8: - | I8: - | J8: ='V1 · Individual'!I41 -> 5 | K8: ='V1 · Individual'!J41 -> 13.351083 | L8: - | M8: =COUNTIF('[3]Opportunity Pipeline '!$Z:$Z,"GB") -> 19 | N8: - | O8: - | P8: - | Q8: ='V1 · Individual'!L41 -> 12.9 | R8: ='V1 · Individual'!M41 -> 28.465465 | S8: =IFERROR(R8/Q8,"-") -> 2.2066252 | T8: - | U8: - | V8: - | W8: ='V1 · Individual'!U41 -> 69 | X8: ='V1 · Individual'!O41 -> 22.1 | Y8: - | Z8: - | AA8: - | AB8: - | AC8: - | AD8: - | AE8: ='V1 · Individual'!R41 -> 35 | AF8: ='V1 · Individual'!S41 -> 28.465465 | AG8: =AF8/AE8 -> 0.81329901 | AH8: - | AI8: - | AJ8: - | AK8: =SUM(W8,AD8) -> 69
A9: South Division Total | B9: South | C9: ='V1 · Individual'!F48 -> 10.5 | D9: ='V1 · Individual'!G48 -> 10.289627 | E9: =IFERROR(D9/C9,"-") -> 0.97996447 | F9: =COUNTIF('[2]Opportunity Pipeline'!$Z:$Z,"South") -> 54 | G9: - | H9: - | I9: - | J9: ='V1 · Individual'!I48 -> 7.5 | K9: ='V1 · Individual'!J48 -> 3.2297364 | L9: - | M9: =COUNTIF('[3]Opportunity Pipeline '!$Z:$Z,"South") -> 25 | N9: - | O9: - | P9: - | Q9: ='V1 · Individual'!L48 -> 22 | R9: ='V1 · Individual'!M48 -> 13.519363 | S9: =IFERROR(R9/Q9,"-") -> 0.61451651 | T9: - | U9: - | V9: - | W9: ='V1 · Individual'!U48 -> 79 | X9: ='V1 · Individual'!O48 -> 23 | Y9: - | Z9: - | AA9: - | AB9: - | AC9: - | AD9: - | AE9: ='V1 · Individual'!R48 -> 45 | AF9: ='V1 · Individual'!S48 -> 13.519363 | AG9: =AF9/AE9 -> 0.30043029 | AH9: - | AI9: - | AJ9: - | AK9: =SUM(W9,AD9) -> 79
A10: Geo Expansion Division | B10: Geo X | C10: ='V1 · Individual'!F53 -> 2.5 | D10: ='V1 · Individual'!G53 -> 3.8126084 | E10: =IFERROR(D10/C10,"-") -> 1.5250434 | F10: =COUNTIF('[2]Opportunity Pipeline'!$Z:$Z,"Geo X") -> 53 | G10: ='V1 · Individual'!F51 -> 0.4 | H10: ='V1 · Individual'!G51 -> 0.29095014 | I10: =IFERROR(D10/G10,"-") -> 9.531521 | J10: ='V1 · Individual'!I53 -> 5 | K10: ='V1 · Individual'!J53 -> 0.3138498 | L10: - | M10: =COUNTIF('[3]Opportunity Pipeline '!$Z:$Z,"GeoX") -> 4 | N10: ='V1 · Individual'!I51 -> 0.65 | O10: ='V1 · Individual'!J51 -> 0.023679 | P10: =O10/N10 -> 0.036429231 | Q10: ='V1 · Individual'!L53 -> 0 | R10: ='V1 · Individual'!M53 -> 4.1264582 | S10: =IFERROR(R10/Q10,"-") -> - | W10: ='V1 · Individual'!U53 -> 57 | X10: - | Y10: - | Z10: - | AA10: ='V1 · Individual'!O53 -> 1.35 | AB10: - | AC10: - | AD10: - | AE10: ='V1 · Individual'!R53 -> 2.4 | AF10: ='V1 · Individual'!S53 -> 4.1264582 | AG10: ='V1 · Individual'!T53 -> 1.7193576 | AK10: =SUM(W10,AD10) -> 57
A12: COMPANY TOTAL (Revenue IC, excl. GeoX BL) | C12: =SUM(C5:C10) -> 199.225 | D12: =SUM(D5:D10) -> 97.334077 | E12: =D12/C12 -> 0.48856357 | F12: =SUM(F5:F10) -> 314 | G12: =SUM(G5:G10) -> 0.4 | H12: =SUM(H5:H10) -> 0.29095014 | I12: =H12/G12 -> 0.72737536 | J12: =SUM(J5:J10) -> 325.325 | K12: =SUM(K5:K10) -> 89.27013 | L12: =SUM(L5:L10) -> 0 | M12: =SUM(M5:M10) -> 153 | N12: =SUM(N5:N10) -> 0.65 | O12: =SUM(O5:O10) -> 0.023679 | P12: =SUM(P5:P10) -> 0.036429231 | Q12: =SUM(Q5:Q10) -> 498 | R12: =SUM(R5:R10) -> 186.60421 | S12: =R12/Q12 -> 0.37470724 | T12: =SUM(T5:T10) -> 0 | U12: =SUM(U5:U10) -> 0 | V12: =SUM(V5:V10) -> 0 | W12: =SUM(W5:W10) -> 467 | X12: =SUM(X5:X10) -> 615.5 | Y12: =SUM(Y5:Y10) -> 0 | Z12: =SUM(Z5:Z10) -> 0 | AA12: =SUM(AA5:AA10) -> 1.35 | ... AK12: =SUM(AK5:AK10) -> 467

Sheet V5 · DCG
A1: VIEW 5 — RTM CONTRIBUTION | DCG | Booking (Revenue) | H1 & Annual
A2: # | B2: RTM Name | C2: Division | D2: FY | E2: Q1 Quota (₹ Cr) | F2: Q1 Actuals (₹ Cr) | G2: Attainment % (Q1) | H2: Q2 Quota (₹ Cr) | I2: Q2 Actuals (₹ Cr) | J2: Attainment % (Q2) | K2: H1 Quota (₹ Cr) | L2: H1 Actuals (₹ Cr) | M2: Attainment % (H1) | N2: H2 Quota (₹ Cr) | O2: H2 Actuals (₹ Cr) | P2: Attainment % (H2) | Q2: Annual Quota (₹ Cr) | R2: Annual Actuals (₹ Cr) | S2: Attainment % (Annual) | T2: # Deals (Total) | U2: Led-By Deals (count) | V2: Led-By Rev (₹ Cr) | W2: Contributed Deals (count) | X2: Contributed Rev (₹ Cr) | Y2: Rank (Div.)
A3: 1 | B3: S1 Division Total | C3: S1 | D3: FY 25-26 | E3: - | F3: =SUMIFS('[2]Opportunity Pipeline'!$O:$O,'[2]Opportunity Pipeline'!$K:$K,"Data Centre",'[2]Opportunity Pipeline'!$Z:$Z,"S1")/10^7 -> 13.039549 | G3: =IFERROR(F3/E3,"-") -> - | H3: - | I3: =SUMIFS('[3]Opportunity Pipeline '!$O:$O,'[3]Opportunity Pipeline '!$K:$K,"Data Centre",'[3]Opportunity Pipeline '!$Z:$Z,"S1")/10^7 -> 10.480089 | J3: =IFERROR(I3/H3,"-") -> - | K3: - | L3: =SUM(F3,I3) -> 23.519638 | M3: =IFERROR(L3/K3,"-") -> - | N3: - | O3: - | P3: - | Q3: 455 | R3: =SUM(L3,O3) -> 23.519638 | S3: =IFERROR(R3/Q3,"-") -> 0.051691513 | T3: =COUNTIFS('[2]Opportunity Pipeline'!$K:$K,"Data Centre",'[2]Opportunity Pipeline'!$Z:$Z,"S1")+COUNTIFS('[3]Opportunity Pipeline '!$K:$K,"Data Centre",'[3]Opportunity Pipeline '!$Z:$Z,"S1") -> 19
A4: 2 | B4: S2 Division Total | C4: S2 | D4: FY 25-26 | E4: - | F4: =SUMIFS('[2]Opportunity Pipeline'!$O:$O,'[2]Opportunity Pipeline'!$K:$K,"Data Centre",'[2]Opportunity Pipeline'!$Z:$Z,"S2")/10^7 -> 6.0336357 | G4: =IFERROR(F4/E4,"-") -> - | H4: - | I4: =SUMIFS('[3]Opportunity Pipeline '!$O:$O,'[3]Opportunity Pipeline '!$K:$K,"Data Centre",'[3]Opportunity Pipeline '!$Z:$Z,"S2")/10^7 -> 33.943729 | J4: =IFERROR(I4/H4,"-") -> - | K4: - | L4: =SUM(F4,I4) -> 39.977364 | M4: =IFERROR(L4/K4,"-") -> - | N4: - | O4: - | P4: - | Q4: 225 | R4: =SUM(L4,O4) -> 39.977364 | S4: =IFERROR(R4/Q4,"-") -> 0.17767717 | T4: =COUNTIFS('[2]Opportunity Pipeline'!$K:$K,"Data Centre",'[2]Opportunity Pipeline'!$Z:$Z,"S2")+COUNTIFS('[3]Opportunity Pipeline '!$K:$K,"Data Centre",'[3]Opportunity Pipeline '!$Z:$Z,"S2") -> 9
A5: 3 | B5: CB Division Total | C5: CB | D5: FY 25-26 | E5: - | F5: =SUMIFS('[2]Opportunity Pipeline'!$O:$O,'[2]Opportunity Pipeline'!$K:$K,"Data Centre",'[2]Opportunity Pipeline'!$Z:$Z,"CB")/10^7 -> 8.1258048 | G5: =IFERROR(F5/E5,"-") -> - | H5: - | I5: =SUMIFS('[3]Opportunity Pipeline '!$O:$O,'[3]Opportunity Pipeline '!$K:$K,"Data Centre",'[3]Opportunity Pipeline '!$Z:$Z,"CB")/10^7 -> 1.8399346 | J5: =IFERROR(I5/H5,"-") -> - | K5: - | L5: =SUM(F5,I5) -> 9.9657394 | M5: =IFERROR(L5/K5,"-") -> - | N5: - | O5: - | P5: - | Q5: 40 | R5: =SUM(L5,O5) -> 9.9657394 | S5: =IFERROR(R5/Q5,"-") -> 0.24914348 | T5: =COUNTIFS('[2]Opportunity Pipeline'!$K:$K,"Data Centre",'[2]Opportunity Pipeline'!$Z:$Z,"CB")+COUNTIFS('[3]Opportunity Pipeline '!$K:$K,"Data Centre",'[3]Opportunity Pipeline '!$Z:$Z,"CB") -> 8
A6: 4 | B6: GB Division Total | C6: GB | D6: FY 25-26 | E6: - | F6: =SUMIFS('[2]Opportunity Pipeline'!$O:$O,'[2]Opportunity Pipeline'!$K:$K,"Data Centre",'[2]Opportunity Pipeline'!$Z:$Z,"GB")/10^7 -> 0.2438 | G6: =IFERROR(F6/E6,"-") -> - | H6: - | I6: =SUMIFS('[3]Opportunity Pipeline '!$O:$O,'[3]Opportunity Pipeline '!$K:$K,"Data Centre",'[3]Opportunity Pipeline '!$Z:$Z,"GB")/10^7 -> 11.716881 | J6: =IFERROR(I6/H6,"-") -> - | K6: - | L6: =SUM(F6,I6) -> 11.960681 | M6: =IFERROR(L6/K6,"-") -> - | N6: - | O6: - | P6: - | Q6: 11 | R6: =SUM(L6,O6) -> 11.960681 | S6: =IFERROR(R6/Q6,"-") -> 1.0873346 | T6: =COUNTIFS('[2]Opportunity Pipeline'!$K:$K,"Data Centre",'[2]Opportunity Pipeline'!$Z:$Z,"GB")+COUNTIFS('[3]Opportunity Pipeline '!$K:$K,"Data Centre",'[3]Opportunity Pipeline '!$Z:$Z,"GB") -> 4
A7: 5 | B7: South Division Total | C7: South | D7: FY 25-26 | E7: - | F7: =SUMIFS('[2]Opportunity Pipeline'!$O:$O,'[2]Opportunity Pipeline'!$K:$K,"Data Centre",'[2]Opportunity Pipeline'!$Z:$Z,"South")/10^7 -> 5.553386 | G7: =IFERROR(F7/E7,"-") -> - | H7: - | I7: =SUMIFS('[3]Opportunity Pipeline '!$O:$O,'[3]Opportunity Pipeline '!$K:$K,"Data Centre",'[3]Opportunity Pipeline '!$Z:$Z,"South")/10^7 -> 2.448795 | J7: =IFERROR(I7/H7,"-") -> - | K7: - | L7: =SUM(F7,I7) -> 8.002181 | M7: =IFERROR(L7/K7,"-") -> - | N7: - | O7: - | P7: - | Q7: 14 | R7: =SUM(L7,O7) -> 8.002181 | S7: =IFERROR(R7/Q7,"-") -> 0.57158436 | T7: =COUNTIFS('[2]Opportunity Pipeline'!$K:$K,"Data Centre",'[2]Opportunity Pipeline'!$Z:$Z,"South")+COUNTIFS('[3]Opportunity Pipeline '!$K:$K,"Data Centre",'[3]Opportunity Pipeline '!$Z:$Z,"South") -> 14
A8: 6 | B8: GeoX Division Total | C8: GeoX | D8: FY 25-26 | E8: - | F8: =SUMIFS('[2]Opportunity Pipeline'!$O:$O,'[2]Opportunity Pipeline'!$K:$K,"Data Centre",'[2]Opportunity Pipeline'!$Z:$Z,"Geo X")/10^7 -> 0 | G8: =IFERROR(F8/E8,"-") -> - | H8: - | I8: =SUMIFS('[3]Opportunity Pipeline '!$O:$O,'[3]Opportunity Pipeline '!$K:$K,"Data Centre",'[3]Opportunity Pipeline '!$Z:$Z,"GeoX")/10^7 -> 0.2751208 | J8: =IFERROR(I8/H8,"-") -> - | K8: - | L8: =SUM(F8,I8) -> 0.2751208 | M8: =IFERROR(L8/K8,"-") -> - | N8: - | O8: - | P8: - | Q8: 10 | R8: =SUM(L8,O8) -> 0.2751208 | S8: =IFERROR(R8/Q8,"-") -> 0.02751208 | T8: =COUNTIFS('[2]Opportunity Pipeline'!$K:$K,"Data Centre",'[2]Opportunity Pipeline'!$Z:$Z,"Geo X")+COUNTIFS('[3]Opportunity Pipeline '!$K:$K,"Data Centre",'[3]Opportunity Pipeline '!$Z:$Z,"GeoX") -> 2
B9: RTM Total | E9: - | F9: =SUM(F3:F8) -> 32.996176 | G9: =IFERROR(F9/E9,"-") -> - | H9: - | I9: =SUM(I3:I8) -> 60.704549 | J9: =IFERROR(I9/H9,"-") -> - | K9: - | L9: =SUM(L3:L8) -> 93.700725 | M9: =IFERROR(L9/K9,"-") -> - | N9: - | O9: - | P9: - | Q9: =SUM(Q3:Q8) -> 755 | R9: =SUM(R3:R8) -> 93.700725 | S9: =IFERROR(R9/Q9,"-") -> 0.12410692 | T9: =SUM(T3:T8) -> 56

Sheet V6 · CSN
A1: VIEW 5 — RTM CONTRIBUTION | DCG | Booking (Revenue) | H1 & Annual
A2: # | B2: RTM Name | C2: Division | D2: FY | E2: Q1 Quota (₹ Cr) | F2: Q1 Actuals (₹ Cr) | G2: Attainment % (Q1) | H2: Q2 Quota (₹ Cr) | I2: Q2 Actuals (₹ Cr) | J2: Attainment % (Q2) | K2: H1 Quota (₹ Cr) | L2: H1 Actuals (₹ Cr) | M2: Attainment % (H1) | N2: H2 Quota (₹ Cr) | O2: H2 Actuals (₹ Cr) | P2: Attainment % (H2) | Q2: Annual Quota (₹ Cr) | R2: Annual Actuals (₹ Cr) | S2: Attainment % (Annual) | T2: # Deals (Total) | U2: Led-By Deals (count) | V2: Led-By Rev (₹ Cr) | W2: Contributed Deals (count) | X2: Contributed Rev (₹ Cr) | Y2: Rank (Div.)
A3: 1 | B3: S1 Division Total | C3: S1 | D3: FY 25-26 | E3: - | F3: =SUMIFS('[2]Opportunity Pipeline'!$O:$O,'[2]Opportunity Pipeline'!$K:$K,"Cyber Security & Networking",'[2]Opportunity Pipeline'!$Z:$Z,"S1")/10^7 -> 11.430924 | G3: =IFERROR(F3/E3,"-") -> - | H3: - | I3: =SUMIFS('[3]Opportunity Pipeline '!$O:$O,'[3]Opportunity Pipeline '!$K:$K,"Cyber Security & Networking",'[3]Opportunity Pipeline '!$Z:$Z,"S1")/10^7 -> 3.42291 | J3: =IFERROR(I3/H3,"-") -> - | K3: - | L3: =SUM(F3,I3) -> 14.853834 | M3: =IFERROR(L3/K3,"-") -> - | N3: - | O3: - | P3: - | Q3: 90 | R3: =SUM(L3,O3) -> 14.853834 | S3: =IFERROR(R3/Q3,"-") -> 0.1650426 | T3: =COUNTIFS('[2]Opportunity Pipeline'!$K:$K,"Cyber Security & Networking",'[2]Opportunity Pipeline'!$Z:$Z,"S1")+COUNTIFS('[3]Opportunity Pipeline '!$K:$K,"Cyber Security & Networking",'[3]Opportunity Pipeline '!$Z:$Z,"S1") -> 20
A4: 2 | B4: S2 Division Total | C4: S2 | D4: FY 25-26 | E4: - | F4: =SUMIFS('[2]Opportunity Pipeline'!$O:$O,'[2]Opportunity Pipeline'!$K:$K,"Cyber Security & Networking",'[2]Opportunity Pipeline'!$Z:$Z,"S2")/10^7 -> 1.9310275 | G4: =IFERROR(F4/E4,"-") -> - | H4: - | I4: =SUMIFS('[3]Opportunity Pipeline '!$O:$O,'[3]Opportunity Pipeline '!$K:$K,"Cyber Security & Networking",'[3]Opportunity Pipeline '!$Z:$Z,"S2")/10^7 -> 7.926443 | J4: =IFERROR(I4/H4,"-") -> - | K4: - | L4: =SUM(F4,I4) -> 9.8574705 | M4: =IFERROR(L4/K4,"-") -> - | N4: - | O4: - | P4: - | Q4: 30 | R4: =SUM(L4,O4) -> 9.8574705 | S4: =IFERROR(R4/Q4,"-") -> 0.32858235 | T4: =COUNTIFS('[2]Opportunity Pipeline'!$K:$K,"Cyber Security & Networking",'[2]Opportunity Pipeline'!$Z:$Z,"S2")+COUNTIFS('[3]Opportunity Pipeline '!$K:$K,"Cyber Security & Networking",'[3]Opportunity Pipeline '!$Z:$Z,"S2") -> 21
A5: 3 | B5: CB Division Total | C5: CB | D5: FY 25-26 | E5: - | F5: =SUMIFS('[2]Opportunity Pipeline'!$O:$O,'[2]Opportunity Pipeline'!$K:$K,"Cyber Security & Networking",'[2]Opportunity Pipeline'!$Z:$Z,"CB")/10^7 -> 5.8855196 | G5: =IFERROR(F5/E5,"-") -> - | H5: - | I5: =SUMIFS('[3]Opportunity Pipeline '!$O:$O,'[3]Opportunity Pipeline '!$K:$K,"Cyber Security & Networking",'[3]Opportunity Pipeline '!$Z:$Z,"CB")/10^7 -> 0.031 | J5: =IFERROR(I5/H5,"-") -> - | K5: - | L5: =SUM(F5,I5) -> 5.9165196 | M5: =IFERROR(L5/K5,"-") -> - | N5: - | O5: - | P5: - | Q5: 24 | R5: =SUM(L5,O5) -> 5.9165196 | S5: =IFERROR(R5/Q5,"-") -> 0.24652165 | T5: =COUNTIFS('[2]Opportunity Pipeline'!$K:$K,"Cyber Security & Networking",'[2]Opportunity Pipeline'!$Z:$Z,"CB")+COUNTIFS('[3]Opportunity Pipeline '!$K:$K,"Cyber Security & Networking",'[3]Opportunity Pipeline '!$Z:$Z,"CB") -> 7
A6: 4 | B6: GB Division Total | C6: GB | D6: FY 25-26 | E6: - | F6: =SUMIFS('[2]Opportunity Pipeline'!$O:$O,'[2]Opportunity Pipeline'!$K:$K,"Cyber Security & Networking",'[2]Opportunity Pipeline'!$Z:$Z,"GB")/10^7 -> 5.6325779 | G6: =IFERROR(F6/E6,"-") -> - | H6: - | I6: =SUMIFS('[3]Opportunity Pipeline '!$O:$O,'[3]Opportunity Pipeline '!$K:$K,"Cyber Security & Networking",'[3]Opportunity Pipeline '!$Z:$Z,"GB")/10^7 -> 1.2569719 | J6: =IFERROR(I6/H6,"-") -> - | K6: - | L6: =SUM(F6,I6) -> 6.8895498 | M6: =IFERROR(L6/K6,"-") -> - | N6: - | O6: - | P6: - | Q6: 20 | R6: =SUM(L6,O6) -> 6.8895498 | S6: =IFERROR(R6/Q6,"-") -> 0.34447749 | T6: =COUNTIFS('[2]Opportunity Pipeline'!$K:$K,"Cyber Security & Networking",'[2]Opportunity Pipeline'!$Z:$Z,"GB")+COUNTIFS('[3]Opportunity Pipeline '!$K:$K,"Cyber Security & Networking",'[3]Opportunity Pipeline '!$Z:$Z,"GB") -> 27
A7: 5 | B7: South Division Total | C7: South | D7: FY 25-26 | E7: - | F7: =SUMIFS('[2]Opportunity Pipeline'!$O:$O,'[2]Opportunity Pipeline'!$K:$K,"Cyber Security & Networking",'[2]Opportunity Pipeline'!$Z:$Z,"South")/10^7 -> 0.5456455 | G7: =IFERROR(F7/E7,"-") -> - | H7: - | I7: =SUMIFS('[3]Opportunity Pipeline '!$O:$O,'[3]Opportunity Pipeline '!$K:$K,"Cyber Security & Networking",'[3]Opportunity Pipeline '!$Z:$Z,"South")/10^7 -> 0.1769364 | J7: =IFERROR(I7/H7,"-") -> - | K7: - | L7: =SUM(F7,I7) -> 0.7225819 | M7: =IFERROR(L7/K7,"-") -> - | N7: - | O7: - | P7: - | Q7: 1 | R7: =SUM(L7,O7) -> 0.7225819 | S7: =IFERROR(R7/Q7,"-") -> 0.7225819 | T7: =COUNTIFS('[2]Opportunity Pipeline'!$K:$K,"Cyber Security & Networking",'[2]Opportunity Pipeline'!$Z:$Z,"South")+COUNTIFS('[3]Opportunity Pipeline '!$K:$K,"Cyber Security & Networking",'[3]Opportunity Pipeline '!$Z:$Z,"South") -> 24
