Workbook

Sheet V1 · Individual
A1: VIEW 1 — INDIVIDUAL CONTRIBUTION | Booking (Revenue) | H1 & Annual
A2: # | B2: Employee Name | C2: Division | D2: FY | E2: Type / Notes | F2: Q1 Quota (₹ Cr) | G2: Q1 Actuals (₹ Cr) | H2: Attainment % (Q1) | I2: Q2 Quota (₹ Cr) | J2: Q2 Actuals (₹ Cr) | K2: Attainment % (Q2) | L2: H1 Quota (₹ Cr) | M2: H1 Actuals (₹ Cr) | N2: Attainment % (H1) | O2: H2 Quota (₹ Cr) | P2: H2 Actuals (₹ Cr) | Q2: Attainment % (H2) | R2: Annual Quota (₹ Cr) | S2: Annual Actuals (₹ Cr) | T2: Attainment % (Annual) | U2: # Deals (Total) | V2: Led-By Deals (count) | W2: Led-By Rev (₹ Cr) | X2: Contributed Deals (count) | Y2: Contributed Rev (₹ Cr) | Z2: Rank (Div.)
A3: S1 Division
A4: 1 | B4: Tasneem K | C4: S1 | D4: FY 25-26 | E4: IC | F4: =SUMIF('[2]S1 '!$B:$B,"Tasneem khatri",'[2]S1 '!$H:$H) -> #VALUE! | G4: =SUMIF('[1]Opportunity Pipeline'!$F:$F, "Tasneem k",'[1]Opportunity Pipeline'!$O:$O)/10^7 -> #VALUE! | H4: =IFERROR(G4/F4,"-") -> - | I4: =SUMIF('[2]S1 '!$B:$B,"Tasneem khatri",'[2]S1 '!$I:$I) -> 95.275 | J4: - | K4: =IFERROR(J4/I4,"-") -> - | L4: ='[3]Tasneem- TARGET LETTER - 26-27'!$D$9/10^7 -> 130.35 | M4: =SUMIF('[1]Opportunity Pipeline'!$F:$F, "Tasneem k",'[1]Opportunity Pipeline'!$O:$O)/10^7 -> 15.920587 | N4: =IFERROR(M4/L4,"-") -> 0.12213723 | O4: ='[3]Tasneem- TARGET LETTER - 26-27'!$D$16/10^7 -> 129.65 | P4: - | Q4: =IFERROR(P4/O4,"-") -> - | R4: =SUM(L4,O4) -> 260 | S4: =SUM(M4,P4) -> 15.920587 | T4: =IFERROR(S4/R4,"-") -> 0.061233029 | U4: =COUNTIF('[1]Opportunity Pipeline'!$F:$F,"Tasneem K") -> 7
A5: 2 | B5: Riya Bhatt | C5: S1 | D5: FY 25-26 | E5: IC | F5: =SUMIF('[2]S1 '!$B:$B,"Riya Roshyara",'[2]S1 '!$H:$H) -> 20 | G5: =SUMIF('[1]Opportunity Pipeline'!$F:$F, "Riya Bhatt",'[1]Opportunity Pipeline'!$O:$O)/10^7 -> 0.5798 | H5: =IFERROR(G5/F5,"-") -> 0.02899 | I5: =SUMIF('[2]S1 '!$B:$B,"Riya Roshyara",'[2]S1 '!$I:$I) -> 38 | J5: - | K5: =IFERROR(J5/I5,"-") -> - | L5: ='[4]RIYA- TARGET LETTER - 26-27'!$D$9/10^7 -> 59 | M5: =SUMIF('[1]Opportunity Pipeline'!$F:$F, "Riya Bhatt",'[1]Opportunity Pipeline'!$O:$O)/10^7 -> 0.5798 | N5: =IFERROR(M5/L5,"-") -> 0.0098271186 | O5: ='[4]RIYA- TARGET LETTER - 26-27'!$D$15/10^7 -> 61 | P5: - | Q5: =IFERROR(P5/O5,"-") -> - | R5: =SUM(L5,O5) -> 120 | S5: =SUM(M5,P5) -> 0.5798 | T5: =IFERROR(S5/R5,"-") -> 0.0048316667 | U5: =COUNTIF('[1]Opportunity Pipeline'!$F:$F,"Riya Bhatt") -> 2
A6: 3 | B6: Pratik Kadam | C6: S1 | D6: FY 25-26 | E6: IC | F6: =SUMIF('[2]S1 '!$B:$B,"Pratik Kadam",'[2]S1 '!$H:$H) -> 3 | G6: =SUMIF('[1]Opportunity Pipeline'!$F:$F, "Pratik Kadam",'[1]Opportunity Pipeline'!$O:$O)/10^7 -> 1.400457 | H6: =IFERROR(G6/F6,"-") -> 0.46681901 | I6: =SUMIF('[2]S1 '!$B:$B,"Pratik Kadam",'[2]S1 '!$I:$I) -> 2 | J6: - | K6: =IFERROR(J6/I6,"-") -> - | L6: ='[5]Pratik- TARGET LETTER - 26-27'!$D$9/10^7 -> 5 | M6: =SUMIF('[1]Opportunity Pipeline'!$F:$F, "Pratik Kadam",'[1]Opportunity Pipeline'!$O:$O)/10^7 -> 1.400457 | N6: =IFERROR(M6/L6,"-") -> 0.28009141 | O6: ='[5]Pratik- TARGET LETTER - 26-27'!$D$10/10^7 -> 5 | P6: - | Q6: =IFERROR(P6/O6,"-") -> - | R6: =SUM(L6,O6) -> 10 | S6: =SUM(M6,P6) -> 1.400457 | T6: =IFERROR(S6/R6,"-") -> 0.1400457 | U6: =COUNTIF('[1]Opportunity Pipeline'!$F:$F,"Pratik Kadam") -> 38
A7: 4 | B7: Prashant Ddugu | C7: S1 | D7: FY 25-26 | E7: TL | F7: =SUM(F8:F9,7.5) -> 28.8 | G7: =SUM(G8:G9) -> 19.016648 | H7: =IFERROR(G7/F7,"-") -> 0.66030028 | I7: =SUM(I8:I9,5) -> 31.95 | J7: - | K7: =IFERROR(J7/I7,"-") -> - | L7: ='[6]Prashant- TARGET LETTER - 26-27'!$D$9/10^7 -> 60.5 | M7: =SUM(M8:M9) -> 19.016648 | N7: =IFERROR(M7/L7,"-") -> 0.31432476 | O7: ='[6]Prashant- TARGET LETTER - 26-27'!$D$13/10^7 -> 89.5 | P7: - | Q7: =IFERROR(P7/O7,"-") -> - | R7: =SUM(L7,O7) -> 150 | S7: =SUM(M7,P7) -> 19.016648 | T7: =IFERROR(S7/R7,"-") -> 0.12677765 | U7: =COUNTIF('[1]Opportunity Pipeline'!$F:$F,"Prashant Ddugu") -> 0
A8: 5 | B8: Chirag Palande | C8: S1 | D8: FY 25-26 | E8: IC | F8: =SUMIF('[2]S1 '!$B:$B,"Chirag Palande",'[2]S1 '!$H:$H) -> 13 | G8: =SUMIF('[1]Opportunity Pipeline'!$F:$F, "Chirag Palande",'[1]Opportunity Pipeline'!$O:$O)/10^7 -> 0.1286674 | H8: =IFERROR(G8/F8,"-") -> 0.0098974923 | I8: =SUMIF('[2]S1 '!$B:$B,"Chirag Palande",'[2]S1 '!$I:$I) -> 10 | J8: - | K8: =IFERROR(J8/I8,"-") -> - | L8: ='[7]Chirag- TARGET LETTER - 26-27'!$D$9/10^7 -> 27.5 | M8: =SUMIF('[1]Opportunity Pipeline'!$F:$F, "Chirag Palande",'[1]Opportunity Pipeline'!$O:$O)/10^7 -> 0.1286674 | N8: =IFERROR(M8/L8,"-") -> 0.0046788145 | O8: ='[7]Chirag- TARGET LETTER - 26-27'!$D$14/10^7 -> 32.5 | P8: - | Q8: =IFERROR(P8/O8,"-") -> - | R8: =SUM(L8,O8) -> 60 | S8: =SUM(M8,P8) -> 0.1286674 | T8: =IFERROR(S8/R8,"-") -> 0.0021444567 | U8: =COUNTIF('[1]Opportunity Pipeline'!$F:$F,"Chirag Palande") -> 3
A9: 6 | B9: Richa Tiwari | C9: S1 | D9: FY 25-26 | E9: IC | F9: =SUMIF('[2]S1 '!$B:$B,"Richa Tiwari",'[2]S1 '!$H:$H) -> 8.3 | G9: =SUMIF('[1]Opportunity Pipeline'!$F:$F, "RICHA TIWARI",'[1]Opportunity Pipeline'!$O:$O)/10^7 -> 18.887981 | H9: =IFERROR(G9/F9,"-") -> 2.2756603 | I9: =SUMIF('[2]S1 '!$B:$B,"Richa Tiwari",'[2]S1 '!$I:$I) -> 16.95 | J9: - | K9: =IFERROR(J9/I9,"-") -> - | L9: ='[8]Richa- TARGET LETTER - 26-27'!$D$9/10^7 -> 25 | M9: =SUMIF('[1]Opportunity Pipeline'!$F:$F, "RICHA TIWARI",'[1]Opportunity Pipeline'!$O:$O)/10^7 -> 18.887981 | N9: =IFERROR(M9/L9,"-") -> 0.75551923 | O9: ='[8]Richa- TARGET LETTER - 26-27'!$D$12/10^7 -> 35 | P9: - | Q9: =IFERROR(P9/O9,"-") -> - | R9: =SUM(L9,O9) -> 60 | S9: =SUM(M9,P9) -> 18.887981 | T9: =IFERROR(S9/R9,"-") -> 0.31479968 | U9: =COUNTIF('[1]Opportunity Pipeline'!$F:$F,"Richa Tiwari") -> 41
B10: IC Subtotal — S1 | F10: =SUM(F4:F9) -> #VALUE! | G10: =SUM(G4:G9) -> #VALUE! | H10: =G10/F10 -> #VALUE! | I10: =SUM(I4:I9) -> 194.175 | J10: =SUM(J4:J9) -> 0 | K10: =J10/I10 -> 0 | L10: =SUM(L4:L9) -> 307.35 | M10: =SUM(M4:M9) -> 55.934141 | N10: =M10/L10 -> 0.18198842 | O10: =SUM(O4:O9) -> 352.65 | P10: =SUM(P4:P9) -> 0 | Q10: =P10/O10 -> 0 | R10: =SUM(R4:R9) -> 660 | S10: =SUM(S4:S9) -> 55.934141 | T10: =S10/R10 -> 0.084748698 | U10: =SUM(U4:U9) -> 91
A12: S2 Division
A13: 1 | B13: Rohit Deshmukh | C13: S2 | D13: FY 25-26 | E13: IC | F13: =SUMIF('[2]S2 '!$B$1:$B$45,"Rohit",'[2]S2 '!$G$1:$G$45) -> 29 | G13: =SUMIF('[1]Opportunity Pipeline'!$F:$F, "Rohit Deshmukh",'[1]Opportunity Pipeline'!$O:$O)/10^7 -> 2.2971172 | H13: =IFERROR(G13/F13,"-") -> 0.079210936 | I13: =SUMIF('[2]S2 '!$B$1:$B$45,"Rohit",'[2]S2 '!$H$1:$H$45) -> 53 | J13: - | K13: =IFERROR(J13/I13,"-") -> - | L13: ='[9]Rohit- TARGET LETTER - 26-27'!$D$9/10^7 -> 76 | M13: =SUMIF('[1]Opportunity Pipeline'!$F:$F, "Rohit Deshmukh",'[1]Opportunity Pipeline'!$O:$O)/10^7 -> 2.2971172 | N13: =IFERROR(M13/L13,"-") -> 0.030225226 | O13: ='[9]Rohit- TARGET LETTER - 26-27'!$D$12/10^7 -> 59 | P13: - | Q13: =IFERROR(P13/O13,"-") -> - | R13: =SUM(L13,O13) -> 135 | S13: =SUM(M13,P13) -> 2.2971172 | T13: =IFERROR(S13/R13,"-") -> 0.017015683 | U13: =COUNTIF('[1]Opportunity Pipeline'!$F:$F,"Rohit Deshmukh") -> 9
A14: 2 | B14: Chetna Sharma | C14: S2 | D14: FY 25-26 | E14: IC | F14: =SUMIF('[2]S2 '!$B$1:$B$45,"Chetna",'[2]S2 '!$G$1:$G$45) -> 8 | G14: =SUMIF('[1]Opportunity Pipeline'!$F:$F, "Chetna Sharma",'[1]Opportunity Pipeline'!$O:$O)/10^7 -> 11.771069 | H14: =IFERROR(G14/F14,"-") -> 1.4713836 | I14: =SUMIF('[2]S2 '!$B$1:$B$45,"Chetna",'[2]S2 '!$H$1:$H$45) -> 10 | J14: - | K14: =IFERROR(J14/I14,"-") -> - | L14: ='[10]Chetna- TARGET LETTER - 26-27'!$D$9/10^7 -> 20 | M14: =SUMIF('[1]Opportunity Pipeline'!$F:$F, "Chetna Sharma",'[1]Opportunity Pipeline'!$O:$O)/10^7 -> 11.771069 | N14: =IFERROR(M14/L14,"-") -> 0.58855343 | O14: ='[10]Chetna- TARGET LETTER - 26-27'!$D$17/10^7 -> 49 | P14: - | Q14: =IFERROR(P14/O14,"-") -> - | R14: =SUM(L14,O14) -> 69 | S14: =SUM(M14,P14) -> 11.771069 | T14: =IFERROR(S14/R14,"-") -> 0.1705952 | U14: =COUNTIF('[1]Opportunity Pipeline'!$F:$F,"Chetna Sharma") -> 7
A15: 3 | B15: Sankeerth Bhargav | C15: S2 | D15: FY 25-26 | E15: IC | F15: =SUMIF('[2]S2 '!$B$1:$B$45,"Sankeerth",'[2]S2 '!$G$1:$G$45) -> 2.75 | G15: =SUMIF('[1]Opportunity Pipeline'!$F:$F, "Sankeerth Bhargav",'[1]Opportunity Pipeline'!$O:$O)/10^7 -> 0.21652 | H15: =IFERROR(G15/F15,"-") -> 0.078734545 | I15: =SUMIF('[2]S2 '!$B$1:$B$45,"Sankeerth",'[2]S2 '!$H$1:$H$45) -> 2.75 | J15: - | K15: =IFERROR(J15/I15,"-") -> - | L15: ='[11]Sankeerth TARGET LETTER - 26-27'!$D$9/10^7 -> 11.75 | M15: =SUMIF('[1]Opportunity Pipeline'!$F:$F, "Sankeerth Bhargav",'[1]Opportunity Pipeline'!$O:$O)/10^7 -> 0.21652 | N15: =IFERROR(M15/L15,"-") -> 0.018427234 | O15: ='[11]Sankeerth TARGET LETTER - 26-27'!$D$15/10^7 -> 30.25 | P15: - | Q15: =IFERROR(P15/O15,"-") -> - | R15: =SUM(L15,O15) -> 42 | S15: =SUM(M15,P15) -> 0.21652 | T15: =IFERROR(S15/R15,"-") -> 0.0051552381 | U15: =COUNTIF('[1]Opportunity Pipeline'!$F:$F,"Sankeerth Bhargav") -> 3
A16: 4 | B16: TBH (Varsha) | C16: S2 | D16: FY 25-26 | E16: IC | F16: =SUMIF('[2]S2 '!$B$1:$B$45,"Varsha",'[2]S2 '!$G$1:$G$45) -> 7.3 | G16: =SUMIF('[1]Opportunity Pipeline'!$F:$F, "Varsha Ray",'[1]Opportunity Pipeline'!$O:$O)/10^7 -> 1.055469 | H16: =IFERROR(G16/F16,"-") -> 0.14458479 | I16: =SUMIF('[2]S2 '!$B$1:$B$45,"Varsha",'[2]S2 '!$H$1:$H$45) -> 9.8 | J16: - | K16: =IFERROR(J16/I16,"-") -> - | L16: =IFERROR(K16/J16,"-") -> - | M16: =SUMIF('[1]Opportunity Pipeline'!$F:$F, "Varsha Ray",'[1]Opportunity Pipeline'!$O:$O)/10^7 -> 1.055469 | N16: =IFERROR(M16/L16,"-") -> - | O16: =IFERROR(N16/M16,"-") -> - | P16: - | Q16: =IFERROR(P16/O16,"-") -> - | R16: =SUM(L16,O16) -> 0 | S16: =SUM(M16,P16) -> 1.055469 | T16: =IFERROR(S16/R16,"-") -> - | U16: =COUNTIF('[1]Opportunity Pipeline'!$F:$F,"Varsha Ray") -> 4
A17: 5 | B17: TBH (Arpit) | C17: S2 | D17: FY 25-26 | E17: IC | F17: =SUMIF('[2]S2 '!$B$1:$B$45,"Arpit",'[2]S2 '!$G$1:$G$45) -> 6.75 | G17: =SUMIF('[1]Opportunity Pipeline'!$F:$F, "Arpit Srivastava",'[1]Opportunity Pipeline'!$O:$O)/10^7 -> 0.056395833 | H17: =IFERROR(G17/F17,"-") -> 0.0083549382 | I17: =SUMIF('[2]S2 '!$B$1:$B$45,"Arpit",'[2]S2 '!$H$1:$H$45) -> 6.75 | J17: - | K17: =IFERROR(J17/I17,"-") -> - | L17: =IFERROR(K17/J17,"-") -> - | M17: =SUMIF('[1]Opportunity Pipeline'!$F:$F, "Arpit Srivastava",'[1]Opportunity Pipeline'!$O:$O)/10^7 -> 0.056395833 | N17: =IFERROR(M17/L17,"-") -> - | O17: =IFERROR(N17/M17,"-") -> - | P17: - | Q17: =IFERROR(P17/O17,"-") -> - | R17: =SUM(L17,O17) -> 0 | S17: =SUM(M17,P17) -> 0.056395833 | T17: =IFERROR(S17/R17,"-") -> - | U17: =COUNTIF('[1]Opportunity Pipeline'!$F:$F,"Arpit Srivastavah") -> 0
A18: 6 | B18: TBH (Dennis) | C18: S2 | D18: FY 25-26 | E18: IC | F18: =SUMIF('[2]S2 '!$B$1:$B$45,"Dennis",'[2]S2 '!$G$1:$G$45) -> 1.05 | G18: =SUMIF('[1]Opportunity Pipeline'!$F:$F, "Dennis",'[1]Opportunity Pipeline'!$O:$O)/10^7 -> 0 | H18: =IFERROR(G18/F18,"-") -> 0 | I18: =SUMIF('[2]S2 '!$B$1:$B$45,"Dennis",'[2]S2 '!$H$1:$H$45) -> 1.85 | J18: - | K18: =IFERROR(J18/I18,"-") -> - | L18: =IFERROR(K18/J18,"-") -> - | M18: =SUMIF('[1]Opportunity Pipeline'!$F:$F, "Dennis",'[1]Opportunity Pipeline'!$O:$O)/10^7 -> 0 | N18: =IFERROR(M18/L18,"-") -> - | O18: =IFERROR(N18/M18,"-") -> - | P18: - | Q18: =IFERROR(P18/O18,"-") -> - | R18: =SUM(L18,O18) -> 0 | S18: =SUM(M18,P18) -> 0 | T18: =IFERROR(S18/R18,"-") -> - | U18: =COUNTIF('[1]Opportunity Pipeline'!$F:$F,"Dennis") -> 0
B19: IC Subtotal — S2 | F19: =SUM(F13:F18) -> 54.85 | G19: =SUM(G13:G18) -> 15.396571 | H19: =G19/F19 -> 0.2807032 | I19: =SUM(I13:I18) -> 84.15 | J19: =SUM(J13:J18) -> 0 | K19: =J19/I19 -> 0 | L19: =SUM(L13:L18) -> 107.75 | M19: =SUM(M13:M18) -> 15.396571 | N19: =M19/L19 -> 0.14289161 | O19: =SUM(O13:O18) -> 138.25 | P19: =SUM(P13:P18) -> 0 | Q19: =P19/O19 -> 0 | R19: =SUM(R13:R18) -> 246 | S19: =SUM(S13:S18) -> 15.396571 | T19: =S19/R19 -> 0.062587685 | U19: =SUM(U13:U18) -> 23
A21: CB Division
A22: 1 | B22: Prachi Mayekar | C22: CB | D22: FY 26-27 | E22: IC | F22: =SUMIF('[2]CB '!$A$1:$A$16,"Prachi Mayekar",'[2]CB '!$C$1:$C$16) -> 7.5 | G22: =SUMIF('[1]Opportunity Pipeline'!$F:$F, "Prachi Mayekar",'[1]Opportunity Pipeline'!$O:$O)/10^7 -> 12.897684 | H22: =IFERROR(G22/F22,"-") -> 1.7196913 | I22: =SUMIF('[2]CB '!$A$1:$A$16,"Prachi Mayekar",'[2]CB '!$D$1:$D$22) -> 7.5 | J22: - | K22: =IFERROR(J22/I22,"-") -> - | L22: ='[12]Prachi TARGET LETTER - 26-27'!$D$9/10^7 -> 15 | M22: =SUMIF('[1]Opportunity Pipeline'!$F:$F, "Prachi Mayekar",'[1]Opportunity Pipeline'!$O:$O)/10^7 -> 12.897684 | N22: =IFERROR(M22/L22,"-") -> 0.85984563 | O22: ='[12]Prachi TARGET LETTER - 26-27'!$D$10/10^7 -> 18 | P22: - | Q22: =IFERROR(P22/O22,"-") -> - | R22: =SUM(L22,O22) -> 33 | S22: =SUM(M22,P22) -> 12.897684 | T22: =IFERROR(S22/R22,"-") -> 0.39083892 | U22: =COUNTIF('[1]Opportunity Pipeline'!$F:$F,"Prachi Mayekar") -> 10
A23: 2 | B23: Shilpa Kavde | C23: CB | D23: FY 26-27 | E23: IC | F23: =SUMIF('[2]CB '!$A$1:$A$16,"Shilpa Kavde",'[2]CB '!$C$1:$C$16) -> 5 | G23: =SUMIF('[1]Opportunity Pipeline'!$F:$F, "Shilpa Kavde",'[1]Opportunity Pipeline'!$O:$O)/10^7 -> 2.9018714 | H23: =IFERROR(G23/F23,"-") -> 0.58037427 | I23: =SUMIF('[2]CB '!$A$1:$A$16,"Shilpa Kavde",'[2]CB '!$D$1:$D$22) -> 10 | J23: - | K23: =IFERROR(J23/I23,"-") -> - | L23: ='[13]Shilpa TARGET LETTER - 26-27'!$D$9/10^7 -> 15 | M23: =SUMIF('[1]Opportunity Pipeline'!$F:$F, "Shilpa Kavde",'[1]Opportunity Pipeline'!$O:$O)/10^7 -> 2.9018714 | N23: =IFERROR(M23/L23,"-") -> 0.19345809 | O23: ='[13]Shilpa TARGET LETTER - 26-27'!$D$10/10^7 -> 25 | P23: - | Q23: =IFERROR(P23/O23,"-") -> - | R23: =SUM(L23,O23) -> 40 | S23: =SUM(M23,P23) -> 2.9018714 | T23: =IFERROR(S23/R23,"-") -> 0.072546784 | U23: =COUNTIF('[1]Opportunity Pipeline'!$F:$F,"Shilpa Kavde") -> 28
A24: 3 | B24: Vidula Chawan | C24: CB | D24: FY 26-27 | E24: IC | F24: =SUMIF('[2]CB '!$A$1:$A$22,"Vidula Chavan",'[2]CB '!$C$1:$C$22) -> 1 | G24: =SUMIF('[1]Opportunity Pipeline'!$F:$F, "Vidula Chawan",'[1]Opportunity Pipeline'!$O:$O)/10^7 -> 0.00384 | H24: =IFERROR(G24/F24,"-") -> 0.00384 | I24: =SUMIF('[2]CB '!$A$1:$A$22,"Vidula Chavan",'[2]CB '!$D$1:$D$22) -> 2 | J24: - | K24: =IFERROR(J24/I24,"-") -> - | L24: ='[14]Vidula TARGET LETTER - 26-27'!$D$9/10^7 -> 3 | M24: =SUMIF('[1]Opportunity Pipeline'!$F:$F, "Vidula Chawan",'[1]Opportunity Pipeline'!$O:$O)/10^7 -> 0.00384 | N24: =IFERROR(M24/L24,"-") -> 0.00128 | O24: ='[14]Vidula TARGET LETTER - 26-27'!$D$10/10^7 -> 6.5 | P24: - | Q24: =IFERROR(P24/O24,"-") -> - | R24: =SUM(L24,O24) -> 9.5 | S24: =SUM(M24,P24) -> 0.00384 | T24: =IFERROR(S24/R24,"-") -> 0.00040421053 | U24: =COUNTIF('[1]Opportunity Pipeline'!$F:$F,"Vidula Chawan") -> 3
A25: 4 | B25: Jimesh Shah | C25: CB | D25: FY 26-27 | E25: TL | F25: 5 | G25: =SUMIF('[1]Opportunity Pipeline'!$F:$F, "Jimesh Shah",'[1]Opportunity Pipeline'!$O:$O)/10^7 -> 0.0227272 | H25: =IFERROR(G25/F25,"-") -> 0.00454544 | I25: 10 | J25: - | K25: =IFERROR(J25/I25,"-") -> - | L25: ='[15]Jimesh TARGET LETTER - 26-27'!$D$9/10^7 -> 15 | M25: =SUMIF('[1]Opportunity Pipeline'!$F:$F, "Jimesh Shah",'[1]Opportunity Pipeline'!$O:$O)/10^7 -> 0.0227272 | N25: =IFERROR(M25/L25,"-") -> 0.0015151467 | O25: ='[15]Jimesh TARGET LETTER - 26-27'!$D$13/10^7 -> 30 | P25: - | Q25: =IFERROR(P25/O25,"-") -> - | R25: =SUM(L25,O25) -> 45 | S25: =SUM(M25,P25) -> 0.0227272 | T25: =IFERROR(S25/R25,"-") -> 0.00050504889 | U25: =COUNTIF('[1]Opportunity Pipeline'!$F:$F,"Jimesh Shah") -> 2
B26: IC Subtotal — CB | F26: =SUM(F20:F25) -> 18.5 | G26: =SUM(G20:G25) -> 15.826123 | H26: =G26/F26 -> 0.85546611 | I26: =SUM(I20:I25) -> 29.5 | J26: =SUM(J20:J25) -> 0 | K26: =J26/I26 -> 0 | L26: =SUM(L20:L25) -> 48 | M26: =SUM(M20:M25) -> 15.826123 | N26: =M26/L26 -> 0.3297109 | O26: =SUM(O20:O25) -> 79.5 | P26: =SUM(P20:P25) -> 0 | Q26: =P26/O26 -> 0 | R26: =SUM(R20:R25) -> 127.5 | S26: =SUM(S20:S25) -> 15.826123 | T26: =S26/R26 -> 0.12412645 | U26: =SUM(U20:U25) -> 43
A28: GB Division
A29: 1 | B29: Ashish Singh | C29: GB | D29: FY 26-27 | E29: IC, Cloud | F29: =SUMIF('[2]GB '!$A$1:$A$28,"Ashish",'[2]GB '!$C$1:$C$28) -> 2 | G29: =SUMIF('[1]Opportunity Pipeline'!$F:$F, "Ashish Singh",'[1]Opportunity Pipeline'!$O:$O)/10^7 -> 1.3458431 | H29: =IFERROR(G29/F29,"-") -> 0.67292153 | I29: =SUMIF('[2]GB '!$A$1:$A$28,"Ashish",'[2]GB '!$D$1:$D$28) -> 3 | J29: - | K29: =IFERROR(J29/I29,"-") -> - | L29: ='[16]Ashish Target Letter 26 27 '!$D$9/10^7 -> 5 | M29: =SUMIF('[1]Opportunity Pipeline'!$F:$F, "Ashish Singh",'[1]Opportunity Pipeline'!$O:$O)/10^7 -> 1.3458431 | N29: =IFERROR(M29/L29,"-") -> 0.26916861 | O29: ='[16]Ashish Target Letter 26 27 '!$D$10/10^7 -> 10 | P29: - | Q29: =IFERROR(P29/O29,"-") -> - | R29: =SUM(L29,O29) -> 15 | S29: =SUM(M29,P29) -> 1.3458431 | T29: =IFERROR(S29/R29,"-") -> 0.08972287 | U29: =COUNTIF('[1]Opportunity Pipeline'!$F:$F,"Ashish Singh") -> 9
A30: 2 | B30: Rima Kamalakar Ingle | C30: GB | D30: FY 26-27 | E30: IC, Cloud | F30: - | G30: =SUMIF('[1]Opportunity Pipeline'!$F:$F, "Rima",'[1]Opportunity Pipeline'!$O:$O)/10^7 -> 0 | H30: =IFERROR(G30/F30,"-") -> - | I30: - | J30: - | K30: =IFERROR(J30/I30,"-") -> - | L30: ='[17]Rima Target Letter 26 27 '!$D$9/10^7 -> 3 | M30: =SUMIF('[1]Opportunity Pipeline'!$F:$F, "Rima",'[1]Opportunity Pipeline'!$O:$O)/10^7 -> 0 | N30: =IFERROR(M30/L30,"-") -> 0 | O30: ='[17]Rima Target Letter 26 27 '!$D$10/10^7 -> 5 | P30: - | Q30: =IFERROR(P30/O30,"-") -> - | R30: =SUM(L30,O30) -> 8 | S30: =SUM(M30,P30) -> 0 | T30: =IFERROR(S30/R30,"-") -> 0 | U30: =COUNTIF('[1]Opportunity Pipeline'!$F:$F,"Rima") -> 0
A31: 3 | B31: Ayushman Singh | C31: GB | D31: FY 26-27 | E31: IC, Cyber security | F31: =SUMIF('[2]GB '!$A$1:$A$28,"Ayushaman",'[2]GB '!$C$1:$C$28) -> 1 | G31: =SUMIF('[1]Opportunity Pipeline'!$F:$F, "Ayushman Singh",'[1]Opportunity Pipeline'!$O:$O)/10^7 -> 0.3020589 | H31: =IFERROR(G31/F31,"-") -> 0.3020589 | I31: =SUMIF('[2]GB '!$A$1:$A$28,"Ayushaman",'[2]GB '!$D$1:$D$28) -> 2 | J31: - | K31: =IFERROR(J31/I31,"-") -> - | L31: ='[18]Ayushman-TARGET LETTER - 26-27'!$D$9/10^7 -> 3 | M31: =SUMIF('[1]Opportunity Pipeline'!$F:$F, "Ayushman Singh",'[1]Opportunity Pipeline'!$O:$O)/10^7 -> 0.3020589 | N31: =IFERROR(M31/L31,"-") -> 0.1006863 | O31: ='[18]Ayushman-TARGET LETTER - 26-27'!$D$10/10^7 -> 9 | P31: - | Q31: =IFERROR(P31/O31,"-") -> - | R31: =SUM(L31,O31) -> 12 | S31: =SUM(M31,P31) -> 0.3020589 | T31: =IFERROR(S31/R31,"-") -> 0.025171575 | U31: =COUNTIF('[1]Opportunity Pipeline'!$F:$F,"Ayushman Singh") -> 4
A32: 4 | B32: Shubhangi Srinivasan | C32: GB | D32: FY 26-27 | E32: IC, Cyber security | F32: =SUMIF('[2]GB '!$A$1:$A$28,"Shubhangi",'[2]GB '!$C$1:$C$28) -> 2 | G32: =SUMIF('[1]Opportunity Pipeline'!$F:$F, "Shubhangi Srinivasan",'[1]Opportunity Pipeline'!$O:$O)/10^7 -> 5.5185176 | H32: =IFERROR(G32/F32,"-") -> 2.7592588 | I32: =SUMIF('[2]GB '!$A$1:$A$28,"Shubhangi",'[2]GB '!$D$1:$D$28) -> 3 | J32: - | K32: =IFERROR(J32/I32,"-") -> - | L32: ='[19]Shubhangi-TARGET LETTER - 26-27'!$D$9/10^7 -> 5 | M32: =SUMIF('[1]Opportunity Pipeline'!$F:$F, "Shubhangi Srinivasan",'[1]Opportunity Pipeline'!$O:$O)/10^7 -> 5.5185176 | N32: =IFERROR(M32/L32,"-") -> 1.1037035 | O32: ='[19]Shubhangi-TARGET LETTER - 26-27'!$D$10/10^7 -> 10 | P32: - | Q32: =IFERROR(P32/O32,"-") -> - | R32: =SUM(L32,O32) -> 15 | S32: =SUM(M32,P32) -> 5.5185176 | T32: =IFERROR(S32/R32,"-") -> 0.36790117 | U32: =COUNTIF('[1]Opportunity Pipeline'!$F:$F,"Shubhangi Srinivasan") -> 13
A33: 5 | B33: Atharva Karpe | C33: GB | D33: FY 26-27 | E33: IC | F33: =SUMIF('[2]GB '!$A$1:$A$28,"Atharva Kapre",'[2]GB '!$C$1:$C$28) -> 3 | G33: =SUMIF('[1]Opportunity Pipeline'!$F:$F, "Atharva Karpe",'[1]Opportunity Pipeline'!$O:$O)/10^7 -> 6.4578697 | H33: =IFERROR(G33/F33,"-") -> 2.1526232 | I33: =SUMIF('[2]GB '!$A$1:$A$28,"Atharva Kapre",'[2]GB '!$D$1:$D$28) -> 1 | J33: - | K33: =IFERROR(J33/I33,"-") -> - | L33: ='[20]Atharva -TARGET LETTER - 26-27'!$D$9/10^7 -> 4 | M33: =SUMIF('[1]Opportunity Pipeline'!$F:$F, "Atharva Karpe",'[1]Opportunity Pipeline'!$O:$O)/10^7 -> 6.4578697 | N33: =IFERROR(M33/L33,"-") -> 1.6144674 | O33: ='[20]Atharva -TARGET LETTER - 26-27'!$D$10/10^7 -> 4 | P33: - | Q33: =IFERROR(P33/O33,"-") -> - | R33: =SUM(L33,O33) -> 8 | S33: =SUM(M33,P33) -> 6.4578697 | T33: =IFERROR(S33/R33,"-") -> 0.80723371 | U33: =COUNTIF('[1]Opportunity Pipeline'!$F:$F,"Atharva Karpe") -> 12
A34: 6 | B34: Jay Rushi | C34: GB | D34: FY 26-27 | E34: IC | F34: =SUMIF('[2]GB '!$A$1:$A$28,"Jay Rushi",'[2]GB '!$C$1:$C$28) -> 1 | G34: =SUMIF('[1]Opportunity Pipeline'!$F:$F, "Jay Rushi",'[1]Opportunity Pipeline'!$O:$O)/10^7 -> 1.4900934 | H34: =IFERROR(G34/F34,"-") -> 1.4900934 | I34: =SUMIF('[2]GB '!$A$1:$A$28,"Jay Rushi",'[2]GB '!$D$1:$D$28) -> 2 | J34: - | K34: =IFERROR(J34/I34,"-") -> - | L34: ='[21]Jay Rushi TARGET LETTER - 26-27'!$D$9/10^7 -> 3 | M34: =SUMIF('[1]Opportunity Pipeline'!$F:$F, "Jay Rushi",'[1]Opportunity Pipeline'!$O:$O)/10^7 -> 1.4900934 | N34: =IFERROR(M34/L34,"-") -> 0.4966978 | O34: ='[21]Jay Rushi TARGET LETTER - 26-27'!$D$10/10^7 -> 5 | P34: - | Q34: =IFERROR(P34/O34,"-") -> - | R34: =SUM(L34,O34) -> 8 | S34: =SUM(M34,P34) -> 1.4900934 | T34: =IFERROR(S34/R34,"-") -> 0.18626167 | U34: =COUNTIF('[1]Opportunity Pipeline'!$F:$F,"Jay Rushi") -> 12
A35: 7 | B35: Sana Rashid Bhatkar | C35: GB | D35: FY 26-27 | E35: TL | F35: - | G35: =SUMIF('[1]Opportunity Pipeline'!$F:$F, "Sana",'[1]Opportunity Pipeline'!$O:$O)/10^7 -> 0 | H35: =IFERROR(G35/F35,"-") -> - | I35: - | J35: - | K35: =IFERROR(J35/I35,"-") -> - | L35: ='[22]SANA -TARGET LETTER - 26-27'!$D$9/10^7 -> 3.2 | M35: =SUMIF('[1]Opportunity Pipeline'!$F:$F, "Sana",'[1]Opportunity Pipeline'!$O:$O)/10^7 -> 0 | N35: =IFERROR(M35/L35,"-") -> 0 | O35: ='[22]SANA -TARGET LETTER - 26-27'!$D$14/10^7 -> 6.8 | P35: - | Q35: =IFERROR(P35/O35,"-") -> - | R35: =SUM(L35,O35) -> 10 | S35: =SUM(M35,P35) -> 0 | T35: =IFERROR(S35/R35,"-") -> 0 | U35: =COUNTIF('[1]Opportunity Pipeline'!$F:$F,"Sana") -> 0
A36: 8 | B36: Bhumi Karelia | C36: GB | D36: FY 26-27 | E36: IC | F36: =SUMIF('[2]GB '!$A$1:$A$28,"Bhumi ",'[2]GB '!$C$1:$C$28) -> 0.1 | G36: =SUMIF('[1]Opportunity Pipeline'!$F:$F, "Bhumi",'[1]Opportunity Pipeline'!$O:$O)/10^7 -> 0 | H36: =IFERROR(G36/F36,"-") -> 0 | I36: =SUMIF('[2]GB '!$A$1:$A$28,"Bhumi ",'[2]GB '!$D$1:$D$28) -> 0.5 | J36: - | K36: =IFERROR(J36/I36,"-") -> - | L36: ='[23]Bhumi Target Letter 26 27 '!$D$9/10^7 -> 0.6 | M36: =SUMIF('[1]Opportunity Pipeline'!$F:$F, "Bhumi",'[1]Opportunity Pipeline'!$O:$O)/10^7 -> 0 | N36: =IFERROR(M36/L36,"-") -> 0 | O36: ='[23]Bhumi Target Letter 26 27 '!$D$10/10^7 -> 1.4 | P36: - | Q36: =IFERROR(P36/O36,"-") -> - | R36: =SUM(L36,O36) -> 2 | S36: =SUM(M36,P36) -> 0 | T36: =IFERROR(S36/R36,"-") -> 0 | U36: =COUNTIF('[1]Opportunity Pipeline'!$F:$F,"Bhumi Karelia") -> 0
A37: 9 | B37: Rizwana Khan | C37: GB | D37: FY 26-27 | E37: IC | F37: =SUMIF('[2]GB '!$A$1:$A$28,"Rizwana (ISR/OSR)",'[2]GB '!$C$1:$C$28) -> 0.5 | G37: =SUMIF('[1]Opportunity Pipeline'!$F:$F, "Rizwana",'[1]Opportunity Pipeline'!$O:$O)/10^7 -> 0 | H37: =IFERROR(G37/F37,"-") -> 0 | I37: =SUMIF('[2]GB '!$A$1:$A$28,"Rizwana (ISR/OSR)",'[2]GB '!$D$1:$D$28) -> 1 | J37: - | K37: =IFERROR(J37/I37,"-") -> - | L37: ='[24]Rizwana Target Letter 26 27 '!$D$9/10^7 -> 1.5 | M37: =SUMIF('[1]Opportunity Pipeline'!$F:$F, "Rizwana",'[1]Opportunity Pipeline'!$O:$O)/10^7 -> 0 | N37: =IFERROR(M37/L37,"-") -> 0 | O37: ='[24]Rizwana Target Letter 26 27 '!$D$10/10^7 -> 3.5 | P37: - | Q37: =IFERROR(P37/O37,"-") -> - | R37: =SUM(L37,O37) -> 5 | S37: =SUM(M37,P37) -> 0 | T37: =IFERROR(S37/R37,"-") -> 0 | U37: =COUNTIF('[1]Opportunity Pipeline'!$F:$F,"Rizwana Khan") -> 0
A38: 10 | B38: Suvesh Malakar | C38: GB | D38: FY 26-27 | E38: IC | F38: =SUMIF('[2]GB '!$A$1:$A$28,"Suyesh",'[2]GB '!$C$1:$C$28) -> 0.1 | G38: =SUMIF('[1]Opportunity Pipeline'!$F:$F, "Suvesh Malakar",'[1]Opportunity Pipeline'!$O:$O)/10^7 -> 0 | H38: =IFERROR(G38/F38,"-") -> 0 | I38: =SUMIF('[2]GB '!$A$1:$A$28,"Suyesh",'[2]GB '!$D$1:$D$28) -> 0.5 | J38: - | K38: =IFERROR(J38/I38,"-") -> - | L38: ='[25]Suvesh- Target Letter 26 27 '!$D$9/10^7 -> 0.6 | M38: =SUMIF('[1]Opportunity Pipeline'!$F:$F, "Suvesh Malakar",'[1]Opportunity Pipeline'!$O:$O)/10^7 -> 0 | N38: =IFERROR(M38/L38,"-") -> 0 | O38: ='[25]Suvesh- Target Letter 26 27 '!$D$10/10^7 -> 1.4 | P38: - | Q38: =IFERROR(P38/O38,"-") -> - | R38: =SUM(L38,O38) -> 2 | S38: =SUM(M38,P38) -> 0 | T38: =IFERROR(S38/R38,"-") -> 0 | U38: =COUNTIF('[1]Opportunity Pipeline'!$F:$F,"Suvesh Malakar") -> 0
B39: IC Subtotal — GB | F39: =SUM(F33:F38) -> 4.7 | G39: =SUM(G33:G38) -> 7.9479631 | H39: =G39/F39 -> 1.691056 | I39: =SUM(I33:I38) -> 5 | J39: =SUM(J33:J38) -> 0 | K39: =J39/I39 -> 0 | L39: =SUM(L33:L38) -> 12.9 | M39: =SUM(M33:M38) -> 7.9479631 | N39: =M39/L39 -> 0.61612117 | O39: =SUM(O33:O38) -> 22.1 | P39: =SUM(P33:P38) -> 0 | Q39: =P39/O39 -> 0 | R39: =SUM(R33:R38) -> 35 | S39: =SUM(S33:S38) -> 7.9479631 | T39: =S39/R39 -> 0.22708466 | U39: =SUM(U33:U38) -> 24
A41: South Division
A42: 1 | B42: Abrar Memon | C42: South | D42: FY 26-27 | E42: IC | F42: =SUMIF('[2]South '!$B$1:$B$28,"Abrar Altaf Menon",'[2]South '!$D$1:$D$28) -> 2 | G42: =SUMIF('[1]Opportunity Pipeline'!$F:$F, "Abrar Memon",'[1]Opportunity Pipeline'!$O:$O)/10^7 -> 0.041457089 | H42: =IFERROR(G42/F42,"-") -> 0.020728545 | I42: =SUMIF('[2]South '!$B$1:$B$28,"Abrar Altaf Menon",'[2]South '!$E$1:$E$28) -> 2 | J42: - | K42: =IFERROR(J42/I42,"-") -> - | L42: ='[26]Abrar TARGET LETTER - 26-27'!$D$9/10^7 -> 4 | M42: =SUMIF('[1]Opportunity Pipeline'!$F:$F, "Abrar Memon",'[1]Opportunity Pipeline'!$O:$O)/10^7 -> 0.041457089 | N42: =IFERROR(M42/L42,"-") -> 0.010364272 | O42: ='[26]Abrar TARGET LETTER - 26-27'!$D$10/10^7 -> 4 | P42: - | Q42: =IFERROR(P42/O42,"-") -> - | R42: =SUM(L42,O42) -> 8 | S42: =SUM(M42,P42) -> 0.041457089 | T42: =IFERROR(S42/R42,"-") -> 0.0051821361 | U42: =COUNTIF('[1]Opportunity Pipeline'!$F:$F,"Abrar Memon") -> 6
A43: 2 | B43: Sagar TR | C43: South | D43: FY 26-27 | E43: IC | F43: =SUMIF('[2]South '!$B$1:$B$28,"Sagar TR",'[2]South '!$D$1:$D$28) -> 2.5 | G43: =SUMIF('[1]Opportunity Pipeline'!$F:$F, "Sagar TR",'[1]Opportunity Pipeline'!$O:$O)/10^7 -> 1.1067547 | H43: =IFERROR(G43/F43,"-") -> 0.44270188 | I43: =SUMIF('[2]South '!$B$1:$B$28,"Sagar TR",'[2]South '!$E$1:$E$28) -> 2.5 | J43: - | K43: =IFERROR(J43/I43,"-") -> - | L43: ='[27]Sagar- TARGET LETTER - 26-27'!$D$9/10^7 -> 5 | M43: =SUMIF('[1]Opportunity Pipeline'!$F:$F, "Sagar TR",'[1]Opportunity Pipeline'!$O:$O)/10^7 -> 1.1067547 | N43: =IFERROR(M43/L43,"-") -> 0.22135094 | O43: ='[27]Sagar- TARGET LETTER - 26-27'!$D$10/10^7 -> 5 | P43: - | Q43: =IFERROR(P43/O43,"-") -> - | R43: =SUM(L43,O43) -> 10 | S43: =SUM(M43,P43) -> 1.1067547 | T43: =IFERROR(S43/R43,"-") -> 0.11067547 | U43: =COUNTIF('[1]Opportunity Pipeline'!$F:$F,"Sagar TR") -> 34
A44: 3 | B44: Shahbaz Khan | C44: South | D44: FY 26-27 | E44: IC | F44: =SUMIF('[2]South '!$B$1:$B$28,"Shahbaz Khan",'[2]South '!$D$1:$D$28) -> 3 | G44: =SUMIF('[1]Opportunity Pipeline'!$F:$F, "Shahbaz Khan",'[1]Opportunity Pipeline'!$O:$O)/10^7 -> 3.8053236 | H44: =IFERROR(G44/F44,"-") -> 1.2684412 | I44: =SUMIF('[2]South '!$B$1:$B$28,"Shahbaz Khan",'[2]South '!$E$1:$E$28) -> 3 | J44: - | K44: =IFERROR(J44/I44,"-") -> - | L44: ='[28]Shahbaz - TARGET LETTER - 26-27'!$D$9/10^7 -> 6 | M44: =SUMIF('[1]Opportunity Pipeline'!$F:$F, "Shahbaz Khan",'[1]Opportunity Pipeline'!$O:$O)/10^7 -> 3.8053236 | N44: =IFERROR(M44/L44,"-") -> 0.6342206 | O44: ='[28]Shahbaz - TARGET LETTER - 26-27'!$D$10/10^7 -> 6 | P44: - | Q44: =IFERROR(P44/O44,"-") -> - | R44: =SUM(L44,O44) -> 12 | S44: =SUM(M44,P44) -> 3.8053236 | T44: =IFERROR(S44/R44,"-") -> 0.3171103 | U44: =COUNTIF('[1]Opportunity Pipeline'!$F:$F,"Shahbaz Khan") -> 12
...

Sheet V2 · Leadership 
A1: VIEW 2 | LEADER'S CONTRIBUTION | Booking (Revenue) | H1 & Annual
A2: # | B2: Employee Name | C2: Division | D2: FY | E2: Type / Notes | F2: Q1 Quota (₹ Cr) | G2: Q1 Actuals (₹ Cr) | H2: Attainment % (Q1) | I2: Q2 Quota (₹ Cr) | J2: Q2 Actuals (₹ Cr) | K2: Attainment % (Q2) | L2: H1 Quota (₹ Cr) | M2: H1 Actuals (₹ Cr) | N2: Attainment % (H1) | O2: H2 Quota (₹ Cr) | P2: H2 Actuals (₹ Cr) | Q2: Attainment % (H2) | R2: Annual Quota (₹ Cr) | S2: Annual Actuals (₹ Cr) | T2: Attainment % (Annual) | U2: # Deals (Total) | V2: Led-By Deals (count) | W2: Led-By Rev (₹ Cr) | X2: Contributed Deals (count) | Y2: Contributed Rev (₹ Cr) | Z2: Rank (Div.)
A3: 1 | B3: Ajay Patodia | C3: DCG | D3: FY 25-26 | E3: Head
A4: 2 | B4: Dipti Karpe | C4: S2 | D4: FY 25-26 | E4: AVP
A5: 3 | B5: Ishwari Santosh Kadam | C5: S1 | D5: FY 25-26 | E5: AVP
A6: 4 | B6: Vineet Gadia | C6: CB | D6: FY 25-26 | E6: Head
A7: 5 | B7: Sanjeev Kohli | C7: GEO X | D7: FY 25-26 | E7: Head
A8: 6 | B8: Yogesh Bhatia | C8: GB | D8: FY 25-26 | E8: Head
A9: 7 | B9: Jitesh Rajput | C9: CLOUD | D9: FY 25-26 | E9: Head
A10: 8 | B10: Rocky Braganza | C10: CSN | D10: FY 25-26 | E10: Head

Sheet V3 · RTM Division level
A1: VIEW 2 — SUMMARY OUTLOOK | BU Roll-up | Revenue + Bottomline (BL) | H1 & Annual
A2: Level / Name | B2: Division | C2: Q1 — Revenue (₹ Cr) | F2: Q1 — Bottomline (₹ Cr) | I2: Q2 — Revenue (₹ Cr) | L2: Q2 — Bottomline (₹ Cr) | O2: H1 — Revenue (₹ Cr) | R2: H1 — Bottomline (₹ Cr) | U2: H1 # Deals | V2: H2 — Revenue (₹ Cr) | Y2: H2 — Bottomline (₹ Cr) | AB2: H2 # Deals | AC2: Annual — Revenue (₹ Cr) | AF2: Annual — Bottomline (₹ Cr) | AI2: Ann # Deals
A3: Level | B3: Div. | C3: Quota | D3: Actuals | E3: Att% | F3: Quota | G3: Actuals | H3: Att% | I3: Quota | J3: Actuals | K3: Att% | L3: Quota | M3: Actuals | N3: Att% | O3: Quota | P3: Actuals | Q3: Att% | R3: Quota | S3: Actuals | T3: Att% | U3: Count | V3: Quota | W3: Actuals | X3: Att% | Y3: Quota | Z3: Actuals | AA3: Att% | AB3: Count | AC3: Quota | AD3: Actuals | AE3: Att% | AF3: Quota | AG3: Actuals | AH3: Att% | AI3: Count
A4: RTM Division Level
A5: S1 Division Total | B5: S1 | C5: ='V1 · Individual'!F10 -> #VALUE! | D5: ='V1 · Individual'!G10 -> #VALUE! | E5: =IFERROR(D5/C5,"-") -> - | F5: - | G5: - | H5: - | I5: ='V1 · Individual'!I10 -> 194.175 | J5: - | K5: - | L5: - | M5: - | N5: - | O5: ='V1 · Individual'!L10 -> 307.35 | P5: ='V1 · Individual'!M10 -> 55.934141 | Q5: =IFERROR(P5/O5,"-") -> 0.18198842 | R5: - | S5: - | T5: - | U5: ='V1 · Individual'!U10 -> 91 | V5: ='V1 · Individual'!O10 -> 352.65 | W5: - | X5: - | Y5: - | Z5: - | AA5: - | AB5: - | AC5: ='V1 · Individual'!R10 -> 660 | AD5: ='V1 · Individual'!S10 -> 55.934141 | AE5: =AD5/AC5 -> 0.084748698 | AF5: - | AG5: - | AH5: - | AI5: =SUM(U5,AB5) -> 91
A6: S2 Division Total | B6: S2 | C6: ='V1 · Individual'!F19 -> 54.85 | D6: ='V1 · Individual'!G19 -> 15.396571 | E6: =IFERROR(D6/C6,"-") -> 0.2807032 | F6: - | G6: - | H6: - | I6: ='V1 · Individual'!I19 -> 84.15 | J6: - | K6: - | L6: - | M6: - | N6: - | O6: ='V1 · Individual'!L19 -> 107.75 | P6: ='V1 · Individual'!M19 -> 15.396571 | Q6: =IFERROR(P6/O6,"-") -> 0.14289161 | R6: - | S6: - | T6: - | U6: ='V1 · Individual'!U19 -> 23 | V6: ='V1 · Individual'!O19 -> 138.25 | W6: - | X6: - | Y6: - | Z6: - | AA6: - | AB6: - | AC6: ='V1 · Individual'!R19 -> 246 | AD6: ='V1 · Individual'!S19 -> 15.396571 | AE6: =AD6/AC6 -> 0.062587685 | AF6: - | AG6: - | AH6: - | AI6: =SUM(U6,AB6) -> 23
A7: CB Division Total | B7: CB | C7: ='V1 · Individual'!F26 -> 18.5 | D7: ='V1 · Individual'!G26 -> 15.826123 | E7: =IFERROR(D7/C7,"-") -> 0.85546611 | F7: - | G7: - | H7: - | I7: ='V1 · Individual'!I26 -> 29.5 | J7: - | K7: - | L7: - | M7: - | N7: - | O7: ='V1 · Individual'!L26 -> 48 | P7: ='V1 · Individual'!M26 -> 15.826123 | Q7: =IFERROR(P7/O7,"-") -> 0.3297109 | R7: - | S7: - | T7: - | U7: ='V1 · Individual'!U26 -> 43 | V7: ='V1 · Individual'!O26 -> 79.5 | W7: - | X7: - | Y7: - | Z7: - | AA7: - | AB7: - | AC7: ='V1 · Individual'!R26 -> 127.5 | AD7: ='V1 · Individual'!S26 -> 15.826123 | AE7: =AD7/AC7 -> 0.12412645 | AF7: - | AG7: - | AH7: - | AI7: =SUM(U7,AB7) -> 43
A8: GB Division Total | B8: GB | C8: ='V1 · Individual'!F39 -> 4.7 | D8: ='V1 · Individual'!G39 -> 7.9479631 | E8: =IFERROR(D8/C8,"-") -> 1.691056 | F8: - | G8: - | H8: - | I8: ='V1 · Individual'!I39 -> 5 | J8: - | K8: - | L8: - | M8: - | N8: - | O8: ='V1 · Individual'!L39 -> 12.9 | P8: ='V1 · Individual'!M39 -> 7.9479631 | Q8: =IFERROR(P8/O8,"-") -> 0.61612117 | R8: - | S8: - | T8: - | U8: ='V1 · Individual'!U39 -> 24 | V8: ='V1 · Individual'!O39 -> 22.1 | W8: - | X8: - | Y8: - | Z8: - | AA8: - | AB8: - | AC8: ='V1 · Individual'!R39 -> 35 | AD8: ='V1 · Individual'!S39 -> 7.9479631 | AE8: =AD8/AC8 -> 0.22708466 | AF8: - | AG8: - | AH8: - | AI8: =SUM(U8,AB8) -> 24
A9: South Division Total | B9: South | C9: ='V1 · Individual'!F46 -> 10.5 | D9: ='V1 · Individual'!G46 -> 10.289627 | E9: =IFERROR(D9/C9,"-") -> 0.97996447 | F9: - | G9: - | H9: - | I9: ='V1 · Individual'!I46 -> 7.5 | J9: - | K9: - | L9: - | M9: - | N9: - | O9: ='V1 · Individual'!L46 -> 22 | P9: ='V1 · Individual'!M46 -> 10.289627 | Q9: =IFERROR(P9/O9,"-") -> 0.46771031 | R9: - | S9: - | T9: - | U9: ='V1 · Individual'!U46 -> 54 | V9: ='V1 · Individual'!O46 -> 23 | W9: - | X9: - | Y9: - | Z9: - | AA9: - | AB9: - | AC9: ='V1 · Individual'!R46 -> 45 | AD9: ='V1 · Individual'!S46 -> 10.289627 | AE9: =AD9/AC9 -> 0.22865838 | AF9: - | AG9: - | AH9: - | AI9: =SUM(U9,AB9) -> 54
A10: Geo Expansion Division | B10: Geo X | C10: - | D10: - | E10: - | F10: ='V1 · Individual'!F50 -> 0.4 | G10: ='V1 · Individual'!G50 -> 3.8126084 | H10: =IFERROR(G10/F10,"-") -> 9.531521 | I10: - | J10: - | K10: - | L10: ='V1 · Individual'!I50 -> 0.65 | M10: ='V1 · Individual'!J50 -> 0 | N10: =M10/L10 -> 0 | O10: - | P10: - | Q10: - | R10: ='V1 · Individual'!L50 -> 1.05 | S10: ='V1 · Individual'!M50 -> 3.8126084 | T10: =S10/R10 -> 3.6310556 | U10: - | V10: - | W10: - | X10: - | Y10: ='V1 · Individual'!O50 -> 1.35 | Z10: - | AA10: - | AB10: - | AC10: - | AD10: - | AE10: =IFERROR(AD10/AC10,"-") -> - | AF10: ='V1 · Individual'!R50 -> 2.4 | AG10: ='V1 · Individual'!S50 -> 3.8126084 | AH10: ='V1 · Individual'!T50 -> 1.5885868 | AI10: =SUM(U10,AB10) -> 0
A11: COMPANY TOTAL (Revenue IC, excl. GeoX BL) | C11: =SUM(C5:C10) -> #VALUE! | D11: =SUM(D5:D10) -> #VALUE! | E11: =D11/C11 -> #VALUE! | F11: =SUM(F5:F10) -> 0.4 | G11: =SUM(G5:G10) -> 3.8126084 | H11: =G11/F11 -> 9.531521 | I11: =SUM(I5:I10) -> 320.325 | J11: =SUM(J5:J10) -> 0 | K11: =SUM(K5:K10) -> 0 | L11: =SUM(L5:L10) -> 0.65 | M11: =SUM(M5:M10) -> 0 | N11: =SUM(N5:N10) -> 0 | O11: =SUM(O5:O10) -> 498 | P11: =SUM(P5:P10) -> 105.39442 | Q11: =P11/O11 -> 0.21163539 | R11: =SUM(R5:R10) -> 1.05 | S11: =SUM(S5:S10) -> 3.8126084 | T11: =SUM(T5:T10) -> 3.6310556 | U11: =SUM(U5:U10) -> 235 | V11: =SUM(V5:V10) -> 615.5 | W11: =SUM(W5:W10) -> 0 | X11: =SUM(X5:X10) -> 0 | Y11: =SUM(Y5:Y10) -> 1.35 | ... AI11: =SUM(AI5:AI10) -> 235

Sheet V5 · DCG
A1: VIEW 5 — RTM CONTRIBUTION | DCG | Booking (Revenue) | H1 & Annual
A2: # | B2: RTM Name | C2: Division | D2: FY | E2: Q1 Quota (₹ Cr) | F2: Q1 Actuals (₹ Cr) | G2: Attainment % (Q1) | H2: Q2 Quota (₹ Cr) | I2: Q2 Actuals (₹ Cr) | J2: Attainment % (Q2) | K2: H1 Quota (₹ Cr) | L2: H1 Actuals (₹ Cr) | M2: Attainment % (H1) | N2: H2 Quota (₹ Cr) | O2: H2 Actuals (₹ Cr) | P2: Attainment % (H2) | Q2: Annual Quota (₹ Cr) | R2: Annual Actuals (₹ Cr) | S2: Attainment % (Annual) | T2: # Deals (Total) | U2: Led-By Deals (count) | V2: Led-By Rev (₹ Cr) | W2: Contributed Deals (count) | X2: Contributed Rev (₹ Cr) | Y2: Rank (Div.)
A3: 1 | B3: S1 Division Total | C3: S1 | D3: FY 25-26 | E3: - | F3: =SUMIFS('[1]Opportunity Pipeline'!$O:$O,'[1]Opportunity Pipeline'!$K:$K,"Data Centre",'[1]Opportunity Pipeline'!$Z:$Z,"S1")/10^7 -> 13.039549 | G3: =IFERROR(F3/E3,"-") -> - | H3: - | I3: - | J3: =IFERROR(I3/H3,"-") -> - | K3: - | L3: =SUM(F3,I3) -> 13.039549 | M3: =IFERROR(L3/K3,"-") -> - | N3: - | O3: - | P3: - | Q3: 455 | R3: =SUM(L3,O3) -> 13.039549 | S3: =IFERROR(R3/Q3,"-") -> 0.02865835 | T3: =COUNTIFS('[1]Opportunity Pipeline'!$K:$K,"Data Centre",'[1]Opportunity Pipeline'!$Z:$Z,"S1") -> 11
A4: 2 | B4: S2 Division Total | C4: S2 | D4: FY 25-26 | E4: - | F4: =SUMIFS('[1]Opportunity Pipeline'!$O:$O,'[1]Opportunity Pipeline'!$K:$K,"Data Centre",'[1]Opportunity Pipeline'!$Z:$Z,"S2")/10^7 -> 5.8072067 | G4: =IFERROR(F4/E4,"-") -> - | H4: - | I4: - | J4: =IFERROR(I4/H4,"-") -> - | K4: - | L4: =SUM(F4,I4) -> 5.8072067 | M4: =IFERROR(L4/K4,"-") -> - | N4: - | O4: - | P4: - | Q4: 225 | R4: =SUM(L4,O4) -> 5.8072067 | S4: =IFERROR(R4/Q4,"-") -> 0.025809808 | T4: =COUNTIFS('[1]Opportunity Pipeline'!$K:$K,"Data Centre",'[1]Opportunity Pipeline'!$Z:$Z,"S2") -> 4
A5: 3 | B5: CB Division Total | C5: CB | D5: FY 25-26 | E5: - | F5: =SUMIFS('[1]Opportunity Pipeline'!$O:$O,'[1]Opportunity Pipeline'!$K:$K,"Data Centre",'[1]Opportunity Pipeline'!$Z:$Z,"CB")/10^7 -> 8.1258048 | G5: =IFERROR(F5/E5,"-") -> - | H5: - | I5: - | J5: =IFERROR(I5/H5,"-") -> - | K5: - | L5: =SUM(F5,I5) -> 8.1258048 | M5: =IFERROR(L5/K5,"-") -> - | N5: - | O5: - | P5: - | Q5: 40 | R5: =SUM(L5,O5) -> 8.1258048 | S5: =IFERROR(R5/Q5,"-") -> 0.20314512 | T5: =COUNTIFS('[1]Opportunity Pipeline'!$K:$K,"Data Centre",'[1]Opportunity Pipeline'!$Z:$Z,"CB") -> 3
A6: 4 | B6: GB Division Total | C6: GB | D6: FY 25-26 | E6: - | F6: =SUMIFS('[1]Opportunity Pipeline'!$O:$O,'[1]Opportunity Pipeline'!$K:$K,"Data Centre",'[1]Opportunity Pipeline'!$Z:$Z,"GB")/10^7 -> 0.2438 | G6: =IFERROR(F6/E6,"-") -> - | H6: - | I6: - | J6: =IFERROR(I6/H6,"-") -> - | K6: - | L6: =SUM(F6,I6) -> 0.2438 | M6: =IFERROR(L6/K6,"-") -> - | N6: - | O6: - | P6: - | Q6: 11 | R6: =SUM(L6,O6) -> 0.2438 | S6: =IFERROR(R6/Q6,"-") -> 0.022163636 | T6: =COUNTIFS('[1]Opportunity Pipeline'!$K:$K,"Data Centre",'[1]Opportunity Pipeline'!$Z:$Z,"GB") -> 2
A7: 5 | B7: South Division Total | C7: South | D7: FY 25-26 | E7: - | F7: =SUMIFS('[1]Opportunity Pipeline'!$O:$O,'[1]Opportunity Pipeline'!$K:$K,"Data Centre",'[1]Opportunity Pipeline'!$Z:$Z,"South")/10^7 -> 5.553386 | G7: =IFERROR(F7/E7,"-") -> - | H7: - | I7: - | J7: =IFERROR(I7/H7,"-") -> - | K7: - | L7: =SUM(F7,I7) -> 5.553386 | M7: =IFERROR(L7/K7,"-") -> - | N7: - | O7: - | P7: - | Q7: 14 | R7: =SUM(L7,O7) -> 5.553386 | S7: =IFERROR(R7/Q7,"-") -> 0.39667043 | T7: =COUNTIFS('[1]Opportunity Pipeline'!$K:$K,"Data Centre",'[1]Opportunity Pipeline'!$Z:$Z,"South") -> 5
A8: 6 | B8: GeoX Division Total | C8: GeoX | D8: FY 25-26 | E8: - | F8: =SUMIFS('[1]Opportunity Pipeline'!$O:$O,'[1]Opportunity Pipeline'!$K:$K,"Data Centre",'[1]Opportunity Pipeline'!$Z:$Z,"GeoX")/10^7 -> 0 | G8: =IFERROR(F8/E8,"-") -> - | H8: - | I8: - | J8: =IFERROR(I8/H8,"-") -> - | K8: - | L8: =SUM(F8,I8) -> 0 | M8: =IFERROR(L8/K8,"-") -> - | N8: - | O8: - | P8: - | Q8: 10 | R8: =SUM(L8,O8) -> 0 | S8: =IFERROR(R8/Q8,"-") -> 0 | T8: =COUNTIFS('[1]Opportunity Pipeline'!$K:$K,"Data Centre",'[1]Opportunity Pipeline'!$Z:$Z,"GeoX") -> 0
B9: RTM Total | E9: - | F9: =SUM(F3:F8) -> 32.769747 | G9: =IFERROR(F9/E9,"-") -> - | H9: - | I9: - | J9: =IFERROR(I9/H9,"-") -> - | K9: - | L9: =SUM(L3:L8) -> 32.769747 | M9: =IFERROR(L9/K9,"-") -> - | N9: - | O9: - | P9: - | Q9: =SUM(Q3:Q8) -> 755 | R9: =SUM(R3:R8) -> 32.769747 | S9: =IFERROR(R9/Q9,"-") -> 0.043403638 | T9: =SUM(T3:T8) -> 25

Sheet V6 · CSN
A1: VIEW 6 — RTM CONTRIBUTION | CSN | Booking (Revenue) | H1 & Annual
A2: # | B2: RTM Name | C2: Division | D2: FY | E2: Q1 Quota (₹ Cr) | F2: Q1 Actuals (₹ Cr) | G2: Attainment % (Q1) | H2: Q2 Quota (₹ Cr) | I2: Q2 Actuals (₹ Cr) | J2: Attainment % (Q2) | K2: H1 Quota (₹ Cr) | L2: H1 Actuals (₹ Cr) | M2: Attainment % (H1) | N2: H2 Quota (₹ Cr) | O2: H2 Actuals (₹ Cr) | P2: Attainment % (H2) | Q2: Annual Quota (₹ Cr) | R2: Annual Actuals (₹ Cr) | S2: Attainment % (Annual) | T2: # Deals (Total) | U2: Led-By Deals (count) | V2: Led-By Rev (₹ Cr) | W2: Contributed Deals (count) | X2: Contributed Rev (₹ Cr) | Y2: Rank (Div.)
A3: 1 | B3: S1 Division Total | C3: S1 | D3: FY 25-26 | E3: - | F3: =SUMIFS('[1]Opportunity Pipeline'!$O:$O,'[1]Opportunity Pipeline'!$K:$K,"Cyber Security & Networking",'[1]Opportunity Pipeline'!$Z:$Z,"S1")/10^7 -> 11.430924 | G3: =IFERROR(F3/E3,"-") -> - | H3: - | I3: - | J3: =IFERROR(I3/H3,"-") -> - | K3: - | L3: =SUM(F3,I3) -> 11.430924 | M3: =IFERROR(L3/K3,"-") -> - | N3: - | O3: - | P3: - | Q3: 90 | R3: =SUM(L3,O3) -> 11.430924 | S3: =IFERROR(R3/Q3,"-") -> 0.12701027 | T3: =COUNTIFS('[1]Opportunity Pipeline'!$K:$K,"Cyber Security & Networking",'[1]Opportunity Pipeline'!$Z:$Z,"S1") -> 16
A4: 2 | B4: S2 Division Total | C4: S2 | D4: FY 25-26 | E4: - | F4: =SUMIFS('[1]Opportunity Pipeline'!$O:$O,'[1]Opportunity Pipeline'!$K:$K,"Cyber Security & Networking",'[1]Opportunity Pipeline'!$Z:$Z,"S2")/10^7 -> 1.0755916 | G4: =IFERROR(F4/E4,"-") -> - | H4: - | I4: - | J4: =IFERROR(I4/H4,"-") -> - | K4: - | L4: =SUM(F4,I4) -> 1.0755916 | M4: =IFERROR(L4/K4,"-") -> - | N4: - | O4: - | P4: - | Q4: 30 | R4: =SUM(L4,O4) -> 1.0755916 | S4: =IFERROR(R4/Q4,"-") -> 0.035853054 | T4: =COUNTIFS('[1]Opportunity Pipeline'!$K:$K,"Cyber Security & Networking",'[1]Opportunity Pipeline'!$Z:$Z,"S2") -> 8
A5: 3 | B5: CB Division Total | C5: CB | D5: FY 25-26 | E5: - | F5: =SUMIFS('[1]Opportunity Pipeline'!$O:$O,'[1]Opportunity Pipeline'!$K:$K,"Cyber Security & Networking",'[1]Opportunity Pipeline'!$Z:$Z,"CB")/10^7 -> 5.8855196 | G5: =IFERROR(F5/E5,"-") -> - | H5: - | I5: - | J5: =IFERROR(I5/H5,"-") -> - | K5: - | L5: =SUM(F5,I5) -> 5.8855196 | M5: =IFERROR(L5/K5,"-") -> - | N5: - | O5: - | P5: - | Q5: 24 | R5: =SUM(L5,O5) -> 5.8855196 | S5: =IFERROR(R5/Q5,"-") -> 0.24522998 | T5: =COUNTIFS('[1]Opportunity Pipeline'!$K:$K,"Cyber Security & Networking",'[1]Opportunity Pipeline'!$Z:$Z,"CB") -> 6
A6: 4 | B6: GB Division Total | C6: GB | D6: FY 25-26 | E6: - | F6: =SUMIFS('[1]Opportunity Pipeline'!$O:$O,'[1]Opportunity Pipeline'!$K:$K,"Cyber Security & Networking",'[1]Opportunity Pipeline'!$Z:$Z,"GB")/10^7 -> 5.6325779 | G6: =IFERROR(F6/E6,"-") -> - | H6: - | I6: - | J6: =IFERROR(I6/H6,"-") -> - | K6: - | L6: =SUM(F6,I6) -> 5.6325779 | M6: =IFERROR(L6/K6,"-") -> - | N6: - | O6: - | P6: - | Q6: 20 | R6: =SUM(L6,O6) -> 5.6325779 | S6: =IFERROR(R6/Q6,"-") -> 0.28162889 | T6: =COUNTIFS('[1]Opportunity Pipeline'!$K:$K,"Cyber Security & Networking",'[1]Opportunity Pipeline'!$Z:$Z,"GB") -> 20
A7: 5 | B7: South Division Total | C7: South | D7: FY 25-26 | E7: - | F7: =SUMIFS('[1]Opportunity Pipeline'!$O:$O,'[1]Opportunity Pipeline'!$K:$K,"Cyber Security & Networking",'[1]Opportunity Pipeline'!$Z:$Z,"South")/10^7 -> 0.5456455 | G7: =IFERROR(F7/E7,"-") -> - | H7: - | I7: - | J7: =IFERROR(I7/H7,"-") -> - | K7: - | L7: =SUM(F7,I7) -> 0.5456455 | M7: =IFERROR(L7/K7,"-") -> - | N7: - | O7: - | P7: - | Q7: 1 | R7: =SUM(L7,O7) -> 0.5456455 | S7: =IFERROR(R7/Q7,"-") -> 0.5456455 | T7: =COUNTIFS('[1]Opportunity Pipeline'!$K:$K,"Cyber Security & Networking",'[1]Opportunity Pipeline'!$Z:$Z,"South") -> 15
A8: 6 | B8: GeoX Division Total | C8: GeoX | D8: FY 25-26 | E8: - | F8: =SUMIFS('[1]Opportunity Pipeline'!$O:$O,'[1]Opportunity Pipeline'!$K:$K,"Cyber Security & Networking",'[1]Opportunity Pipeline'!$Z:$Z,"GeoX")/10^7 -> 0 | G8: =IFERROR(F8/E8,"-") -> - | H8: - | I8: - | J8: =IFERROR(I8/H8,"-") -> - | K8: - | L8: =SUM(F8,I8) -> 0 | M8: =IFERROR(L8/K8,"-") -> - | N8: - | O8: - | P8: - | Q8: 20 | R8: =SUM(L8,O8) -> 0 | S8: =IFERROR(R8/Q8,"-") -> 0 | T8: =COUNTIFS('[1]Opportunity Pipeline'!$K:$K,"Cyber Security & Networking",'[1]Opportunity Pipeline'!$Z:$Z,"GeoX") -> 0
B9: RTM Total | E9: - | F9: =SUM(F3:F8) -> 24.570259 | G9: =IFERROR(F9/E9,"-") -> - | H9: - | I9: - | J9: =IFERROR(I9/H9,"-") -> - | K9: - | L9: =SUM(L3:L8) -> 24.570259 | M9: =IFERROR(L9/K9,"-") -> - | N9: - | O9: - | P9: - | Q9: =SUM(Q3:Q8) -> 185 | R9: =SUM(R3:R8) -> 24.570259 | S9: =IFERROR(R9/Q9,"-") -> 0.13281221 | T9: =SUM(T3:T8) -> 65

Sheet V7 · PS
A1: VIEW 7 — RTM CONTRIBUTION | PS | Booking (Revenue) | H1 & Annual
A2: # | B2: RTM Name | C2: Division | D2: FY | E2: Q1 Quota (₹ Cr) | F2: Q1 Actuals (₹ Cr) | G2: Attainment % (Q1) | H2: Q2 Quota (₹ Cr) | I2: Q2 Actuals (₹ Cr) | J2: Attainment % (Q2) | K2: H1 Quota (₹ Cr) | L2: H1 Actuals (₹ Cr) | M2: Attainment % (H1) | N2: H2 Quota (₹ Cr) | O2: H2 Actuals (₹ Cr) | P2: Attainment % (H2) | Q2: Annual Quota (₹ Cr) | R2: Annual Actuals (₹ Cr) | S2: Attainment % (Annual) | T2: # Deals (Total) | U2: Led-By Deals (count) | V2: Led-By Rev (₹ Cr) | W2: Contributed Deals (count) | X2: Contributed Rev (₹ Cr) | Y2: Rank (Div.)
A3: 1 | B3: S1 Division Total | C3: S1 | D3: FY 25-26 | E3: - | F3: =SUMIFS('[1]Opportunity Pipeline'!$O:$O,'[1]Opportunity Pipeline'!$K:$K,"Professional Services",'[1]Opportunity Pipeline'!$Z:$Z,"S1")/10^7 -> 1.5529837 | G3: - | H3: - | I3: - | J3: - | K3: - | L3: =SUM(F3,I3) -> 1.5529837 | M3: - | N3: - | O3: - | P3: - | Q3: 2 | R3: =SUM(L3,O3) -> 1.5529837 | S3: =IFERROR(R3/Q3,"-") -> 0.77649185 | T3: =COUNTIFS('[1]Opportunity Pipeline'!$K:$K,"Professional Services",'[1]Opportunity Pipeline'!$Z:$Z,"S1") -> 6
A4: 2 | B4: S2 Division Total | C4: S2 | D4: FY 25-26 | E4: - | F4: =SUMIFS('[1]Opportunity Pipeline'!$O:$O,'[1]Opportunity Pipeline'!$K:$K,"Professional Services",'[1]Opportunity Pipeline'!$Z:$Z,"S2")/10^7 -> 7.104184 | G4: - | H4: - | I4: - | J4: - | K4: - | L4: =SUM(F4,I4) -> 7.104184 | M4: - | N4: - | O4: - | P4: - | Q4: 3 | R4: =SUM(L4,O4) -> 7.104184 | S4: =IFERROR(R4/Q4,"-") -> 2.3680613 | T4: =COUNTIFS('[1]Opportunity Pipeline'!$K:$K,"Professional Services",'[1]Opportunity Pipeline'!$Z:$Z,"S2") -> 2
A5: 3 | B5: CB Division Total | C5: CB | D5: FY 25-26 | E5: - | F5: =SUMIFS('[1]Opportunity Pipeline'!$O:$O,'[1]Opportunity Pipeline'!$K:$K,"Professional Services",'[1]Opportunity Pipeline'!$Z:$Z,"CB")/10^7 -> 0 | G5: - | H5: - | I5: - | J5: - | K5: - | L5: =SUM(F5,I5) -> 0 | M5: - | N5: - | O5: - | P5: - | Q5: 10 | R5: =SUM(L5,O5) -> 0 | S5: =IFERROR(R5/Q5,"-") -> 0 | T5: =COUNTIFS('[1]Opportunity Pipeline'!$K:$K,"Professional Services",'[1]Opportunity Pipeline'!$Z:$Z,"CB") -> 0
A6: 4 | B6: GB Division Total | C6: GB | D6: FY 25-26 | E6: - | F6: =SUMIFS('[1]Opportunity Pipeline'!$O:$O,'[1]Opportunity Pipeline'!$K:$K,"Professional Services",'[1]Opportunity Pipeline'!$Z:$Z,"GB")/10^7 -> 0.28294596 | G6: - | H6: - | I6: - | J6: - | K6: - | L6: =SUM(F6,I6) -> 0.28294596 | M6: - | N6: - | O6: - | P6: - | Q6: 5 | R6: =SUM(L6,O6) -> 0.28294596 | S6: =IFERROR(R6/Q6,"-") -> 0.056589191 | T6: =COUNTIFS('[1]Opportunity Pipeline'!$K:$K,"Professional Services",'[1]Opportunity Pipeline'!$Z:$Z,"GB") -> 8
A7: 5 | B7: South Division Total | C7: South | D7: FY 25-26 | E7: - | F7: =SUMIFS('[1]Opportunity Pipeline'!$O:$O,'[1]Opportunity Pipeline'!$K:$K,"Professional Services",'[1]Opportunity Pipeline'!$Z:$Z,"South")/10^7 -> 0 | G7: - | H7: - | I7: - | J7: - | K7: - | L7: =SUM(F7,I7) -> 0 | M7: - | N7: - | O7: - | P7: - | Q7: 1 | R7: =SUM(L7,O7) -> 0 | S7: =IFERROR(R7/Q7,"-") -> 0 | T7: =COUNTIFS('[1]Opportunity Pipeline'!$K:$K,"Professional Services",'[1]Opportunity Pipeline'!$Z:$Z,"South") -> 0
A8: 6 | B8: GeoX Division Total | C8: GeoX | D8: FY 25-26 | E8: - | F8: =SUMIFS('[1]Opportunity Pipeline'!$O:$O,'[1]Opportunity Pipeline'!$K:$K,"Professional Services",'[1]Opportunity Pipeline'!$Z:$Z,"GeoX")/10^7 -> 0 | G8: - | H8: - | I8: - | J8: - | K8: - | L8: =SUM(F8,I8) -> 0 | M8: - | N8: - | O8: - | P8: - | Q8: 5 | R8: =SUM(L8,O8) -> 0 | S8: =IFERROR(R8/Q8,"-") -> 0 | T8: =COUNTIFS('[1]Opportunity Pipeline'!$K:$K,"Professional Services",'[1]Opportunity Pipeline'!$Z:$Z,"GeoX") -> 0
B9: RTM Total | E9: - | F9: =SUM(F3:F8) -> 8.9401137 | G9: - | H9: - | I9: - | J9: - | K9: - | L9: =SUM(L3:L8) -> 8.9401137 | M9: - | N9: - | O9: - | P9: - | Q9: =SUM(Q3:Q8) -> 26 | R9: =SUM(R3:R8) -> 8.9401137 | S9: =IFERROR(R9/Q9,"-") -> 0.34385053 | T9: =SUM(T3:T8) -> 16

Sheet V8 · CSG
A1: VIEW 8 — RTM CONTRIBUTION | CSG | Booking (Revenue) | H1 & Annual
A2: # | B2: RTM Name | C2: Division | D2: FY | E2: Q1 Quota (₹ Cr) | F2: Q1 Actuals (₹ Cr) | G2: Attainment % (Q1) | H2: Q2 Quota (₹ Cr) | I2: Q2 Actuals (₹ Cr) | J2: Attainment % (Q2) | K2: H1 Quota (₹ Cr) | L2: H1 Actuals (₹ Cr) | M2: Attainment % (H1) | N2: H2 Quota (₹ Cr) | O2: H2 Actuals (₹ Cr) | P2: Attainment % (H2) | Q2: Annual Quota (₹ Cr) | R2: Annual Actuals (₹ Cr) | S2: Attainment % (Annual) | T2: # Deals (Total) | U2: Led-By Deals (count) | V2: Led-By Rev (₹ Cr) | W2: Contributed Deals (count) | X2: Contributed Rev (₹ Cr) | Y2: Rank (Div.)
A3: 1 | B3: S1 Division Total | C3: S1 | D3: FY 25-26 | E3: - | F3: =SUMIFS('[1]Opportunity Pipeline'!$O:$O,'[1]Opportunity Pipeline'!$K:$K,"CSG (EndPoint)",'[1]Opportunity Pipeline'!$Z:$Z,"S1")/10^7 -> 10.894036 | G3: - | H3: - | I3: - | J3: - | K3: - | L3: =SUM(F3,I3) -> 10.894036 | M3: - | N3: - | O3: - | P3: - | Q3: 37 | R3: =SUM(L3,O3) -> 10.894036 | S3: =IFERROR(R3/Q3,"-") -> 0.29443339 | T3: =COUNTIFS('[1]Opportunity Pipeline'!$K:$K,"CSG (Endpoint)",'[1]Opportunity Pipeline'!$Z:$Z,"S1") -> 58
A4: 2 | B4: S2 Division Total | C4: S2 | D4: FY 25-26 | E4: - | F4: =SUMIFS('[1]Opportunity Pipeline'!$O:$O,'[1]Opportunity Pipeline'!$K:$K,"CSG (EndPoint)",'[1]Opportunity Pipeline'!$Z:$Z,"S2")/10^7 -> 0.2977234 | G4: - | H4: - | I4: - | J4: - | K4: - | L4: =SUM(F4,I4) -> 0.2977234 | M4: - | N4: - | O4: - | P4: - | Q4: 42 | R4: =SUM(L4,O4) -> 0.2977234 | S4: =IFERROR(R4/Q4,"-") -> 0.0070886524 | T4: =COUNTIFS('[1]Opportunity Pipeline'!$K:$K,"CSG (Endpoint)",'[1]Opportunity Pipeline'!$Z:$Z,"S2") -> 5
A5: 3 | B5: CB Division Total | C5: CB | D5: FY 25-26 | E5: - | F5: =SUMIFS('[1]Opportunity Pipeline'!$O:$O,'[1]Opportunity Pipeline'!$K:$K,"CSG (EndPoint)",'[1]Opportunity Pipeline'!$Z:$Z,"CB")/10^7 -> 0.240026 | G5: - | H5: - | I5: - | J5: - | K5: - | L5: =SUM(F5,I5) -> 0.240026 | M5: - | N5: - | O5: - | P5: - | Q5: 30 | R5: =SUM(L5,O5) -> 0.240026 | S5: =IFERROR(R5/Q5,"-") -> 0.0080008667 | T5: =COUNTIFS('[1]Opportunity Pipeline'!$K:$K,"CSG (Endpoint)",'[1]Opportunity Pipeline'!$Z:$Z,"CB") -> 12
A6: 4 | B6: GB Division Total | C6: GB | D6: FY 25-26 | E6: - | F6: =SUMIFS('[1]Opportunity Pipeline'!$O:$O,'[1]Opportunity Pipeline'!$K:$K,"CSG (EndPoint)",'[1]Opportunity Pipeline'!$Z:$Z,"GB")/10^7 -> 7.8676617 | G6: - | H6: - | I6: - | J6: - | K6: - | L6: =SUM(F6,I6) -> 7.8676617 | M6: - | N6: - | O6: - | P6: - | Q6: 0 | R6: =SUM(L6,O6) -> 7.8676617 | S6: =IFERROR(R6/Q6,"-") -> - | T6: =COUNTIFS('[1]Opportunity Pipeline'!$K:$K,"CSG (Endpoint)",'[1]Opportunity Pipeline'!$Z:$Z,"GB") -> 18
A7: 5 | B7: South Division Total | C7: South | D7: FY 25-26 | E7: - | F7: =SUMIFS('[1]Opportunity Pipeline'!$O:$O,'[1]Opportunity Pipeline'!$K:$K,"CSG (EndPoint)",'[1]Opportunity Pipeline'!$Z:$Z,"South")/10^7 -> 4.1905954 | G7: - | H7: - | I7: - | J7: - | K7: - | L7: =SUM(F7,I7) -> 4.1905954 | M7: - | N7: - | O7: - | P7: - | Q7: 18 | R7: =SUM(L7,O7) -> 4.1905954 | S7: =IFERROR(R7/Q7,"-") -> 0.23281085 | T7: =COUNTIFS('[1]Opportunity Pipeline'!$K:$K,"CSG (Endpoint)",'[1]Opportunity Pipeline'!$Z:$Z,"South") -> 34
A8: 6 | B8: GeoX Division Total | C8: GeoX | D8: FY 25-26 | E8: - | F8: =SUMIFS('[1]Opportunity Pipeline'!$O:$O,'[1]Opportunity Pipeline'!$K:$K,"CSG (EndPoint)",'[1]Opportunity Pipeline'!$Z:$Z,"GeoX")/10^7 -> 0 | G8: - | H8: - | I8: - | J8: - | K8: - | L8: =SUM(F8,I8) -> 0 | M8: - | N8: - | O8: - | P8: - | Q8: 8 | R8: =SUM(L8,O8) -> 0 | S8: =IFERROR(R8/Q8,"-") -> 0 | T8: =COUNTIFS('[1]Opportunity Pipeline'!$K:$K,"CSG (Endpoint)",'[1]Opportunity Pipeline'!$Z:$Z,"GeoX") -> 0
B9: RTM Total | E9: - | F9: =SUM(F3:F8) -> 23.490042 | G9: - | H9: - | I9: - | J9: - | K9: - | L9: =SUM(L3:L8) -> 23.490042 | M9: - | N9: - | O9: - | P9: - | Q9: =SUM(Q3:Q8) -> 135 | R9: =SUM(R3:R8) -> 23.490042 | S9: =IFERROR(R9/Q9,"-") -> 0.17400031 | T9: =SUM(T3:T8) -> 127

Sheet V9 · Cloud
A1: VIEW 9 — RTM CONTRIBUTION | CLOUD | Booking (Revenue) | H1 & Annual
A2: # | B2: RTM Name | C2: Division | D2: FY | E2: Q1 Quota (₹ Cr) | F2: Q1 Actuals (₹ Cr) | G2: Attainment % (Q1) | H2: Q2 Quota (₹ Cr) | I2: Q2 Actuals (₹ Cr) | J2: Attainment % (Q2) | K2: H1 Quota (₹ Cr) | L2: H1 Actuals (₹ Cr) | M2: Attainment % (H1) | N2: H2 Quota (₹ Cr) | O2: H2 Actuals (₹ Cr) | P2: Attainment % (H2) | Q2: Annual Quota (₹ Cr) | R2: Annual Actuals (₹ Cr) | S2: Attainment % (Annual) | T2: # Deals (Total)
A3: 1 | B3: S1 Division Total | C3: S1 | D3: FY 25-26 | E3: - | F3: =SUMIFS('[1]Opportunity Pipeline'!$O:$O,'[1]Opportunity Pipeline'!$K:$K,"Cloud",'[1]Opportunity Pipeline'!$Z:$Z,"S1")/10^7 -> 0 | G3: - | H3: - | I3: - | J3: - | K3: - | L3: =SUM(F3,I3) -> 0 | M3: - | N3: - | O3: - | P3: - | Q3: 37 | R3: =SUM(L3,O3) -> 0 | S3: =IFERROR(R3/Q3,"-") -> 0 | T3: =COUNTIFS('[1]Opportunity Pipeline'!$K:$K,"Cloud",'[1]Opportunity Pipeline'!$Z:$Z,"S1") -> 0
A4: 2 | B4: S2 Division Total | C4: S2 | D4: FY 25-26 | E4: - | F4: =SUMIFS('[1]Opportunity Pipeline'!$O:$O,'[1]Opportunity Pipeline'!$K:$K,"Cloud",'[1]Opportunity Pipeline'!$Z:$Z,"S2")/10^7 -> 0 | G4: - | H4: - | I4: - | J4: - | K4: - | L4: =SUM(F4,I4) -> 0 | M4: - | N4: - | O4: - | P4: - | Q4: 42 | R4: =SUM(L4,O4) -> 0 | S4: =IFERROR(R4/Q4,"-") -> 0 | T4: =COUNTIFS('[1]Opportunity Pipeline'!$K:$K,"Cloud",'[1]Opportunity Pipeline'!$Z:$Z,"S2") -> 0
A5: 3 | B5: CB Division Total | C5: CB | D5: FY 25-26 | E5: - | F5: =SUMIFS('[1]Opportunity Pipeline'!$O:$O,'[1]Opportunity Pipeline'!$K:$K,"Cloud",'[1]Opportunity Pipeline'!$Z:$Z,"CB")/10^7 -> 1.5520454 | G5: - | H5: - | I5: - | J5: - | K5: - | L5: =SUM(F5,I5) -> 1.5520454 | M5: - | N5: - | O5: - | P5: - | Q5: 30 | R5: =SUM(L5,O5) -> 1.5520454 | S5: =IFERROR(R5/Q5,"-") -> 0.051734845 | T5: =COUNTIFS('[1]Opportunity Pipeline'!$K:$K,"Cloud",'[1]Opportunity Pipeline'!$Z:$Z,"CB") -> 20
A6: 4 | B6: GB Division Total | C6: GB | D6: FY 25-26 | E6: - | F6: =SUMIFS('[1]Opportunity Pipeline'!$O:$O,'[1]Opportunity Pipeline'!$K:$K,"Cloud",'[1]Opportunity Pipeline'!$Z:$Z,"GB")/10^7 -> 1.0873971 | G6: - | H6: - | I6: - | J6: - | K6: - | L6: =SUM(F6,I6) -> 1.0873971 | M6: - | N6: - | O6: - | P6: - | Q6: 0 | R6: =SUM(L6,O6) -> 1.0873971 | S6: =IFERROR(R6/Q6,"-") -> - | T6: =COUNTIFS('[1]Opportunity Pipeline'!$K:$K,"Cloud",'[1]Opportunity Pipeline'!$Z:$Z,"GB") -> 2
A7: 5 | B7: South Division Total | C7: South | D7: FY 25-26 | E7: - | F7: =SUMIFS('[1]Opportunity Pipeline'!$O:$O,'[1]Opportunity Pipeline'!$K:$K,"Cloud",'[1]Opportunity Pipeline'!$Z:$Z,"South")/10^7 -> 0 | G7: - | H7: - | I7: - | J7: - | K7: - | L7: =SUM(F7,I7) -> 0 | M7: - | N7: - | O7: - | P7: - | Q7: 18 | R7: =SUM(L7,O7) -> 0 | S7: =IFERROR(R7/Q7,"-") -> 0 | T7: =COUNTIFS('[1]Opportunity Pipeline'!$K:$K,"Cloud",'[1]Opportunity Pipeline'!$Z:$Z,"South") -> 0
A8: 6 | B8: GeoX Division Total | C8: GeoX | D8: FY 25-26 | E8: - | F8: =SUMIFS('[1]Opportunity Pipeline'!$O:$O,'[1]Opportunity Pipeline'!$K:$K,"Cloud",'[1]Opportunity Pipeline'!$Z:$Z,"GeoX")/10^7 -> 0 | G8: - | H8: - | I8: - | J8: - | K8: - | L8: =SUM(F8,I8) -> 0 | M8: - | N8: - | O8: - | P8: - | Q8: 8 | R8: =SUM(L8,O8) -> 0 | S8: =IFERROR(R8/Q8,"-") -> 0 | T8: =COUNTIFS('[1]Opportunity Pipeline'!$K:$K,"Cloud",'[1]Opportunity Pipeline'!$Z:$Z,"GeoX") -> 0
B9: RTM Total | E9: - | F9: =SUM(F3:F8) -> 2.6394425 | G9: - | H9: - | I9: - | J9: - | K9: - | L9: =SUM(L3:L8) -> 2.6394425 | M9: - | N9: - | O9: - | P9: - | Q9: =SUM(Q3:Q8) -> 135 | R9: =SUM(R3:R8) -> 2.6394425 | S9: =IFERROR(R9/Q9,"-") -> 0.019551426 | T9: =SUM(T3:T8) -> 22
